Workbook
Name dataku: 'Cetak Kartu (2)'!$H$11
Name dataku: 'Cetak Kartu '!$H$11

Sheet MENU UTAMA

Sheet DataSiswa
A1: No Urut | B1: Nama Siswa | C1: L/P | D1: Tempat Tanggal Lahir | E1: Nama Orang Tua/ Wali | F1: NISN | G1: Asal Sekolah
A2: 1 | B2: A. ARTIANDRA MANGGALA | C2: L | D2: Surabaya, 01 Mei 2014 | E2: HARDIAN ANWAR | F2: 0149281176 | G2: SDN 1 MEKARSARI
A3: 2 | B3: ABDURRAHMAN RIZQI | C3: L | D3: SUNTALANGU, 25 AGUSTUS 2013 | E3: M. ROSIDI | F3: 0132181238 | G3: SDN 1 SUNTALANGU
A4: 3 | B4: Adrian Ripano | C4: L | D4: Ketangga. 23 April 2014 | E4: Hirjan | G4: SDN 2 Ketangga
A5: 4 | B5: AFDHAL GILANG RAHMAN | C5: L | D5: SUNTALANGU, 13 DESEMBER 2013 | E5: ABD. RAHMAN | F5: 0131168304 | G5: SDN 2 SUNTALANGU
A6: 5 | B6: Afriana Ida Melia | C6: P | D6: Ketangga, 27 Juni 2013 | E6: Buhari | G6: SDN 2 Ketangga
A7: 6 | B7: AHYAR RASYIDIN | C7: L | D7: SUELA, 29 MEI 2013 | E7: IMRAN RASYIDIN | F7: 0147142546 | G7: SDN 2 SUELA
A8: 7 | B8: AIRIN SABRINA ZUHRI | C8: P | D8: KETANGGA, 16 SEPTEMBER 2013 | E8: ZOHRI | F8: 0133534911 | G8: SDN 1 KETANGGA
A9: 8 | B9: AJWAD DILARA | C9: P | D9: SUNTALANGU, 5 OKTOBER 2013 | E9: ROLIADI | F9: 0136590570 | G9: SDN 4 SUNTALANGU
A10: 9 | B10: AKIVA NAILA | C10: P | D10: SUNTALANGU, 4 MARET 2014 | E10: SIATUN | F10: 3141174977 | G10: SDN 2 SUNTALANGU
A11: 10 | B11: AL PREDO HEIYANTO | C11: L | D11: SUNTALANGU, 09 MEI 2013 | E11: SUGIANTO | F11: 3133178038 | G11: SDN 4 SUNTALANGU
A12: 11 | B12: ALBY NAZROFI | C12: L | D12: SUNTALANGU, 3 DESEMBER 2013 | E12: NASREN | F12: 0131381971 | G12: SDN 2 SUNTALANGU
A13: 12 | B13: ALFIA SHAFIYYA | C13: P | D13: SUNTALANGU, 3 MARET 2014 | E13: SUHEDI | F13: 0149153443 | G13: SDN 2 SUNTALANGU
A14: 13 | B14: ALFIAN PRATAMA | C14: L | D14: AIK EMBUK, 25 NOPEMBE 2013 | E14: SERUM | F14: 3130515492 | G14: SDN 1 MEKARSARI
A15: 14 | B15: ALFINA SYAKILA | C15: P | D15: KETANGGA, 28 DESEMBER 2014 | E15: HABIBI | G15: SDN 4 KETANGGA
A16: 15 | B16: ALIFHA NURUL IDHA | C16: P | D16: SUNTALANGU, 15 OKTOBER 2013 | E16: MAHRUP | F16: 0134883509 | G16: SDN 2 SUNTALANGU
A17: 16 | B17: ALISYA LATIFAH | C17: P | D17: SUELA, 26 DESEMBER 2013 | E17: NAAM | F17: 0136984695 | G17: SDN 1 SUELA
A18: 17 | B18: ALMIRA KISYA ADIBHA | C18: P | D18: SUNTALANGU, 3 OKTOBER 2013 | E18: SAPARWADI | F18: 0135283544 | G18: SDN 4 SUNTALANGU
A19: 18 | B19: AMELIA NA'IM | C19: P | D19: SUNTALANGU, 3 JUNI 2014 | E19: MARDI | F19: 3144584190 | G19: SDN 1 SUNTALANGU
A20: 19 | B20: AMELIA SEPTIAZZAHRA | C20: P | D20: SUELA, 18 SEPTEMBER 2018 | E20: MUHRIP | F20: 03133312865 | G20: SDN 1 SUELA
A21: 20 | B21: AMIAN ABINTANG | C21: L | D21: KETANGGA, 28 APRIL 2014 | E21: HASAN | G21: SDN 3 KETANGGA
A22: 21 | B22: AMRU DHAFFA AL-GHAZY | C22: L | D22: SUELA, 17 APRIL 2013 | E22: SADDAM HUSEN | F22: 3136588175 | G22: SDN 1 SUELA
A23: 22 | B23: ANDIKA ROHMAN ALMAHFUZ | C23: L | D23: DASAN KOAK, 9 AGUSTUS 2013 | E23: NURJI | F23: 0139190862 | G23: SDN 1 MEKARSARI
A24: 23 | B24: Andra Dwi Putra | C24: L | D24: Ketangga, 18 Mei 2014 | E24: Latif | G24: SDN 2 Ketangga
A25: 24 | B25: ANGGI WAHYUDI | C25: L | D25: DASAN KOAK, 19 SEPTEMBER 2013 | E25: HAERUL FATONI | F25: 0136635078 | G25: SDN 1 MEKARSARI
A26: 25 | B26: AQILA DWI RAHAYU PUTRI | C26: P | D26: SUNTALANGU, 15 MARET 2013 | E26: WIDI HARTONO | F26: 3134074358 | G26: SDN 3 SUNTALANGU
A27: 26 | B27: ARKAN MISPIRIL AZWA | C27: L | D27: KETANGGA, 27 AGUSTUS 2013 | E27: ASPIUDDIN | G27: SDN 3 KETANGGA
A28: 27 | B28: ARPA ARYA SAPUTRA | C28: L | D28: SUELA, 9 SEPTEMBER 2013 | E28: HAPIZI | F28: 0133685051 | G28: SDN 1 SUELA
A29: 28 | B29: ARSAD ARSYADI AZIZUROHIM | C29: L | D29: KETANGGA, 2 NOVEMBER 2014 | E29: SUMARDI | G29: SDN 5 KETANGGA
A30: 29 | B30: AZIRUL HAQ | C30: L | D30: SUELA, 5 SEPTEMBER 2013 | E30: PATAHARUDDIN | F30: 0139383541 | G30: SDN 1 SUELA
A31: 30 | B31: AZIZ SUDDDIN WAHID | C31: L | D31: Ketangga, 02 Februari 2013 | F31: 135000559 | G31: SDN 3 KETANGGA
A32: 31 | B32: AZMI HAIL | C32: L | D32: KETANGGA, 17 MEI 2014 | E32: HASIPUDDIN | G32: SDN 3 KETANGGA
A33: 32 | B33: AZRATUL ZAONA | C33: P | D33: Suntalangu, 07 Desember 2013 | E33: Mahrup | F33: 0132671075 | G33: SDN 4 SUNTALANGU
A34: 33 | B34: BAHIYYA ATIQA PAIHA | C34: P | D34: KETANGGA, 2 JULI 2015 | E34: SAPAAH | F34: 0143227202 | G34: SDN 1 KETANGGA
A35: 34 | B35: BAIQ AINUL MALASARI | C35: P | D35: Batman, 17 Juli 2014 | E35: LALU MURAHIP | F35: 0 | G35: SDN 3 SELAPARANG
A36: 35 | B36: BAIQ ALFINA NURHIDAYATI | C36: P | D36: SELAPARANG, 03 MARET 2014 | F36: 3146598681 | G36: SDN 3 KETANGGA
A37: 36 | B37: BAIQ JANNATUL QOLBINA SYAHRANI | C37: P | D37: KETANGGA, 19 JUNI 2014 | E37: LALU HAIRUL | G37: MI NW KETANGGA
A38: 37 | B38: BAIQ JIHAN FARHANA | C38: P | D38: Selaparang, 08 Juni 2014 | E38: Lalu Irham | F38: 3141695437 | G38: SDN 2 SELAPARANG
A39: 38 | B39: BAIQ NUR RIZKA TASYA | C39: P | D39: Selaparang, 12 November 2013 | E39: Lalu Ismail Marzuki | F39: 0138799542 | G39: SDN 2 SELAPARANG | I39: Afirmasi
A40: 39 | B40: BAIQ OKTA NILA SAPITRI | C40: P | D40: Selaparang, 04 Oktober 2013 | E40: Lalu Sapren | F40: 3138592896 | G40: SDN 2 SELAPARANG | I40: Afirmasi
...

Sheet syarat
A1: PANITIA SELEKSI PENERIMAAN MURID BARU
A2: SMP NEGERI 1 SUELA
A3: T.P 2025 / 2026
A5: A. | B5: syarat - syarat pendaftaran sebagai berikut;
A6: 1 | B6: Foto copy ijazah terakhir 2 lembar ( bila sudah terbit )
A7: 2 | B7: Surat Keterangan Lulus ( SKL ) / mengikuti ujian sekolah
A8: 3 | B8: Fotocopy Kartu Keluaraga 2 lembar
A9: 4 | B9: Foto copy Akta Kelahiran 2 lembar
A10: 5 | B10: Foto copy KTP Orang btua / wali 2 lembar
A11: 6 | B11: Foto Copy PIP, PKH, dll sejenisnya ( bagi yang memiliki )
A12: 7 | B12: Pas photo ukuran 3 x 4 cm sebanyak 4 lembar memakai baju putih dengan latar biru
A13: 8 | B13: Map warna biru untuk laki-laki dan warna merah untuk perempuan
A15: B | B15: Jadwal Kegiatan SPMB
A16: NO | B16: KEGIATAN | C16: TANGGAL PELAKSANAAN | D16: KETR
A17: 1 | B17: Pendaftaran SPMB | C17: 4 - 15 Juni 2025
A18: 2 | B18: Seleksi | C18: 20 - 21 Juni 2025
A19: 3 | B19: Pengumuman | C19: 24 Juni 2025
A20: 4 | B20: Daftar Ulang | C20: 24 Juni s/d 1 Juli 2025
A21: 5 | B21: Pra MPLS | C21: 8 - 9 Juli 2025
A22: 6 | B22: MPLS | C22: 10 - 12 Juli 2025
A23: 7 | B23: Awal Masuk sekolah | C23: 14 Juli 2025
A27: PANITIA SELEKSI PENERIMAAN MURID BARU
A28: SMP NEGERI 1 SUELA
A29: T.P 2025 / 2026
A31: A. | B31: syarat - syarat pendaftaran sebagai berikut;
A32: 1 | B32: Foto copy ijazah terakhir 2 lembar ( bila sudah terbit )
A33: 2 | B33: Surat Keterangan Lulus ( SKL ) / mengikuti ujian sekolah
A34: 3 | B34: Fotocopy Kartu Keluaraga 2 lembar
A35: 4 | B35: Foto copy Akta Kelahiran 2 lembar
A36: 5 | B36: Foto copy KTP Orang btua / wali 2 lembar
A37: 6 | B37: Foto Copy PIP, PKH, dll sejenisnya ( bagi yang memiliki )
A38: 7 | B38: Pas photo ukuran 3 x 4 cm sebanyak 4 lembar memakai baju putih dengan latar biru
A39: 8 | B39: Map warna biru untuk laki-laki dan warna merah untuk perempuan
A41: B | B41: Jadwal Kegiatan SPMB
A42: NO | B42: KEGIATAN | C42: TANGGAL PELAKSANAAN | D42: KETR
A43: 1 | B43: Pendaftaran SPMB | C43: 4 - 15 Juni 2025
A44: 2 | B44: Seleksi | C44: 20 - 21 Juni 2025
A45: 3 | B45: Pengumuman | C45: 24 Juni 2025
A46: 4 | B46: Daftar Ulang | C46: 24 Juni s/d 1 Juli 2025
A47: 5 | B47: Pra MPLS | C47: 8 - 9 Juli 2025
...

Sheet FORMULIR IND.
A1: PEMERINTAH KABUPATEN LOMBOK TIMUR
A2: DINAS PENDIDIKAN DAN KEBUDAYAAN
A3: SMP NEGERI 1 SUELA
A4: Jl. H.M.Makmun, Kecamatan Suela Kabupaten Lombok Timur Kode Pos 83657
A6: FORMULIR SPMB SMPN 1 SUELA T.P.2025-2026
A8: I. | B8: IDENTITAS CALON SISWA
B9: 1. | C9: Nama Siswa | G9: : | H9: .....................................................................................
B10: 2 | C10: Nomor Induk Siswa Nasional (NISN) | G10: : | H10: .....................................................................................
B11: 3 | C11: Jenis Kelamin | G11: : | H11: .....................................................................................
B12: 4 | C12: Tempat / Tanggal Lahir | G12: : | H12: .....................................................................................
B13: 5 | C13: Agama | G13: : | H13: .....................................................................................
B14: 6 | C14: Anak ke berapa | G14: : | H14: .....................................................................................
B15: 7 | C15: Jumlah Saudara Kandung | G15: : | H15: .....................................................................................
B16: 8 | C16: Memiliki Kartu KIP | G16: : | H16: Ada/ Tidak ada (Coret yg tidak Perlu)
B17: 9 | C17: Nomer Kartu KIP | G17: : | H17: ...............................................................................................
B18: 10 | C18: No.HP yang bisa dihubungi | G18: : | H18: ...............................................................................................
A19: II. | B19: IDENTITAS ORANG TUA KANDUNG
B21: No. | C21: Orang Tua Kandung | F21: Ayah | J21: Ibu
B22: 1 | C22: Nama
B23: 2 | C23: Tempat / Tanggal Lahir
B24: 3 | C24: Agama
B25: 4 | C25: Pendidikan
B26: 5 | C26: Pekerjaan
B27: 6 | C27: Penghasilan / Bulan | F27: Rp. | G27: ............................ | J27: Rp. | K27: ....................
B28: 7 | C28: Alamat Rumah
B29: 8 | C29: Masih Hidup / Meninggal Dunia
A31: III. | B31: KETERANGAN TEMPAT TINGGAL
B32: 1. | C32: Alamat Siswa | G32: : | H32: ...................................................................................
B33: 2. | C33: Jarak dari tempat tinggal | G33: : | H33: ...................................................................................
B34: 3. | C34: Ke sekolah dengan | G34: : | H34: ...................................................................................
A36: IV. | B36: KETERANGAN TEMPAT WALI
B37: 1. | C37: Nama | G37: : | H37: ...................................................................................
B38: 2. | C38: Tempat / Tanggal Lahir | G38: : | H38: ...................................................................................
B39: 3. | C39: Agama | G39: : | H39: ...................................................................................
B40: 4. | C40: Hubungan Keluarga | G40: : | H40: ...................................................................................
B41: 5. | C41: Pekerjaan | G41: : | H41: ...................................................................................
B42: 6. | C42: Penghasilan / Bulan | G42: : | H42: ...................................................................................
B43: 7. | C43: Alamat | G43: : | H43: ...................................................................................
A45: V. | B45: KETERANGAN LAIN- LAIN
B46: 1. | C46: Golongan Darah | G46: : | H46: ...................................................................................
...

Sheet RUANG MPLS 
A6: NO. | B6: NOMOR PESERTA | C6: NAMA PESERTA | D6: L/P | E6: ASAL SEKOLAH
A7: 1 | B7: =DataSiswa!#REF! -> #REF! | C7: =DataSiswa!B2 -> A. ARTIANDRA MANGGALA | D7: =DataSiswa!C2 -> L | E7: =DataSiswa!G2 -> SDN 1 MEKARSARI
A8: 2 | B8: =DataSiswa!#REF! -> #REF! | C8: =DataSiswa!B3 -> ABDURRAHMAN RIZQI | D8: =DataSiswa!C3 -> L | E8: =DataSiswa!G3 -> SDN 1 SUNTALANGU
A9: 3 | B9: =DataSiswa!#REF! -> #REF! | C9: =DataSiswa!B4 -> Adrian Ripano | D9: =DataSiswa!C4 -> L | E9: =DataSiswa!G4 -> SDN 2 Ketangga
A10: 4 | B10: =DataSiswa!#REF! -> #REF! | C10: =DataSiswa!B5 -> AFDHAL GILANG RAHMAN | D10: =DataSiswa!C5 -> L | E10: =DataSiswa!G5 -> SDN 2 SUNTALANGU
A11: 5 | B11: =DataSiswa!#REF! -> #REF! | C11: =DataSiswa!B6 -> Afriana Ida Melia | D11: =DataSiswa!C6 -> P | E11: =DataSiswa!G6 -> SDN 2 Ketangga
A12: 6 | B12: =DataSiswa!#REF! -> #REF! | C12: =DataSiswa!B7 -> AHYAR RASYIDIN | D12: =DataSiswa!C7 -> L | E12: =DataSiswa!G7 -> SDN 2 SUELA
A13: 7 | B13: =DataSiswa!#REF! -> #REF! | C13: =DataSiswa!B8 -> AIRIN SABRINA ZUHRI | D13: =DataSiswa!C8 -> P | E13: =DataSiswa!G8 -> SDN 1 KETANGGA
A14: 8 | B14: =DataSiswa!#REF! -> #REF! | C14: =DataSiswa!B9 -> AJWAD DILARA | D14: =DataSiswa!C9 -> P | E14: =DataSiswa!G9 -> SDN 4 SUNTALANGU
A15: 9 | B15: =DataSiswa!#REF! -> #REF! | C15: =DataSiswa!B10 -> AKIVA NAILA | D15: =DataSiswa!C10 -> P | E15: =DataSiswa!G10 -> SDN 2 SUNTALANGU
A16: 10 | B16: =DataSiswa!#REF! -> #REF! | C16: =DataSiswa!B11 -> AL PREDO HEIYANTO | D16: =DataSiswa!C11 -> L | E16: =DataSiswa!G11 -> SDN 4 SUNTALANGU
A17: 11 | B17: =DataSiswa!#REF! -> #REF! | C17: =DataSiswa!B12 -> ALBY NAZROFI | D17: =DataSiswa!C12 -> L | E17: =DataSiswa!G12 -> SDN 2 SUNTALANGU
A18: 12 | B18: =DataSiswa!#REF! -> #REF! | C18: =DataSiswa!B13 -> ALFIA SHAFIYYA | D18: =DataSiswa!C13 -> P | E18: =DataSiswa!G13 -> SDN 2 SUNTALANGU
... A35: 29 | B35: =DataSiswa!#REF! -> #REF! | C35: =DataSiswa!B30 -> AZIRUL HAQ | D35: =DataSiswa!C30 -> L | E35: =DataSiswa!G30 -> SDN 1 SUELA
B38: PANITIA SPMB
C40: KETUA | E40: SEKRETARIS
C44: L.M. MUSHLIHUDIN, S. Pd | E44: HAMZANWADI, S. Pd
C45: NIP. 19741231 200901 1 027 | E45: NIP. 19721231 200801 1 119
A52: NO. | B52: NOMOR PESERTA | C52: NAMA PESERTA | D52: L/P | E52: ASAL SEKOLAH
A53: 1 | B53: 030 | C53: =DataSiswa!B31 -> AZIZ SUDDDIN WAHID | D53: =DataSiswa!C31 -> L | E53: =DataSiswa!G31 -> SDN 3 KETANGGA
A54: 2 | B54: 031 | C54: =DataSiswa!B32 -> AZMI HAIL | D54: =DataSiswa!C32 -> L | E54: =DataSiswa!G32 -> SDN 3 KETANGGA
A55: 3 | B55: 032 | C55: =DataSiswa!B33 -> AZRATUL ZAONA | D55: =DataSiswa!C33 -> P | E55: =DataSiswa!G33 -> SDN 4 SUNTALANGU
A56: 4 | B56: 033 | C56: =DataSiswa!B34 -> BAHIYYA ATIQA PAIHA | D56: =DataSiswa!C34 -> P | E56: =DataSiswa!G34 -> SDN 1 KETANGGA
A57: 5 | B57: 034 | C57: =DataSiswa!B35 -> BAIQ AINUL MALASARI | D57: =DataSiswa!C35 -> P | E57: =DataSiswa!G35 -> SDN 3 SELAPARANG
A58: 6 | B58: 035 | C58: =DataSiswa!B36 -> BAIQ ALFINA NURHIDAYATI | D58: =DataSiswa!C36 -> P | E58: =DataSiswa!G36 -> SDN 3 KETANGGA
A59: 7 | B59: 036 | C59: =DataSiswa!B37 -> BAIQ JANNATUL QOLBINA SYAHRANI | D59: =DataSiswa!C37 -> P | E59: =DataSiswa!G37 -> MI NW KETANGGA
A60: 8 | B60: 037 | C60: =DataSiswa!B38 -> BAIQ JIHAN FARHANA | D60: =DataSiswa!C38 -> P | E60: =DataSiswa!G38 -> SDN 2 SELAPARANG
A61: 9 | B61: 038 | C61: =DataSiswa!B39 -> BAIQ NUR RIZKA TASYA | D61: =DataSiswa!C39 -> P | E61: =DataSiswa!G39 -> SDN 2 SELAPARANG
A62: 10 | B62: 039 | C62: =DataSiswa!B40 -> BAIQ OKTA NILA SAPITRI | D62: =DataSiswa!C40 -> P | E62: =DataSiswa!G40 -> SDN 2 SELAPARANG
A63: 11 | B63: 040 | C63: =DataSiswa!B41 -> BAIQ PEBRIANI | D63: =DataSiswa!C41 -> P | E63: =DataSiswa!G41 -> SDN 2 SELAPARANG
A64: 12 | B64: 041 | C64: =DataSiswa!B42 -> BAIQ SALBY NURIN NAZWA | D64: =DataSiswa!C42 -> P | E64: =DataSiswa!G42 -> SDN 2 SELAPARANG
... A81: 29 | B81: 058 | C81: =DataSiswa!B59 -> DWI SRI DINA MELIZA | D81: =DataSiswa!C59 -> P | E81: =DataSiswa!G59 -> SDI MT MEKAR SARI
B82: PANITIA SPMB
B85: SEKRETARIS | E85: KETUA
B89: =H44 -> 0 | E89: L.M. MUSHLIHUDIN, S. Pd
B90: =H45 -> 0 | E90: NIP. 19741231 200901 1 027
A97: NO. | B97: NOMOR PESERTA | C97: NAMA PESERTA | D97: L/P | E97: ASAL SEKOLAH
A98: 1 | B98: 059 | C98: =DataSiswa!B60 -> DZAKYAN ARROHMAN | D98: =DataSiswa!C60 -> L | E98: =DataSiswa!G60 -> SDN 1 SAPIT
A99: 2 | B99: 060 | C99: =DataSiswa!B61 -> ELYA RIZKIA WATI | D99: =DataSiswa!C61 -> P | E99: =DataSiswa!G61 -> SDN 2 SUNTALANGU
A100: 3 | B100: 061 | C100: =DataSiswa!B62 -> FACHRI ZAFRAN KHAIRI | D100: =DataSiswa!C62 -> L | E100: =DataSiswa!G62 -> SDN 2 SELAPARANG
...

Sheet Cetak Kartu 
A1: PEMERINTAH KABUPATEN LOMBOK TIMUR | T1: PEMERINTAH KABUPATEN LOMBOK TIMUR | AL1: 190
A2: DINAS PENDIDIKAN DAN KEBUDAYAAN | T2: DINAS PENDIDIKAN DAN KEBUDAYAAN
A3: SMP NEGERI 1 SUELA | T3: SMP NEGERI 1 SUELA
A4: Jalan H.M. Makmun ketangga Kec. Suela - Lotim, KP. 83657 | T4: =A4 -> Jalan H.M. Makmun ketangga Kec. Suela - Lotim, KP. 83657
A6: KARTU PENDAFTARAN CALON MURID BARU | T6: KARTU PENDAFTARAN CALON MURID BARU
A7: TAHUN PELAJARAN 2026-2027 | T7: TAHUN PELAJARAN 2026-2027
A9: Nomor Peserta | G9: : | H9: =VLOOKUP($AL$1,datakartu[],2) -> SITI ZULAIKHA | T9: Nomor Peserta | Z9: : | AA9: =H9 -> SITI ZULAIKHA
A10: Nama Peserta | G10: : | H10: =VLOOKUP($AL$1,datakartu[],3) -> P | T10: Nama Peserta | Z10: : | AA10: =H10 -> P
A11: Tempat Tgl. Lahir | G11: : | H11: =VLOOKUP(AL1,datakartu[],5) -> NAWIREP | T11: Tempat Tgl. Lahir | Z11: : | AA11: =H11 -> NAWIREP
A12: Asal Sekolah | G12: : | H12: =VLOOKUP(AL1,datakartu[],8) -> #REF! | T12: Asal Sekolah | Z12: : | AA12: =H12 -> #REF!
I13: Suela, 08 Juni 2026 | AB13: =I13 -> Suela, 08 Juni 2026
I14: Ketua Panitia SPMB | AB14: Ketua Panitia SPMB
I17: L.M. MUSHLIHUDIN, S. Pd | AB17: =I17 -> L.M. MUSHLIHUDIN, S. Pd
I18: NIP. 197412312009011027 | AB18: =I18 -> NIP. 197412312009011027
B19: *Catatan | U19: =B19 -> *Catatan
A20: 1. Pelaksanaan tes Calon Murid baru dilaksanakan pada tgl 22 s/d 23 Juni 2026 | T20: =A20 -> 1. Pelaksanaan tes Calon Murid baru dilaksanakan pada tgl 22 s/d 23 Juni 2026
A21: 2. Peserta didik yang tidak masuk pada hari tersebut dianggap mengundurkan diri | T21: =A21 -> 2. Peserta didik yang tidak masuk pada hari tersebut dianggap mengundurkan diri
AO22: p
A24: PEMERINTAH KABUPATEN LOMBOK TIMUR | T24: PEMERINTAH KABUPATEN LOMBOK TIMUR | AL24: =AL1+1 -> 191
A25: DINAS PENDIDIKAN DAN KEBUDAYAAN | T25: DINAS PENDIDIKAN DAN KEBUDAYAAN
A26: SMP NEGERI 1 SUELA | T26: SMP NEGERI 1 SUELA
A27: Jalan H.M. Makmun ketangga Kec. Suela - Lotim, KP. 83657 | T27: =A27 -> Jalan H.M. Makmun ketangga Kec. Suela - Lotim, KP. 83657
A29: KARTU PENDAFTARAN CALON MURID BARU | T29: KARTU PENDAFTARAN CALON MURID BARU
A30: TAHUN PELAJARAN 2026-2027 | T30: TAHUN PELAJARAN 2026-2027
A32: Nomor Peserta | G32: : | H32: =VLOOKUP($AL$24,datakartu[],2,0) -> SRI WIDIASTUTI | T32: Nomor Peserta | Z32: : | AA32: =H32 -> SRI WIDIASTUTI
A33: Nama Peserta | G33: : | H33: =VLOOKUP($AL$24,datakartu[],3,0) -> P | T33: Nama Peserta | Z33: : | AA33: =H33 -> P
A34: Tempat Tgl. Lahir | G34: : | H34: =CONCATENATE(VLOOKUP($AL$24,datakartu[],5,0)) -> H. MUH. SAID | T34: Tempat Tgl. Lahir | Z34: : | AA34: =H34 -> H. MUH. SAID
A35: Asal Sekolah | G35: : | H35: =VLOOKUP($AL$24,datakartu[],8,0) -> #REF! | T35: Asal Sekolah | Z35: : | AA35: =H35 -> #REF!
I36: =I13 -> Suela, 08 Juni 2026 | AB36: =I36 -> Suela, 08 Juni 2026
I37: Ketua Panitia SPMB | AB37: Ketua Panitia SPMB
I40: L.M. MUSHLIHUDIN, S. Pd | AB40: =I40 -> L.M. MUSHLIHUDIN, S. Pd
I41: NIP. 197412312009011027 | AB41: =I41 -> NIP. 197412312009011027
B42: *Catatan | U42: =B42 -> *Catatan
A43: 1. Pelaksanaan tes Calon Murid baru dilaksanakan pada tgl 22 s/d 23 Juni 2026 | T43: =A43 -> 1. Pelaksanaan tes Calon Murid baru dilaksanakan pada tgl 22 s/d 23 Juni 2026
A44: 2. Peserta didik yang tidak masuk pada hari tersebut dianggap mengundurkan diri | T44: =A44 -> 2. Peserta didik yang tidak masuk pada hari tersebut dianggap mengundurkan diri
A46: PEMERINTAH KABUPATEN LOMBOK TIMUR | T46: PEMERINTAH KABUPATEN LOMBOK TIMUR | AL46: =AL24+1 -> 192
A47: DINAS PENDIDIKAN DAN KEBUDAYAAN | T47: DINAS PENDIDIKAN DAN KEBUDAYAAN
A48: SMP NEGERI 1 SUELA | T48: SMP NEGERI 1 SUELA
A49: Jalan H.M. Makmun ketangga Kec. Suela - Lotim, KP. 83657 | T49: =A49 -> Jalan H.M. Makmun ketangga Kec. Suela - Lotim, KP. 83657
A51: KARTU PENDAFTARAN CALON MURID BARU | T51: KARTU PENDAFTARAN CALON MURID BARU
...

Sheet cek list
A1: CEK LIST ADMINISTRASI | F1: CEK LIST ADMINISTRASI
A3: NO | B3: DOKUMEN | C3: ADA | D3: TDK | F3: NO | G3: DOKUMEN | H3: ADA | I3: TDK
A4: 1 | B4: Fotocopy Ijazah | F4: 1 | G4: Fotocopy Ijazah
A5: 2 | B5: Surat Keterangan Lulus ( SKL ) | F5: 2 | G5: Surat Keterangan Lulus ( SKL )
A6: 3 | B6: Fotocopy Kartu Keluarga | F6: 3 | G6: Fotocopy Kartu Keluarga
A7: 4 | B7: Foto Copy Akta Kelahiran | F7: 4 | G7: Foto Copy Akta Kelahiran
A8: 5 | B8: Foto KTP orang tua / wali | F8: 5 | G8: Foto KTP orang tua / wali
A9: 6 | B9: Pas Photo | F9: 6 | G9: Pas Photo
A10: 7 | B10: Foto copy kartu KIS, KIP, PKH, dll | F10: 7 | G10: Foto copy kartu KIS, KIP, PKH, dll
A12: CEK LIST ADMINISTRASI | F12: CEK LIST ADMINISTRASI
A14: NO | B14: DOKUMEN | C14: ADA | D14: TDK | F14: NO | G14: DOKUMEN | H14: ADA | I14: TDK
A15: 1 | B15: Fotocopy Ijazah | F15: 1 | G15: Fotocopy Ijazah
A16: 2 | B16: Surat Keterangan Lulus ( SKL ) | F16: 2 | G16: Surat Keterangan Lulus ( SKL )
A17: 3 | B17: Fotocopy Kartu Keluarga | F17: 3 | G17: Fotocopy Kartu Keluarga
A18: 4 | B18: Foto Copy Akta Kelahiran | F18: 4 | G18: Foto Copy Akta Kelahiran
A19: 5 | B19: Foto KTP orang tua / wali | F19: 5 | G19: Foto KTP orang tua / wali
A20: 6 | B20: Pas Photo | F20: 6 | G20: Pas Photo
A21: 7 | B21: Foto copy kartu KIS, KIP, PKH, dll | F21: 7 | G21: Foto copy kartu KIS, KIP, PKH, dll
A23: CEK LIST ADMINISTRASI | F23: CEK LIST ADMINISTRASI
A25: NO | B25: DOKUMEN | C25: ADA | D25: TDK | F25: NO | G25: DOKUMEN | H25: ADA | I25: TDK
A26: 1 | B26: Fotocopy Ijazah | F26: 1 | G26: Fotocopy Ijazah
A27: 2 | B27: Surat Keterangan Lulus ( SKL ) | F27: 2 | G27: Surat Keterangan Lulus ( SKL )
A28: 3 | B28: Fotocopy Kartu Keluarga | F28: 3 | G28: Fotocopy Kartu Keluarga
A29: 4 | B29: Foto Copy Akta Kelahiran | F29: 4 | G29: Foto Copy Akta Kelahiran
A30: 5 | B30: Foto KTP orang tua / wali | F30: 5 | G30: Foto KTP orang tua / wali | J30: ….........................................
A31: 6 | B31: Pas Photo | F31: 6 | G31: Pas Photo
A32: 7 | B32: Foto copy kartu KIS, KIP, PKH, dll | F32: 7 | G32: Foto copy kartu KIS, KIP, PKH, dll
A34: CEK LIST ADMINISTRASI | F34: CEK LIST ADMINISTRASI
A36: NO | B36: DOKUMEN | C36: ADA | D36: TDK | F36: NO | G36: DOKUMEN | H36: ADA | I36: TDK
A37: 1 | B37: Fotocopy Ijazah | F37: 1 | G37: Fotocopy Ijazah
A38: 2 | B38: Surat Keterangan Lulus ( SKL ) | F38: 2 | G38: Surat Keterangan Lulus ( SKL )
A39: 3 | B39: Fotocopy Kartu Keluarga | F39: 3 | G39: Fotocopy Kartu Keluarga
A40: 4 | B40: Foto Copy Akta Kelahiran | F40: 4 | G40: Foto Copy Akta Kelahiran
A41: 5 | B41: Foto KTP orang tua / wali | F41: 5 | G41: Foto KTP orang tua / wali
A42: 6 | B42: Pas Photo | F42: 6 | G42: Pas Photo
A43: 7 | B43: Foto copy kartu KIS, KIP, PKH, dll | F43: 7 | G43: Foto copy kartu KIS, KIP, PKH, dll
A45: CEK LIST ADMINISTRASI | F45: CEK LIST ADMINISTRASI
A47: NO | B47: DOKUMEN | C47: ADA | D47: TDK | F47: NO | G47: DOKUMEN | H47: ADA | I47: TDK
A48: 1 | B48: Fotocopy Ijazah | F48: 1 | G48: Fotocopy Ijazah
A49: 2 | B49: Surat Keterangan Lulus ( SKL ) | F49: 2 | G49: Surat Keterangan Lulus ( SKL )
...

Sheet CetakKartu (2)
AL1: 196
A6: MATERI TES AKADEMIK PPDB | T6: MATERI TES AKADEMIK PPDB
A7: TAHUN PELAJARAN 2020-2021 | T7: TAHUN PELAJARAN 2020-2021
C10: 1. | D10: Membaca Latin | W10: 1. | X10: Membaca Latin
C11: 2. | D11: Membaca Qur'an | W11: 2. | X11: Membaca Qur'an
C12: 3. | D12: Menulis | W12: 3. | X12: Menulis
C13: 4. | D13: Berhitung | W13: 4. | X13: Berhitung
D15: Waktu Pelaksanaan Tes: | X15: Waktu Pelaksanaan Tes:
D16: 07.30 WITA - Selesai | X16: 07.30 WITA - Selesai
AL23: =AL1+1 -> 197
A28: MATERI TES AKADEMIK PPDB | T28: MATERI TES AKADEMIK PPDB
A29: TAHUN PELAJARAN 2020-2021 | T29: TAHUN PELAJARAN 2020-2021
D32: 1. | E32: Membaca Latin | W32: 1. | X32: Membaca Latin
D33: 2. | E33: Membaca Qur'an | W33: 2. | X33: Membaca Qur'an
D34: 3. | E34: Menulis | W34: 3. | X34: Menulis
D35: 4. | E35: Berhitung | W35: 4. | X35: Berhitung
E37: Waktu Pelaksanaan Tes: | X37: Waktu Pelaksanaan Tes:
E38: 07.30 WITA - Selesai | X38: 07.30 WITA - Selesai
AL45: =AL23+1 -> 198
A50: MATERI TES AKADEMIK PPDB | T50: MATERI TES AKADEMIK PPDB
A51: TAHUN PELAJARAN 2020-2021 | T51: TAHUN PELAJARAN 2020-2021
D54: 1. | E54: Membaca Latin | W54: 1. | X54: Membaca Latin
D55: 2. | E55: Membaca Qur'an | W55: 2. | X55: Membaca Qur'an
D56: 3. | E56: Menulis | W56: 3. | X56: Menulis
D57: 4. | E57: Berhitung | W57: 4. | X57: Berhitung
E59: Waktu Pelaksanaan Tes: | X59: Waktu Pelaksanaan Tes:
E60: 07.30 WITA - Selesai | X60: 07.30 WITA - Selesai

Sheet CetakKartu
A1: PEMERINTAH KABUPATEN LOMBOK TIMUR | T1: PEMERINTAH KABUPATEN LOMBOK TIMUR | AL1: 1
A2: DINAS PENDIDIKAN DAN KEBUDAYAAN | T2: DINAS PENDIDIKAN DAN KEBUDAYAAN
A3: SMP NEGERI 1 SUELA | T3: SMP NEGERI 1 SUELA
A4: Jln. H. M. Makmun Ketangga Kecamatan Suela - Lotim, KP. 83657 | T4: Jln. H. M. Makmun Ketangga Kecamatan Suela - Lotim, KP. 83657
A6: KARTU PENDAFTARAN CALON PPDB | T6: KARTU PENDAFTARAN CALON PPDB
A7: TAHUN PELAJARAN 2022-2023 | T7: TAHUN PELAJARAN 2022-2023
A9: Nomor Peserta | G9: : | H9: =VLOOKUP($AL$1,datakartu[],3,0) -> L | T9: Nomor Peserta | Z9: : | AA9: =H9 -> L
A10: Nama Peserta | G10: : | H10: =VLOOKUP($AL$1,datakartu[],4,0) -> Surabaya, 01 Mei 2014 | T10: Nama Peserta | Z10: : | AA10: =H10 -> Surabaya, 01 Mei 2014
A11: Tempat Tgl. Lahir | G11: : | H11: =CONCATENATE(VLOOKUP($AL$1,datakartu[],2,0)) -> A. ARTIANDRA MANGGALA | T11: Tempat Tgl. Lahir | Z11: : | AA11: =H11 -> A. ARTIANDRA MANGGALA
A12: Asal Sekolah | G12: : | H12: =VLOOKUP($AL$1,datakartu[],7,0) -> SDN 1 MEKARSARI | T12: Asal Sekolah | Z12: : | AA12: =H12 -> SDN 1 MEKARSARI
I13: Suela, 25 Juni 2022 | AB13: Suela, 25 Juni 2022
I14: Ketua Panitia PPDB | AB14: Ketua Panitia PPDB
I17: L. MUH. MUSHLIHUDIN, S.Pd. | AB17: L. MUH. MUSHLIHUDIN, S.Pd.
I18: NIP. 19741231 200901 1 027 | AB18: NIP. 19741231 200901 1 027
B19: *Catatan | U19: =B19 -> *Catatan
A20: 1. Pelaksanaan tes peserta didik baru dilaksanakan pada selasa, 27 Juni 2022 | T20: =A20 -> 1. Pelaksanaan tes peserta didik baru dilaksanakan pada selasa, 27 Juni 2022
A21: 2. Peserta didik yang tidak masuk pada hari tersebut dianggap mengundurkan diri | T21: =A21 -> 2. Peserta didik yang tidak masuk pada hari tersebut dianggap mengundurkan diri
A23: PEMERINTAH KABUPATEN LOMBOK TIMUR | T23: PEMERINTAH KABUPATEN LOMBOK TIMUR | AL23: =AL1+1 -> 2
A24: DINAS PENDIDIKAN DAN KEBUDAYAAN | T24: DINAS PENDIDIKAN DAN KEBUDAYAAN
A25: SMP NEGERI 1 SUELA | T25: SMP NEGERI 1 SUELA
A26: Jln. H. M. Makmun Ketangga Kecamatan Suela - Lotim, KP. 83657 | T26: Jln. H. M. Makmun Ketangga Kecamatan Suela - Lotim, KP. 83657
A28: KARTU PENDAFTARAN CALON PPDB | T28: KARTU PENDAFTARAN CALON PPDB
A29: TAHUN PELAJARAN 2022-2023 | T29: TAHUN PELAJARAN 2022-2023
A31: Nomor Peserta | G31: : | H31: =VLOOKUP($AL$23,datakartu[],3,0) -> L | T31: Nomor Peserta | Z31: : | AA31: =H31 -> L
A32: Nama Peserta | G32: : | H32: =VLOOKUP($AL$23,datakartu[],4,0) -> SUNTALANGU, 25 AGUSTUS 2013 | T32: Nama Peserta | Z32: : | AA32: =H32 -> SUNTALANGU, 25 AGUSTUS 2013
A33: Tempat Tgl. Lahir | G33: : | H33: =CONCATENATE(VLOOKUP($AL$23,datakartu[],2,0)) -> ABDURRAHMAN RIZQI | T33: Tempat Tgl. Lahir | Z33: : | AA33: =H33 -> ABDURRAHMAN RIZQI
A34: Asal Sekolah | G34: : | H34: =VLOOKUP($AL$23,datakartu[],7,0) -> SDN 1 SUNTALANGU | T34: Asal Sekolah | Z34: : | AA34: =H34 -> SDN 1 SUNTALANGU
I35: Suela, 25 Juni 2022 | AB35: Suela, 25 Juni 2022
I36: Ketua Panitia PPDB | AB36: Ketua Panitia PPDB
I39: L. MUH. MUSHLIHUDIN, S.Pd. | AB39: L. MUH. MUSHLIHUDIN, S.Pd.
I40: NIP. 19741231 200901 1 027 | AB40: NIP. 19741231 200901 1 027
B41: =B19 -> *Catatan | U41: =B19 -> *Catatan
A42: =A20 -> 1. Pelaksanaan tes peserta didik baru dilaksanakan pada selasa, 27 Juni 2022 | T42: =A42 -> 1. Pelaksanaan tes peserta didik baru dilaksanakan pada selasa, 27 Juni 2022
A43: =A21 -> 2. Peserta didik yang tidak masuk pada hari tersebut dianggap mengundurkan diri | T43: =A43 -> 2. Peserta didik yang tidak masuk pada hari tersebut dianggap mengundurkan diri
A45: PEMERINTAH KABUPATEN LOMBOK TIMUR | T45: PEMERINTAH KABUPATEN LOMBOK TIMUR | AL45: =AL23+1 -> 3
A46: DINAS PENDIDIKAN DAN KEBUDAYAAN | T46: DINAS PENDIDIKAN DAN KEBUDAYAAN
A47: SMP NEGERI 1 SUELA | T47: SMP NEGERI 1 SUELA
A48: Jln. H. M. Makmun Ketangga Kecamatan Suela - Lotim, KP. 83657 | T48: Jln. H. M. Makmun Ketangga Kecamatan Suela - Lotim, KP. 83657
A50: KARTU PENDAFTARAN CALON PPDB | T50: KARTU PENDAFTARAN CALON PPDB
A51: TAHUN PELAJARAN 2022-2023 | T51: TAHUN PELAJARAN 2022-2023
...

Sheet Sheet2 (3)
A1: PEMERINTAH KABUPATEN LOMOK TIMUR
A2: DINAS PENDIDIKAN DAN KEBUDAYAAN
A3: SMP NEGERI 1 SUELA
A4: Jln. Pariwisata Suela Kecamatan Suela – Lotim KP.83657
A6: DAFTAR HADIR PENGAMBILAN KARTU TES SELEKSI CALON PESERTA DIDIK BARU
A7: TAHUN PELAJARAN 2020-2021
A9: NO | B9: NAMA | C9: SEKOLAH ASAL | D9: PARAF
A10: 1 | B10: M. Ihwan Hazali | C10: MI NW Dasan Baru | D10: 1
A11: 2 | B11: Moh. Haerur Roziqin | C11: MI NW Dasan Baru | D11: 2 | E11: 2
A12: 3 | B12: Sapaatun Mulya | C12: MI MT Suela | D12: 3
A13: 4 | B13: Maudi Aulia | C13: MI NW Pekosong | D13: 4 | E13: 2
A14: 5 | B14: Selvi Aprida | C14: MI NW Pekosong | D14: 5
A15: 6 | B15: Bunga Pika Anggraini | C15: MI NW Suela | D15: 6 | E15: 2
A16: 7 | B16: Mirzakul Al Hadi | C16: MI NW Suela | D16: 7
A17: 8 | B17: Rizkan Harkani | C17: MI NW Suela | D17: 8 | E17: 2
A18: 9 | B18: Yuni Aswirana | C18: MI NW Suela | D18: 9
A19: 10 | B19: Aulia Hasna Wardana | C19: MI Yadinu Dasan Koak | D19: 10 | E19: 2
A20: 11 | B20: Muh. Nur Awwali | C20: MI Yadinu Dasan Koak | D20: 11
A21: 12 | B21: Nayatul Nisfa | C21: MI Yadinu Dasan Koak | D21: 12 | E21: 2
A22: 13 | B22: Zulkahfi | C22: MI Yadinu Dasan Koak | D22: 13
A23: 14 | B23: Abu Karim Askari | C23: SD IT Annajiyah | D23: 14 | E23: 2
A24: 15 | B24: Muhammad Agil Izwan | C24: SD IT Annajiyah | D24: 15
A25: 16 | B25: Nabil Al-Gifari | C25: SD IT Annajiyah | D25: 16 | E25: 2
A26: 17 | B26: Riya Maelani | C26: SDI Darul Hikmah NW Pekosong | D26: 17
A27: 18 | B27: Arya Angga Saputra | C27: SDN 1 Ketangga | D27: 18 | E27: 2
A28: 19 | B28: Baiq Karisa Pratiwi | C28: SDN 1 Selaparang | D28: 19
A29: 20 | B29: Baiq Yola Sartika | C29: SDN 1 Selaparang | D29: 20 | E29: 2
A30: 21 | B30: Cahya Agusriawati | C30: SDN 1 Selaparang | D30: 21
A31: 22 | B31: Hayaton Nupus | C31: SDN 1 Selaparang | D31: 22 | E31: 2
A32: 23 | B32: Irwan Kaswadi | C32: SDN 1 Selaparang | D32: 23
A33: 24 | B33: Lalu Moh. Azril Apandi | C33: SDN 1 Selaparang | D33: 24 | E33: 2
A34: 25 | B34: Moh. Rizki Ikka Wijaya | C34: SDN 1 Selaparang | D34: 25
A35: 26 | B35: Sahrial Patrega | C35: SDN 1 Selaparang | D35: 26 | E35: 2
A36: 27 | B36: Salikin | C36: SDN 1 Selaparang | D36: 27
A37: 28 | B37: Septial Budiatman Abadi | C37: SDN 1 Selaparang | D37: 28 | E37: 2
A38: 29 | B38: Ahmad Farid Lazwardi | C38: SDN 1 Suela | D38: 29
A39: 30 | B39: Anida Ramadani | C39: SDN 1 Suela | D39: 30 | E39: 2
A40: 31 | B40: Baiq Dinia Yasmin Maulidia | C40: SDN 1 SUELA | D40: 31
A41: 32 | B41: Dela Nurfajariah | C41: SDN 1 SUELA | D41: 32 | E41: 2
A42: 33 | B42: Fatya Farah Maolida | C42: SDN 1 SUELA | D42: 33
...

Sheet Sheet2
A1: PEMERINTAH KABUPATEN LOMOK TIMUR
A2: DINAS PENDIDIKAN DAN KEBUDAYAAN
A3: SMP NEGERI 1 SUELA
A4: Jln. Pariwisata Suela Kecamatan Suela – Lotim KP.83657
A6: DAFTAR HADIR PENGAMBILAN KARTU TES SELEKSI CALON PESERTA DIDIK BARU
A7: TAHUN PELAJARAN 2020-2021
A9: NO | B9: NAMA | C9: SEKOLAH ASAL | D9: PARAF
A10: 1 | B10: M. Ihwan Hazali | C10: MI NW Dasan Baru | D10: 1
A11: 2 | B11: Moh. Haerur Roziqin | C11: MI NW Dasan Baru | D11: 2 | E11: 2
A12: 3 | B12: Sapaatun Mulya | C12: MI MT Suela | D12: 3
A13: 4 | B13: Maudi Aulia | C13: MI NW Pekosong | D13: 4 | E13: 2
A14: 5 | B14: Selvi Aprida | C14: MI NW Pekosong | D14: 5
A15: 6 | B15: Bunga Pika Anggraini | C15: MI NW Suela | D15: 6 | E15: 2
A16: 7 | B16: Mirzakul Al Hadi | C16: MI NW Suela | D16: 7
A17: 8 | B17: Rizkan Harkani | C17: MI NW Suela | D17: 8 | E17: 2
A18: 9 | B18: Yuni Aswirana | C18: MI NW Suela | D18: 9
A19: 10 | B19: Aulia Hasna Wardana | C19: MI Yadinu Dasan Koak | D19: 10 | E19: 2
A20: 11 | B20: Muh. Nur Awwali | C20: MI Yadinu Dasan Koak | D20: 11
A21: 12 | B21: Nayatul Nisfa | C21: MI Yadinu Dasan Koak | D21: 12 | E21: 2
A22: 13 | B22: Zulkahfi | C22: MI Yadinu Dasan Koak | D22: 13
A23: 14 | B23: Abu Karim Askari | C23: SD IT Annajiyah | D23: 14 | E23: 2
A24: 15 | B24: Muhammad Agil Izwan | C24: SD IT Annajiyah | D24: 15
A25: 16 | B25: Nabil Al-Gifari | C25: SD IT Annajiyah | D25: 16 | E25: 2
A26: 17 | B26: Riya Maelani | C26: SDI Darul Hikmah NW Pekosong | D26: 17
A27: 18 | B27: Arya Angga Saputra | C27: SDN 1 Ketangga | D27: 18 | E27: 2
A28: 19 | B28: Baiq Karisa Pratiwi | C28: SDN 1 Selaparang | D28: 19
A29: 20 | B29: Baiq Yola Sartika | C29: SDN 1 Selaparang | D29: 20 | E29: 2
A30: 21 | B30: Cahya Agusriawati | C30: SDN 1 Selaparang | D30: 21
A31: 22 | B31: Hayaton Nupus | C31: SDN 1 Selaparang | D31: 22 | E31: 2
A32: 23 | B32: Irwan Kaswadi | C32: SDN 1 Selaparang | D32: 23
A33: 24 | B33: Lalu Moh. Azril Apandi | C33: SDN 1 Selaparang | D33: 24 | E33: 2
A34: 25 | B34: Moh. Rizki Ikka Wijaya | C34: SDN 1 Selaparang | D34: 25
A35: 26 | B35: Sahrial Patrega | C35: SDN 1 Selaparang | D35: 26 | E35: 2
A36: 27 | B36: Salikin | C36: SDN 1 Selaparang | D36: 27
A37: 28 | B37: Septial Budiatman Abadi | C37: SDN 1 Selaparang | D37: 28 | E37: 2
A38: 29 | B38: Ahmad Farid Lazwardi | C38: SDN 1 Suela | D38: 29
A39: 30 | B39: Anida Ramadani | C39: SDN 1 Suela | D39: 30 | E39: 2
A40: 31 | B40: Baiq Dinia Yasmin Maulidia | C40: SDN 1 SUELA | D40: 31
A41: 32 | B41: Dela Nurfajariah | C41: SDN 1 SUELA | D41: 32 | E41: 2
A42: 33 | B42: Fatya Farah Maolida | C42: SDN 1 SUELA | D42: 33
...

Sheet Sheet1
A1: 1 | B1: Dasan Baru, 18-03-2008 | C1: 001 | D1: M. Ihwan Hazali | F1: 18-03-2008 | G1: MI NW Dasan Baru
A2: 33 | B2: Dasan Baru, 18-03-2008 | D2: Moh. Haerur Roziqin | F2: 18-03-2008 | G2: MI NW Dasan Baru
A3: 2 | B3: Suela,12-05-2007 | C3: 002 | D3: Sapaatun Mulya | F3: 39214 | G3: MI MT Suela | P3: Sapaatun Mulya
A4: 4 | B4: Pringgabaya,08-01-2007 | C4: 004 | D4: Maudi Aulia | F4: 39090 | G4: MI NW Pekosong | P4: Maudi Aulia
A5: 7 | B5: Bagek Longgek, 26-08-2008 | C5: 007 | D5: Selvi Aprida | F5: 26-08-2008 | G5: MI NW Pekosong | P5: Selvi Aprida
A6: 3 | B6: Suela, 15-8-2007 | C6: 003 | D6: Bunga Pika Anggraini | F6: 15/8/2007 | G6: MI NW Suela | P6: Bunga Pika Anggraini
A7: 5 | B7: Tanjung,29-07-2008 | C7: 005 | D7: Mirzakul Al Hadi | F7: 29-07-2008 | G7: MI NW Suela | P7: Mirzakul Al Hadi
A8: 6 | B8: Suela,10-08-2008 | C8: 006 | D8: Rizkan Harkani | F8: 39670 | G8: MI NW Suela | P8: Rizkan Harkani
A9: 8 | B9: Suela, 27-06-2008 | C9: 008 | D9: Yuni Aswirana | F9: 39626 | G9: MI NW Suela | P9: Yuni Aswirana
A10: 9 | B10: Dasan Koak, 01-07-2008 | C10: 009 | D10: Aulia Hasna Wardana | F10: 39630 | G10: MI Yadinu Dasan Koak | P10: Aulia Hasna Wardana
A11: 10 | B11: Dasan Koak, 07-01-2008 | C11: 010 | D11: Muh. Nur Awwali | F11: 39454 | G11: MI Yadinu Dasan Koak | P11: Muh. Nur Awwali
A12: 11 | B12: Dasan Koak, 19-03-2009 | C12: 011 | D12: Nayatul Nisfa | F12: 39891 | G12: MI Yadinu Dasan Koak | P12: Nayatul Nisfa
A13: 13 | B13: Dasan Koak, 08-12-2008 | C13: 013 | D13: Zulkahfi | F13: 39790 | G13: MI Yadinu Dasan Koak | P13: Zulkahfi
A14: 14 | B14: Suntalangu, 11-06-2007 | C14: 014 | D14: Abu Karim Askari | F14: 39244 | G14: SD IT Annajiyah | P14: Abu Karim Askari
A15: 16 | B15: Suntalangu, 10-08-2008 | C15: 016 | D15: Muhammad Agil Izwan | F15: 39670 | G15: SD IT Annajiyah | P15: Muhammad Agil Izwan
A16: 17 | B16: Suntalangu, 09-11-2008 | C16: 017 | D16: Nabil Al-Gifari | F16: 39761 | G16: SD IT Annajiyah | P16: Nabil Al-Gifari
A17: 12 | B17: Pringgabaya, 05-05-2008 | C17: 012 | D17: Riya Maelani | F17: 39573 | G17: SDI Darul Hikmah NW Pekosong
A18: 15 | B18: Ketangga, 02-08-2007 | C18: 015 | D18: Arya Angga Saputra | F18: 39296 | G18: SDN 1 Ketangga
A19: 21 | B19: Selaparang, 08-01-2009 | D19: Baiq Karisa Pratiwi | F19: 39821 | G19: SDN 1 Selaparang
A20: 22 | B20: Selaparang, 25-10-2007 | D20: Baiq Yola Sartika | F20: 25-10-2007 | G20: SDN 1 Selaparang
A21: 23 | B21: Selaparang, 18-08-2009 | D21: Cahya Agusriawati | F21: 18-08-2009 | G21: SDN 1 Selaparang
A22: 27 | B22: Selaparang, 01-07-2008 | D22: Hayaton Nupus | F22: 39630 | G22: SDN 1 Selaparang
A23: 28 | B23: Selaparang, 12-02-2008 | D23: Irwan Kaswadi | F23: 39490 | G23: SDN 1 Selaparang
A24: 30 | B24: Selaparang, 03-03-2008 | D24: Lalu Moh. Azril Apandi | F24: 03/03/2008 | G24: SDN 1 Selaparang
A25: 34 | B25: Selaparang, 06-08-2008 | D25: MOH. RIZKI IKKA WIJAYA | F25: 06/08/2008 | G25: SDN 1 Selaparang
A26: 39 | B26: Selaparang, 06-08-2008 | D26: Sahrial Patrega | F26: 39666 | G26: SDN 1 Selaparang
A27: 40 | B27: Selaparang, 11-01-2007 | D27: Salikin | F27: 39093 | G27: SDN 1 Selaparang
A28: 41 | B28: Selaparang, 25-04-2009 | D28: Septial Budiatman Abadi | F28: 25/04/2009 | G28: SDN 1 Selaparang
A29: 18 | B29: Suela, 20-11-2008 | D29: Ahmad Farid Lazwardi | F29: 39772 | G29: SDN 1 Suela
A30: 19 | B30: Suela, 30-08-2008 | D30: Anida Ramadani | F30: 39690 | G30: SDN 1 Suela
A31: 20 | B31: Suela, 28-03-2008 | D31: BAIQ DINIA YASMIN MAULIDIA | F31: 39535 | G31: SDN 1 SUELA
A32: 24 | B32: Suela, 24-08-2007 | D32: DELA NURFAJARIAH | F32: 39318 | G32: SDN 1 SUELA
A33: 25 | B33: Suela, 14-04-2008 | D33: FATYA FARAH MAOLIDA | F33: 39552 | G33: SDN 1 SUELA
A34: 26 | B34: Suela, 03-12-2008 | D34: HAMDIAH | F34: 39785 | G34: SDN 1 SUELA
A35: 29 | B35: Suela, 26-03-2008 | D35: JIHADUL KHAIR | F35: 39533 | G35: SDN 1 SUELA
A36: 31 | B36: Ketangga, 06-04-2007 | D36: Lalu Rizki Afandi | F36: 39178 | G36: SDN 1 Suela
A37: 32 | B37: Suela, 05-03-2005 | D37: M. HENDRA SASMIKA | F37: 39512 | G37: SDN 1 SUELA
A38: 35 | B38: Suela, 01-01-2008 | D38: NITA RATNASARI | F38: 39448 | G38: SDN 1 SUELA
A39: 36 | B39: Suela, 10-07-2007 | D39: Pathin Lanang Jagat | F39: 39639 | G39: SDN 1 SUELA
A40: 37 | B40: Suela, 14-09-2007 | D40: RIMA AMELIA PUTRI | F40: 14/09/2007 | G40: SDN 1 Suela
...

Sheet Form. Tes Baca Tulis
A1: PEMERINTAH KABUPATEN LOMBOK TIMUR
A2: DINAS PENDIDIKAN DAN KEBUDAYAAN
A3: SMP NEGERI 1 SUELA
A4: Jl. H.M.Makmun Kecamatan Suela Kabupaten Lombok Timur KP. 83657
A6: FORMAT PENILAIAN TES SELEKSI CALON MURID BARU
A7: TAHUN PELAJARAN 2025 / 2026
A9: MATA UJI | C9: : Baca Tulis Latin
A11: Nomor | C11: Nama Peserta | D11: L/P | E11: Aspek yang dinilai / Skor | J11: Keterangan
A12: Urut | B12: Peserta | E12: Sangat Lancar | F12: Lancar | G12: Kurang Lancar | H12: Mengeja | I12: Tidak Bisa
A13: 1 | B13: 001 | C13: =DataSiswa!B2 -> A. ARTIANDRA MANGGALA | D13: =DataSiswa!C2 -> L
A14: 2 | B14: 002 | C14: =DataSiswa!B3 -> ABDURRAHMAN RIZQI | D14: =DataSiswa!C3 -> L | J14: 4 = Sangat Lancar
A15: 3 | B15: 003 | C15: =DataSiswa!B4 -> Adrian Ripano | D15: =DataSiswa!C4 -> L | J15: 3 = Lancar
A16: 4 | B16: 004 | C16: =DataSiswa!B5 -> AFDHAL GILANG RAHMAN | D16: =DataSiswa!C5 -> L | J16: 2 = Kurang Lancar
A17: 5 | B17: 005 | C17: =DataSiswa!B6 -> Afriana Ida Melia | D17: =DataSiswa!C6 -> P | J17: 1 = Mengeja
A18: 6 | B18: 006 | C18: =DataSiswa!B7 -> AHYAR RASYIDIN | D18: =DataSiswa!C7 -> L | J18: 0 = Tidak Bisa
A19: 7 | B19: 007 | C19: =DataSiswa!B8 -> AIRIN SABRINA ZUHRI | D19: =DataSiswa!C8 -> P
A20: 8 | B20: 008 | C20: =DataSiswa!B9 -> AJWAD DILARA | D20: =DataSiswa!C9 -> P
A21: 9 | B21: 009 | C21: =DataSiswa!B10 -> AKIVA NAILA | D21: =DataSiswa!C10 -> P
A22: 10 | B22: 010 | C22: =DataSiswa!B11 -> AL PREDO HEIYANTO | D22: =DataSiswa!C11 -> L | J22: Rentang Nilai
A23: 11 | B23: 011 | C23: =DataSiswa!B12 -> ALBY NAZROFI | D23: =DataSiswa!C12 -> L | J23: 4 = 90 - 100
A24: 12 | B24: 012 | C24: =DataSiswa!B13 -> ALFIA SHAFIYYA | D24: =DataSiswa!C13 -> P | J24: 3 = 80 - 90
A25: 13 | B25: 013 | C25: =DataSiswa!B14 -> ALFIAN PRATAMA | D25: =DataSiswa!C14 -> L | J25: 2 = 70 - 80
A26: 14 | B26: 014 | C26: =DataSiswa!B15 -> ALFINA SYAKILA | D26: =DataSiswa!C15 -> P | J26: 1 = 60 - 70
A27: 15 | B27: 015 | C27: =DataSiswa!B16 -> ALIFHA NURUL IDHA | D27: =DataSiswa!C16 -> P | J27: 0 = 0
A28: 16 | B28: 016 | C28: =DataSiswa!B17 -> ALISYA LATIFAH | D28: =DataSiswa!C17 -> P
A29: 17 | B29: 017 | C29: =DataSiswa!B18 -> ALMIRA KISYA ADIBHA | D29: =DataSiswa!C18 -> P
A30: 18 | B30: 018 | C30: =DataSiswa!B19 -> AMELIA NA'IM | D30: =DataSiswa!C19 -> P
A31: 19 | B31: 019 | C31: =DataSiswa!B20 -> AMELIA SEPTIAZZAHRA | D31: =DataSiswa!C20 -> P
A32: 20 | B32: 020 | C32: =DataSiswa!B21 -> AMIAN ABINTANG | D32: =DataSiswa!C21 -> L
A33: 21 | B33: 021 | C33: =DataSiswa!B22 -> AMRU DHAFFA AL-GHAZY | D33: =DataSiswa!C22 -> L
A34: 22 | B34: 022 | C34: =DataSiswa!B23 -> ANDIKA ROHMAN ALMAHFUZ | D34: =DataSiswa!C23 -> L
A35: 23 | B35: 023 | C35: =DataSiswa!B24 -> Andra Dwi Putra | D35: =DataSiswa!C24 -> L
A36: 24 | B36: 024 | C36: =DataSiswa!B25 -> ANGGI WAHYUDI | D36: =DataSiswa!C25 -> L
A37: 25 | B37: 025 | C37: =DataSiswa!B26 -> AQILA DWI RAHAYU PUTRI | D37: =DataSiswa!C26 -> P
A38: 26 | B38: 026 | C38: =DataSiswa!B27 -> ARKAN MISPIRIL AZWA | D38: =DataSiswa!C27 -> L
A39: 27 | B39: 027 | C39: =DataSiswa!B28 -> ARPA ARYA SAPUTRA | D39: =DataSiswa!C28 -> L
... A41: 29 | B41: 029 | C41: =DataSiswa!B30 -> AZIRUL HAQ | D41: =DataSiswa!C30 -> L
G44: Suela, ………………….2025
G45: Penguji
G48: …………………………………………
...

Sheet DAFTAR HADIR SELEKSI
A1: PEMERINTAH KABUPATEN LOMOK TIMUR
A2: DINAS PENDIDIKAN DAN KEBUDAYAAN
A3: SMP NEGERI 1 SUELA
A4: Jln. H. M. Makmun Ketangga - Suela Kecamatan Suela – Lotim KP.83657
A6: DAFTAR HADIR TES SELEKSI CALON MURID BARU
A7: TAHUN PELAJARAN 2025 / 2026
A9: NO | B9: PENDF. | C9: NAMA | D9: SEKOLAH ASAL | E9: TANDA TANGAN
A10: 1 | B10: 001 | C10: =DataSiswa!B2 -> A. ARTIANDRA MANGGALA | D10: =DataSiswa!G2 -> SDN 1 MEKARSARI | E10: 1
A11: 2 | B11: 002 | C11: =DataSiswa!B3 -> ABDURRAHMAN RIZQI | D11: =DataSiswa!G3 -> SDN 1 SUNTALANGU | E11: 2 | F11: 2
A12: 3 | B12: 003 | C12: =DataSiswa!B4 -> Adrian Ripano | D12: =DataSiswa!G4 -> SDN 2 Ketangga | E12: 3
A13: 4 | B13: 004 | C13: =DataSiswa!B5 -> AFDHAL GILANG RAHMAN | D13: =DataSiswa!G5 -> SDN 2 SUNTALANGU | E13: 4 | F13: 2
A14: 5 | B14: 005 | C14: =DataSiswa!B6 -> Afriana Ida Melia | D14: =DataSiswa!G6 -> SDN 2 Ketangga | E14: 5
A15: 6 | B15: 006 | C15: =DataSiswa!B7 -> AHYAR RASYIDIN | D15: =DataSiswa!G7 -> SDN 2 SUELA | E15: 6 | F15: 2
A16: 7 | B16: 007 | C16: =DataSiswa!B8 -> AIRIN SABRINA ZUHRI | D16: =DataSiswa!G8 -> SDN 1 KETANGGA | E16: 7
A17: 8 | B17: 008 | C17: =DataSiswa!B9 -> AJWAD DILARA | D17: =DataSiswa!G9 -> SDN 4 SUNTALANGU | E17: 8 | F17: 2
A18: 9 | B18: 009 | C18: =DataSiswa!B10 -> AKIVA NAILA | D18: =DataSiswa!G10 -> SDN 2 SUNTALANGU | E18: 9
A19: 10 | B19: 010 | C19: =DataSiswa!B11 -> AL PREDO HEIYANTO | D19: =DataSiswa!G11 -> SDN 4 SUNTALANGU | E19: 10 | F19: 2
A20: 11 | B20: 011 | C20: =DataSiswa!B12 -> ALBY NAZROFI | D20: =DataSiswa!G12 -> SDN 2 SUNTALANGU | E20: 11
A21: 12 | B21: 012 | C21: =DataSiswa!B13 -> ALFIA SHAFIYYA | D21: =DataSiswa!G13 -> SDN 2 SUNTALANGU | E21: 12 | F21: 2
A22: 13 | B22: 013 | C22: =DataSiswa!B14 -> ALFIAN PRATAMA | D22: =DataSiswa!G14 -> SDN 1 MEKARSARI | E22: 13
A23: 14 | B23: 014 | C23: =DataSiswa!B15 -> ALFINA SYAKILA | D23: =DataSiswa!G15 -> SDN 4 KETANGGA | E23: 14 | F23: 2
A24: 15 | B24: 015 | C24: =DataSiswa!B16 -> ALIFHA NURUL IDHA | D24: =DataSiswa!G16 -> SDN 2 SUNTALANGU | E24: 15
A25: 16 | B25: 016 | C25: =DataSiswa!B17 -> ALISYA LATIFAH | D25: =DataSiswa!G17 -> SDN 1 SUELA | E25: 16 | F25: 2
A26: 17 | B26: 017 | C26: =DataSiswa!B18 -> ALMIRA KISYA ADIBHA | D26: =DataSiswa!G18 -> SDN 4 SUNTALANGU | E26: 17
A27: 18 | B27: 018 | C27: =DataSiswa!B19 -> AMELIA NA'IM | D27: =DataSiswa!G19 -> SDN 1 SUNTALANGU | E27: 18 | F27: 2
A28: 19 | B28: 019 | C28: =DataSiswa!B20 -> AMELIA SEPTIAZZAHRA | D28: =DataSiswa!G20 -> SDN 1 SUELA | E28: 19
A29: 20 | B29: 020 | C29: =DataSiswa!B21 -> AMIAN ABINTANG | D29: =DataSiswa!G21 -> SDN 3 KETANGGA | E29: 20 | F29: 2
A30: 21 | B30: 021 | C30: =DataSiswa!B22 -> AMRU DHAFFA AL-GHAZY | D30: =DataSiswa!G22 -> SDN 1 SUELA | E30: 21
A31: 22 | B31: 022 | C31: =DataSiswa!B23 -> ANDIKA ROHMAN ALMAHFUZ | D31: =DataSiswa!G23 -> SDN 1 MEKARSARI | E31: 22 | F31: 2
A32: 23 | B32: 023 | C32: =DataSiswa!B24 -> Andra Dwi Putra | D32: =DataSiswa!G24 -> SDN 2 Ketangga | E32: 23
A33: 24 | B33: 024 | C33: =DataSiswa!B25 -> ANGGI WAHYUDI | D33: =DataSiswa!G25 -> SDN 1 MEKARSARI | E33: 24 | F33: 2
A34: 25 | B34: 025 | C34: =DataSiswa!B26 -> AQILA DWI RAHAYU PUTRI | D34: =DataSiswa!G26 -> SDN 3 SUNTALANGU | E34: 25
A35: 26 | B35: 026 | C35: =DataSiswa!B27 -> ARKAN MISPIRIL AZWA | D35: =DataSiswa!G27 -> SDN 3 KETANGGA | E35: 26 | F35: 2
A36: 27 | B36: 027 | C36: =DataSiswa!B28 -> ARPA ARYA SAPUTRA | D36: =DataSiswa!G28 -> SDN 1 SUELA | E36: 27
A37: 28 | B37: 028 | C37: =DataSiswa!B29 -> ARSAD ARSYADI AZIZUROHIM | D37: =DataSiswa!G29 -> SDN 5 KETANGGA | E37: 28 | F37: 2
A38: 29 | B38: 029 | C38: =DataSiswa!B30 -> AZIRUL HAQ | D38: =DataSiswa!G30 -> SDN 1 SUELA | E38: 29
D40: PANITIA
A49: PEMERINTAH KABUPATEN LOMOK TIMUR
A50: DINAS PENDIDIKAN DAN KEBUDAYAAN
A51: SMP NEGERI 1 SUELA
...

Sheet Form. Tes Baca Al Qur'an
A1: PEMERINTAH KABUPATEN LOMBOK TIMUR
A2: DINAS PENDIDIKAN DAN KEBUDAYAAN
A3: SMP NEGERI 1 SUELA
A4: Jl. H.M.Makmun Kecamatan Suela Kabupaten Lombok Timur KP. 83657
A6: FORMAT PENILAIAN TES SELEKSI CALON MURID BARU
A7: TAHUN PELAJARAN 2025 / 2026
A9: MATA UJI | C9: : Membaca Al Qur'an
A11: Nomor | C11: Nama Peserta | D11: L/P | E11: Aspek yang dinilai / Skor | J11: Keterangan
A12: Urut | B12: Peserta | E12: Sangat Lancar | F12: Lancar | G12: Kurang Lancar | H12: Mengeja | I12: Tidak Bisa
A13: 1 | B13: 001 | C13: =DataSiswa!B2 -> A. ARTIANDRA MANGGALA | D13: =DataSiswa!C2 -> L
A14: 2 | B14: 002 | C14: =DataSiswa!B3 -> ABDURRAHMAN RIZQI | D14: =DataSiswa!C3 -> L | J14: 4 = Sangat Lancar
A15: 3 | B15: 003 | C15: =DataSiswa!B4 -> Adrian Ripano | D15: =DataSiswa!C4 -> L | J15: 3 = Lancar
A16: 4 | B16: 004 | C16: =DataSiswa!B5 -> AFDHAL GILANG RAHMAN | D16: =DataSiswa!C5 -> L | J16: 2 = Kurang Lancar
A17: 5 | B17: 005 | C17: =DataSiswa!B6 -> Afriana Ida Melia | D17: =DataSiswa!C6 -> P | J17: 1 = Mengeja
A18: 6 | B18: 006 | C18: =DataSiswa!B7 -> AHYAR RASYIDIN | D18: =DataSiswa!C7 -> L | J18: 0 = Tidak Bisa
A19: 7 | B19: 007 | C19: =DataSiswa!B8 -> AIRIN SABRINA ZUHRI | D19: =DataSiswa!C8 -> P
A20: 8 | B20: 008 | C20: =DataSiswa!B9 -> AJWAD DILARA | D20: =DataSiswa!C9 -> P
A21: 9 | B21: 009 | C21: =DataSiswa!B10 -> AKIVA NAILA | D21: =DataSiswa!C10 -> P
A22: 10 | B22: 010 | C22: =DataSiswa!B11 -> AL PREDO HEIYANTO | D22: =DataSiswa!C11 -> L | J22: Rentang Nilai
A23: 11 | B23: 011 | C23: =DataSiswa!B12 -> ALBY NAZROFI | D23: =DataSiswa!C12 -> L | J23: 4 = 90 - 100
A24: 12 | B24: 012 | C24: =DataSiswa!B13 -> ALFIA SHAFIYYA | D24: =DataSiswa!C13 -> P | J24: 3 = 80 - 90
A25: 13 | B25: 013 | C25: =DataSiswa!B14 -> ALFIAN PRATAMA | D25: =DataSiswa!C14 -> L | J25: 2 = 70 - 80
A26: 14 | B26: 014 | C26: =DataSiswa!B15 -> ALFINA SYAKILA | D26: =DataSiswa!C15 -> P | J26: 1 = 60 - 70
A27: 15 | B27: 015 | C27: =DataSiswa!B16 -> ALIFHA NURUL IDHA | D27: =DataSiswa!C16 -> P | J27: 0 = 0
A28: 16 | B28: 016 | C28: =DataSiswa!B17 -> ALISYA LATIFAH | D28: =DataSiswa!C17 -> P
A29: 17 | B29: 017 | C29: =DataSiswa!B18 -> ALMIRA KISYA ADIBHA | D29: =DataSiswa!C18 -> P
A30: 18 | B30: 018 | C30: =DataSiswa!B19 -> AMELIA NA'IM | D30: =DataSiswa!C19 -> P
A31: 19 | B31: 019 | C31: =DataSiswa!B20 -> AMELIA SEPTIAZZAHRA | D31: =DataSiswa!C20 -> P
A32: 20 | B32: 020 | C32: =DataSiswa!B21 -> AMIAN ABINTANG | D32: =DataSiswa!C21 -> L
A33: 21 | B33: 021 | C33: =DataSiswa!B22 -> AMRU DHAFFA AL-GHAZY | D33: =DataSiswa!C22 -> L
A34: 22 | B34: 022 | C34: =DataSiswa!B23 -> ANDIKA ROHMAN ALMAHFUZ | D34: =DataSiswa!C23 -> L
A35: 23 | B35: 023 | C35: =DataSiswa!B24 -> Andra Dwi Putra | D35: =DataSiswa!C24 -> L
A36: 24 | B36: 024 | C36: =DataSiswa!B25 -> ANGGI WAHYUDI | D36: =DataSiswa!C25 -> L
A37: 25 | B37: 025 | C37: =DataSiswa!B26 -> AQILA DWI RAHAYU PUTRI | D37: =DataSiswa!C26 -> P
A38: 26 | B38: 026 | C38: =DataSiswa!B27 -> ARKAN MISPIRIL AZWA | D38: =DataSiswa!C27 -> L
A39: 27 | B39: 027 | C39: =DataSiswa!B28 -> ARPA ARYA SAPUTRA | D39: =DataSiswa!C28 -> L
... A41: 29 | B41: 029 | C41: =DataSiswa!B30 -> AZIRUL HAQ | D41: =DataSiswa!C30 -> L
G45: Suela, ………………….2025
G46: Penguji
G49: …………………………………………
...

Sheet PENGUMUMAN
A1: No Urut | B1: No. Peserta | C1: Nama Siswa | D1: L/P | E1: Asal Sekolah | F1: KETERANGAN
A2: 1 | B2: 001 | C2: =DataSiswa!B2 -> A. ARTIANDRA MANGGALA | D2: =DataSiswa!C2 -> L | E2: =DataSiswa!D2 -> Surabaya, 01 Mei 2014 | F2: DITERIMA
A3: 2 | B3: 002 | C3: =DataSiswa!B3 -> ABDURRAHMAN RIZQI | D3: =DataSiswa!C3 -> L | E3: =DataSiswa!D3 -> SUNTALANGU, 25 AGUSTUS 2013 | F3: DITERIMA
A4: 3 | B4: 003 | C4: =DataSiswa!B4 -> Adrian Ripano | D4: =DataSiswa!C4 -> L | E4: =DataSiswa!D4 -> Ketangga. 23 April 2014 | F4: DITERIMA
A5: 4 | B5: 004 | C5: =DataSiswa!B5 -> AFDHAL GILANG RAHMAN | D5: =DataSiswa!C5 -> L | E5: =DataSiswa!D5 -> SUNTALANGU, 13 DESEMBER 2013 | F5: DITERIMA
A6: 5 | B6: 005 | C6: =DataSiswa!B6 -> Afriana Ida Melia | D6: =DataSiswa!C6 -> P | E6: =DataSiswa!D6 -> Ketangga, 27 Juni 2013 | F6: DITERIMA
A7: 6 | B7: 006 | C7: =DataSiswa!B7 -> AHYAR RASYIDIN | D7: =DataSiswa!C7 -> L | E7: =DataSiswa!D7 -> SUELA, 29 MEI 2013 | F7: DITERIMA
A8: 7 | B8: 007 | C8: =DataSiswa!B8 -> AIRIN SABRINA ZUHRI | D8: =DataSiswa!C8 -> P | E8: =DataSiswa!D8 -> KETANGGA, 16 SEPTEMBER 2013 | F8: DITERIMA
A9: 8 | B9: 008 | C9: =DataSiswa!B9 -> AJWAD DILARA | D9: =DataSiswa!C9 -> P | E9: =DataSiswa!D9 -> SUNTALANGU, 5 OKTOBER 2013 | F9: DITERIMA
A10: 9 | B10: 009 | C10: =DataSiswa!B10 -> AKIVA NAILA | D10: =DataSiswa!C10 -> P | E10: =DataSiswa!D10 -> SUNTALANGU, 4 MARET 2014 | F10: DITERIMA
A11: 10 | B11: 010 | C11: =DataSiswa!B11 -> AL PREDO HEIYANTO | D11: =DataSiswa!C11 -> L | E11: =DataSiswa!D11 -> SUNTALANGU, 09 MEI 2013 | F11: DITERIMA
A12: 11 | B12: 011 | C12: =DataSiswa!B12 -> ALBY NAZROFI | D12: =DataSiswa!C12 -> L | E12: =DataSiswa!D12 -> SUNTALANGU, 3 DESEMBER 2013 | F12: DITERIMA
A13: 12 | B13: 012 | C13: =DataSiswa!B13 -> ALFIA SHAFIYYA | D13: =DataSiswa!C13 -> P | E13: =DataSiswa!D13 -> SUNTALANGU, 3 MARET 2014 | F13: DITERIMA
... A38: 37 | B38: 037 | C38: =DataSiswa!B38 -> BAIQ JIHAN FARHANA | D38: =DataSiswa!C38 -> P | E38: =DataSiswa!D38 -> Selaparang, 08 Juni 2014 | F38: DITERIMA
A39: 38 | B39: 038 | C39: =DataSiswa!B39 -> BAIQ NUR RIZKA TASYA | D39: =DataSiswa!C39 -> P | E39: =DataSiswa!D39 -> Selaparang, 12 November 2013 | F39: DITERIMA | G39: Afirmasi
A40: 39 | B40: 039 | C40: =DataSiswa!B40 -> BAIQ OKTA NILA SAPITRI | D40: =DataSiswa!C40 -> P | E40: =DataSiswa!D40 -> Selaparang, 04 Oktober 2013 | F40: DITERIMA | G40: Afirmasi
A41: 40 | B41: 040 | C41: =DataSiswa!B41 -> BAIQ PEBRIANI | D41: =DataSiswa!C41 -> P | E41: =DataSiswa!D41 -> Selaparang, 04 Februari 2014 | F41: DITERIMA | G41: Afirmasi
A42: 41 | B42: 041 | C42: =DataSiswa!B42 -> BAIQ SALBY NURIN NAZWA | D42: =DataSiswa!C42 -> P | E42: =DataSiswa!D42 -> Selaparang, 18 Oktober 2013 | F42: DITERIMA | G42: Afirmasi
A43: 42 | B43: 042 | C43: =DataSiswa!B43 -> Baiq Sherina Aeni Putri | D43: =DataSiswa!C43 -> P | E43: =DataSiswa!D43 -> Selaparang, 5 Mei 2014 | F43: DITERIMA
A44: 43 | B44: 043 | C44: =DataSiswa!B44 -> BAIQ VANIA ZAHRANI | D44: =DataSiswa!C44 -> P | E44: =DataSiswa!D44 -> Selaparang, 11 Januari 2014 | F44: DITERIMA
A45: 44 | B45: 044 | C45: =DataSiswa!B45 -> BINTANG ALIF KHALFANI | D45: =DataSiswa!C45 -> L | E45: =DataSiswa!D45 -> SUNTALANGU, 19 APRIL 2014 | F45: DITERIMA
A46: 45 | B46: 045 | C46: =DataSiswa!B46 -> BQ. NABILA ANGGRAENI PUTRI | D46: =DataSiswa!C46 -> P | E46: =DataSiswa!D46 -> Batman, 14 Februari 2014 | F46: DITERIMA
A47: 46 | B47: 046 | C47: =DataSiswa!B47 -> BQ. PADILA AZIZAH | D47: =DataSiswa!C47 -> P | E47: =DataSiswa!D47 -> Batman, 17 Maret 2014 | F47: DITERIMA
A48: 47 | B48: 047 | C48: =DataSiswa!B48 -> BQ. PUTRI MALINI | D48: =DataSiswa!C48 -> P | E48: =DataSiswa!D48 -> SELAPARANG, 19 APRIL 2014 | F48: DITERIMA
A49: 48 | B49: 048 | C49: =DataSiswa!B49 -> CHAERUL IHSAN | D49: =DataSiswa!C49 -> L | E49: =DataSiswa!D49 -> Selaparang, 20 Februari 2014 | F49: DITERIMA
A50: 49 | B50: 049 | C50: =DataSiswa!B50 -> CITRA KHAERONNISA | D50: =DataSiswa!C50 -> P | E50: =DataSiswa!D50 -> SUELA, 21 NOPEMBER 2013 | F50: DITERIMA
A51: 50 | B51: 050 | C51: =DataSiswa!B51 -> DANIEL PUTRA MAULANA | D51: =DataSiswa!C51 -> L | E51: =DataSiswa!D51 -> BATU TINJA, 11 MEI 2013 | F51: DITERIMA
A52: 51 | B52: 051 | C52: =DataSiswa!B52 -> DEA AULIA | D52: =DataSiswa!C52 -> P | E52: =DataSiswa!D52 -> DASAN KOAK, 20 OKTOBER 2013 | F52: DITERIMA
A53: 52 | B53: 052 | C53: =DataSiswa!B53 -> DEEPHIKA HANIFA | D53: =DataSiswa!C53 -> P | E53: =DataSiswa!D53 -> KETANGGA, 8 JUNI 2014 | F53: DITERIMA
A54: 53 | B54: 053 | C54: =DataSiswa!B54 -> DELISA MIFTAQIN | D54: =DataSiswa!C54 -> P | E54: =DataSiswa!D54 -> Suntalangu, 01 Juni 2013 | F54: DITERIMA
... A235: 234 | B235: 234 | C235: =DataSiswa!B235 -> 0 | D235: =DataSiswa!C235 -> 0 | E235: =DataSiswa!D235 -> 0 | F235: DITERIMA

Sheet BERHITUNG
A1: PEMERINTAH KABUPATEN LOMBOK TIMUR
A2: DINAS PENDIDIKAN DAN KEBUDAYAAN
A3: SMP NEGERI 1 SUELA
A4: Jl. H.M.Makmun Kecamatan Suela Kabupaten Lombok Timur KP. 83657
A6: FORMAT PENILAIAN TES SELEKSI CALON MURID BARU
A7: TAHUN PELAJARAN 2025 / 2026
A9: MATA UJI | C9: : BERHITUNG
A11: Nomor | C11: Nama Peserta | D11: L/P | E11: NILAI | J11: SOAL/ KETR.
A12: Urut | B12: Peserta | E12: ( + ) | F12: ( - ) | G12: ( x ) | H12: ( : ) | I12: TOTAL
A13: 1 | B13: 001 | C13: =DataSiswa!B2 -> A. ARTIANDRA MANGGALA | D13: =DataSiswa!C2 -> L | J13: ( + )
A14: 2 | B14: 002 | C14: =DataSiswa!B3 -> ABDURRAHMAN RIZQI | D14: =DataSiswa!C3 -> L | J14: 15 + 9 =
A15: 3 | B15: 003 | C15: =DataSiswa!B4 -> Adrian Ripano | D15: =DataSiswa!C4 -> L | J15: 8 + 17 =
A16: 4 | B16: 004 | C16: =DataSiswa!B5 -> AFDHAL GILANG RAHMAN | D16: =DataSiswa!C5 -> L | J16: 16 + 7 =
A17: 5 | B17: 005 | C17: =DataSiswa!B6 -> Afriana Ida Melia | D17: =DataSiswa!C6 -> P | J17: 15 + 9 =
A18: 6 | B18: 006 | C18: =DataSiswa!B7 -> AHYAR RASYIDIN | D18: =DataSiswa!C7 -> L
A19: 7 | B19: 007 | C19: =DataSiswa!B8 -> AIRIN SABRINA ZUHRI | D19: =DataSiswa!C8 -> P | J19: ( - )
A20: 8 | B20: 008 | C20: =DataSiswa!B9 -> AJWAD DILARA | D20: =DataSiswa!C9 -> P | J20: 20 - 16 =
A21: 9 | B21: 009 | C21: =DataSiswa!B10 -> AKIVA NAILA | D21: =DataSiswa!C10 -> P | J21: 35 -20 =
A22: 10 | B22: 010 | C22: =DataSiswa!B11 -> AL PREDO HEIYANTO | D22: =DataSiswa!C11 -> L | J22: 21 - 6 =
A23: 11 | B23: 011 | C23: =DataSiswa!B12 -> ALBY NAZROFI | D23: =DataSiswa!C12 -> L | J23: 16 - 9 =
A24: 12 | B24: 012 | C24: =DataSiswa!B13 -> ALFIA SHAFIYYA | D24: =DataSiswa!C13 -> P
A25: 13 | B25: 013 | C25: =DataSiswa!B14 -> ALFIAN PRATAMA | D25: =DataSiswa!C14 -> L | J25: ( x )
A26: 14 | B26: 014 | C26: =DataSiswa!B15 -> ALFINA SYAKILA | D26: =DataSiswa!C15 -> P | J26: 8 X 4 =
A27: 15 | B27: 015 | C27: =DataSiswa!B16 -> ALIFHA NURUL IDHA | D27: =DataSiswa!C16 -> P | J27: 7 X 5 =
A28: 16 | B28: 016 | C28: =DataSiswa!B17 -> ALISYA LATIFAH | D28: =DataSiswa!C17 -> P | J28: 6 X 6 =
A29: 17 | B29: 017 | C29: =DataSiswa!B18 -> ALMIRA KISYA ADIBHA | D29: =DataSiswa!C18 -> P | J29: 9 X 3 =
A30: 18 | B30: 018 | C30: =DataSiswa!B19 -> AMELIA NA'IM | D30: =DataSiswa!C19 -> P
A31: 19 | B31: 019 | C31: =DataSiswa!B20 -> AMELIA SEPTIAZZAHRA | D31: =DataSiswa!C20 -> P | J31: ( : )
A32: 20 | B32: 020 | C32: =DataSiswa!B21 -> AMIAN ABINTANG | D32: =DataSiswa!C21 -> L | J32: 36 : 9 =
A33: 21 | B33: 021 | C33: =DataSiswa!B22 -> AMRU DHAFFA AL-GHAZY | D33: =DataSiswa!C22 -> L | J33: 36 : 4 =
A34: 22 | B34: 022 | C34: =DataSiswa!B23 -> ANDIKA ROHMAN ALMAHFUZ | D34: =DataSiswa!C23 -> L | J34: 32 : 8 =
A35: 23 | B35: 023 | C35: =DataSiswa!B24 -> Andra Dwi Putra | D35: =DataSiswa!C24 -> L | J35: 45 : 5 =
A36: 24 | B36: 024 | C36: =DataSiswa!B25 -> ANGGI WAHYUDI | D36: =DataSiswa!C25 -> L
A37: 25 | B37: 025 | C37: =DataSiswa!B26 -> AQILA DWI RAHAYU PUTRI | D37: =DataSiswa!C26 -> P
A38: 26 | B38: 026 | C38: =DataSiswa!B27 -> ARKAN MISPIRIL AZWA | D38: =DataSiswa!C27 -> L
A39: 27 | B39: 027 | C39: =DataSiswa!B28 -> ARPA ARYA SAPUTRA | D39: =DataSiswa!C28 -> L
A40: 28 | B40: 028 | C40: =DataSiswa!B29 -> ARSAD ARSYADI AZIZUROHIM | D40: =DataSiswa!C29 -> L
A41: 29 | B41: 029 | C41: =DataSiswa!B30 -> AZIRUL HAQ | D41: =DataSiswa!C30 -> L
C43: KETERANGAN | G43: Suela, ………………….2025
C44: Nilai 2 jika dijawab dg cepat dan tepat | G44: Penguji
...

Sheet Cetak Kartu  (2)
A1: PEMERINTAH KABUPATEN LOMBOK TIMUR | U1: 224
A2: DINAS PENDIDIKAN DAN KEBUDAYAAN
A3: SMP NEGERI 1 SUELA
A4: Jalan H.M. Makmun ketangga Kec. Suela - Lotim, KP. 83657
A6: KARTU PENDAFTARAN CALON MURID BARU
A7: TAHUN PELAJARAN 2025-2026
B9: Nomor Peserta | G9: : | H9: =VLOOKUP($U$1,datakartu[],2) -> 0
B10: Nama Peserta | G10: : | H10: =VLOOKUP($U$1,datakartu[],3) -> 0
B11: Tempat Tgl. Lahir | G11: : | H11: =VLOOKUP(U1,datakartu[],5) -> 0
B12: Asal Sekolah | G12: : | H12: =VLOOKUP(U1,datakartu[],8) -> #REF!
N13: Suela, 04 Juni 2025
N14: Ketua Panitia SPMB
N17: L.M. MUSHLIHUDIN, S. Pd
N18: NIP. 197412312009011027
B19: *Catatan
B20: 1. Pelaksanaan tes peserta didik baru dilaksanakan pada Kamis, 20 s/d 21 juni 2025
B21: 2. Peserta didik yang tidak masuk pada hari tersebut dianggap mengundurkan diri
A24: PEMERINTAH KABUPATEN LOMBOK TIMUR | U24: =U1+1 -> 225
A25: DINAS PENDIDIKAN DAN KEBUDAYAAN
A26: SMP NEGERI 1 SUELA
A27: Jalan H.M. Makmun ketangga Kec. Suela - Lotim, KP. 83657
A29: KARTU PENDAFTARAN CALON MURID BARU
A30: =A7 -> TAHUN PELAJARAN 2025-2026
B32: Nomor Peserta | G32: : | H32: =VLOOKUP($U$24,datakartu[],2,0) -> 0
B33: Nama Peserta | G33: : | H33: =VLOOKUP($U$24,datakartu[],3,0) -> 0
B34: Tempat Tgl. Lahir | G34: : | H34: =CONCATENATE(VLOOKUP($U$24,datakartu[],5,0))
B35: Asal Sekolah | G35: : | H35: =VLOOKUP($U$24,datakartu[],8,0) -> #REF!
N36: =N13 -> Suela, 04 Juni 2025
N37: Ketua Panitia SPMB
N40: L.M. MUSHLIHUDIN, S. Pd
N41: NIP. 197412312009011027
B42: *Catatan
B43: 1. Pelaksanaan tes peserta didik baru dilaksanakan pada Kamis, 20 s/d 21 juni 2025
B44: 2. Peserta didik yang tidak masuk pada hari tersebut dianggap mengundurkan diri
A46: PEMERINTAH KABUPATEN LOMBOK TIMUR | U46: =U24+1 -> 226
A47: DINAS PENDIDIKAN DAN KEBUDAYAAN
A48: SMP NEGERI 1 SUELA
A49: Jalan H.M. Makmun ketangga Kec. Suela - Lotim, KP. 83657
A51: KARTU PENDAFTARAN CALON MURID BARU
A52: =A30 -> TAHUN PELAJARAN 2025-2026
...
