Workbook
Name OLE_LINK1: VIII!#REF!

Sheet VII
A1: PEMERINTAH KABUPATEN MAJALENGKA
A2: DINAS PENDIDIKAN
A3: SMP NEGERI 3 LEUWIMUNDING
A4: TERAKREDITASI “A” SK.Nomor: 1346/BAN-SM/SK/2021
A5: Alamat : Jalan Raya Parungjaya Leuwimunding Kab. Majalengka 45473 Tlp. (0233) 510066
A7: DAFTAR MURID KELAS VII A
A8: TAHUN PELAJARAN 2026 / 2027
A10: NOMOR | D10: N A M A S I S W A | E10: L / P | F10: KET
A11: URUT | B11: INDUK | C11: NISN
A12: 1 | B12: 2627.7.001 | C12: 0134010603 | D12: ADE YANI | E12: P | F12: SDN 1 BANJARAN | H12: ASIFA REGINA PUTRI | I12: P | J12: MIN 2 CIREBON | K12: A | L12: ADE YANI | M12: 0134010603 | N12: A
A13: 2 | B13: 2627.7.002 | C13: 0142420643 | D13: ALBY LUTHFI FACHRY | E13: L | F13: SDN 1 PARUNGJAYA | H13: ADE YANI | I13: P | J13: SDN 1 BANJARAN | K13: A | L13: ALBY LUTHFI FACHRY | M13: 0142420643 | N13: A
A14: 3 | B14: 2627.7.003 | C14: 0135495721 | D14: ALFILA NURI ADLINA | E14: P | F14: SDN 1 PANINGKIRAN | H14: ALBY LUTHFI FACHRY | I14: L | J14: SDN 1 PARUNGJAYA | K14: A | L14: ALFILA NURI ADLINA | M14: 0135495721 | N14: A
A15: 4 | B15: 2627.7.004 | C15: 0145973961 | D15: ALIKA LUTHFI NAFISZA | E15: P | F15: SDN 2 BANJARAN | H15: ALFILA NURI ADLINA | I15: P | J15: SDN 1 PANINGKIRAN | K15: A | L15: ALIKA LUTHFI NAFISZA | M15: 0145973961 | N15: A
A16: 5 | B16: 2627.7.005 | C16: 0131678930 | D16: ALLYSA AZZAHRA JUNAEDI | E16: P | F16: SDN 3 PRAPATAN | H16: ALIKA LUTHFI NAFISZA | I16: P | J16: SDN 2 BANJARAN | K16: A | L16: ALLYSA AZZAHRA JUNAEDI | M16: 0131678930 | N16: A
A17: 6 | B17: 2627.7.006 | C17: 3124791659 | D17: ANINDYA NUR AGUSTIN | E17: P | F17: SDN 1 PANINGKIRAN | H17: ALLYSA AZZAHRA JUNAEDI | I17: P | J17: SDN 3 PRAPATAN | K17: A | L17: ANINDYA NUR AGUSTIN | M17: 3124791659 | N17: A
A18: 7 | B18: 2627.7.007 | C18: 3141865097 | D18: APIF ALFARIZI | E18: L | F18: SDN 2 PARUNGJAYA | H18: ANINDYA NUR AGUSTIN | I18: P | J18: SDN 1 PANINGKIRAN | K18: A | L18: APIF ALFARIZI | M18: 3141865097 | N18: A
A19: 8 | B19: 2627.7.008 | C19: 0135019953 | D19: ASIFA REGINA PUTRI | E19: P | F19: MIN 2 CIREBON | H19: APIF ALFARIZI | I19: L | J19: SDN 2 PARUNGJAYA | K19: A | L19: ASIFA REGINA PUTRI | M19: 0135019953 | N19: A
A20: 9 | B20: 2627.7.009 | C20: 0122093733 | D20: AUFA RAJANA SANUM | E20: P | F20: SDN SEPAT | H20: AUFA RAJANA SANUM | I20: P | J20: SDN SEPAT | K20: A | L20: AUFA RASANA SAHUM | M20: 0122093733 | N20: A
A21: 10 | B21: 2627.7.010 | C21: 3132438371 | D21: AULIA IZZA TUNNISA | E21: P | F21: SDN 1 WALAHAR | H21: AULIA IZZA TUNNISA | I21: P | J21: SDN 1 WALAHAR | K21: A | L21: AULIA IZZA TUNNISA | M21: 3132438371 | N21: A
A22: 11 | B22: 2627.7.011 | C22: 0148675323 | D22: CAESAR SIGIT MAULANA | E22: L | F22: SDN 1 PARUNGJAYA | H22: CAESAR SIGIT MAULANA | I22: L | J22: SDN 1 PARUNGJAYA | K22: A | L22: CAESAR SIGIT MAULANA | M22: 0148675323 | N22: A
A23: 12 | B23: 2627.7.012 | C23: 3141487579 | D23: DAFFA IBNU HAFIDZ | E23: L | F23: SDN 1 KEDONGDONG | H23: DAFFA IBNU HAFIDZ | I23: L | J23: SDN 1 KEDONGDONG | K23: A | L23: DAFFA IBNU HAFIDZ | M23: 3141487579 | N23: A
... A43: 32 | B43: 2627.7.032 | C43: 0137606515 | D43: ZAHIRA AGUSTIN | E43: P | F43: SDN 3 PRAPATAN | H43: ZAHIRA AGUSTIN | I43: P | J43: SDN 3 PRAPATAN | K43: A | L43: ZAHIRA AGUSTIN | M43: 0137606515 | N43: A
A45: P | B45: 20
A46: L | B46: 12
E47: Leuwimunding, Juli 2026
E48: Wali Kelas
E50: =WLKLS!B1 -> IKA KARTIKA, S.Pd
E51: =WLKLS!C1 -> NIP. 199104112023212000
A55: PEMERINTAH KABUPATEN MAJALENGKA
A56: DINAS PENDIDIKAN
A57: SMP NEGERI 3 LEUWIMUNDING
A58: TERAKREDITASI “A” SK.Nomor: 1346/BAN-SM/SK/2021
A59: Alamat : Jalan Raya Parungjaya Leuwimunding Kab. Majalengka 45473 Tlp. (0233) 510066
A61: DAFTAR MURID KELAS VII B
A62: TAHUN PELAJARAN 2026 / 2027
A64: NOMOR | D64: N A M A S I S W A | E64: L / P | F64: KET
A65: URUT | B65: INDUK | C65: NISN
A66: 1 | B66: 262.7.033 | C66: 0133109791 | D66: AFFAN NUR ARISYAHBILA | E66: L | F66: SDN 2 BANJARAN | H66: AFFAN NUR ARISYAHBIA | I66: L | J66: SDN 2 BANJARAN | K66: B | L66: AFFAN NUR ARISYAHBIA | M66: 0133109791 | N66: B
A67: 2 | B67: 2627.7.034 | C67: 0143337147 | D67: AFIFAH AYUNDA | E67: P | F67: SDN 2 WALAHAR | H67: AFIFAH AYUNDA | I67: P | J67: SDN 2 WALAHAR | K67: B | L67: AFIFAH AYUNDA | M67: 0143337147 | N67: B
A68: 3 | B68: 2627.7.035 | C68: 0143828896 | D68: ALIFKHA DINIA AZ ZAHRA | E68: P | F68: SDN 1 GEYONGAN (PPA) | H68: ALIFKHA DINIA AZ ZAHRA | I68: P | J68: SDN 1 GEYONGAN (PPA) | K68: B | L68: ALIFKHA DINIA AZ ZAHRA | M68: 0143828896 | N68: B
...

Sheet VIII
A1: PEMERINTAH KABUPATEN MAJALENGKA
A2: DINAS PENDIDIKAN
A3: SMP NEGERI 3 LEUWIMUNDING
A4: TERAKREDITASI “A” SK.Nomor: 1346/BAN-SM/SK/2021
A5: Alamat : Jalan Raya Parungjaya Leuwimunding Kab. Majalengka 45473 Tlp. (0233) 510066
A7: DAFTAR MURID KELAS VIII A
A8: TAHUN PELAJARAN 2026 / 2027
A10: NOMOR | D10: N A M A S I S W A | E10: L / P | F10: KELAS LAMA
A11: URUT | B11: INDUK | C11: NISN
A12: 1 | B12: 2526.7.060 | C12: 0124860827 | D12: ADAM RAMADHAN | E12: L | F12: VII C | G12: 1 | H12: 2526.7.002 | I12: 3121366237 | J12: AJI HERLAMBANG | K12: L | L12: VII A | M12: A | N12: 2526.7.002 | O12: 3121366237 | P12: AJI HERLAMBANG | Q12: L | R12: VII A | S12: A | U12: 1 | V12: 2526.7.002 | W12: 3121366237 | X12: AJI HERLAMBANG | Y12: L | Z12: VII A | AC12: 1 | AD12: 2526.7.001 | AE12: 3123204104 | AF12: ADI SAPUTRA | AG12: L | AH12: VII A
A13: 2 | B13: 2526.7.114 | C13: 3136402419 | D13: ADHELIA ZAHRA NUR HAFISYAH | E13: P | F13: VII E | G13: 2 | H13: 2526.7.016 | I13: 3127443097 | J13: KUMAEDI | K13: L | L13: VII A | M13: A | N13: 2526.7.003 | O13: 3125085140 | P13: ALDI HIDAYAT SAPUTRA | Q13: L | R13: VII A | S13: B | U13: 2 | V13: 2526.7.003 | W13: 3125085140 | X13: ALDI HIDAYAT SAPUTRA | Y13: L | Z13: VII A | AC13: 2 | AD13: 2526.7.002 | AE13: 3121366237 | AF13: AJI HERLAMBANG | AG13: L | AH13: VII A
A14: 3 | B14: 2526.7.141 | D14: AERA ZASKIA PUTRI | E14: P | F14: VII F | G14: 3 | H14: 2526.7.037 | I14: 0128530581 | J14: ASEP HERMANSYAH | K14: L | L14: VII B | M14: A | N14: 2526.7.006 | O14: 3123491428 | P14: DEDEN HAMDANI | Q14: L | R14: VII A | S14: C | U14: 3 | V14: 2526.7.006 | W14: 3123491428 | X14: DEDEN HAMDANI | Y14: L | Z14: VII A | AC14: 3 | AD14: 2526.7.003 | AE14: 3125085140 | AF14: ALDI HIDAYAT SAPUTRA | AG14: L | AH14: VII A
A15: 4 | B15: 2526.7.140 | D15: AFZAL SYAHPUTRA | E15: L | F15: VII F | G15: 4 | H15: 2526.7.047 | I15: 0126488139 | J15: MUHAMAD PADLI AL RIZKY | K15: L | L15: VII B | M15: A | N15: 2526.7.011 | O15: 3128181864 | P15: GUSTI WARDANA | Q15: L | R15: VII A | S15: D | U15: 4 | V15: 2526.7.011 | W15: 3128181864 | X15: GUSTI WARDANA | Y15: L | Z15: VII A | AC15: 4 | AD15: 2526.7.005 | AE15: 0127928792 | AF15: BENING | AG15: P | AH15: VII A
A16: 5 | B16: 2526.7.116 | C16: 3129631380 | D16: AHMAD NIZAM MUFASIR | E16: L | F16: VII E | G16: 5 | H16: 2526.7.060 | I16: 0124860827 | J16: ADAM RAMADHAN | K16: L | L16: VII C | M16: A | N16: 2526.7.014 | P16: IRWAN TRI SETIAWAN | Q16: L | R16: VII A | S16: E | U16: 5 | V16: 2526.7.014 | X16: IRWAN TRI SETIAWAN | Y16: L | Z16: VII A | AC16: 5 | AD16: 2526.7.006 | AE16: 3123491428 | AF16: DEDEN HAMDANI | AG16: L | AH16: VII A
A17: 26 | B17: 2526.7.061 | C17: 01289020075 | D17: AHMAD RIVALDI | E17: L | F17: VII C | G17: 6 | H17: 2526.7.069 | I17: 0125183340 | J17: GENGGAM JAGADT AGAMI | K17: L | L17: VII C | M17: A | N17: 2526.7.016 | O17: 3127443097 | P17: KUMAEDI | Q17: L | R17: VII A | S17: A | U17: 6 | V17: 2526.7.016 | W17: 3127443097 | X17: KUMAEDI | Y17: L | Z17: VII A | AC17: 6 | AD17: 2526.7.007 | AF17: DENIS ALNA A | AG17: L | AH17: VII A
A18: 6 | B18: 2526.7.002 | C18: 3121366237 | D18: AJI HERLAMBANG | E18: L | F18: VII A | G18: 7 | H18: 2526.7.089 | I18: 3121361780 | J18: AZAM | K18: L | L18: VII D | M18: A | N18: 2526.7.018 | O18: 0134105339 | P18: MUHAMMAD HAIQAL | Q18: L | R18: VII A | S18: B | U18: 7 | V18: 2526.7.018 | W18: 0134105339 | X18: MUHAMMAD HAIQAL | Y18: L | Z18: VII A | AC18: 7 | AD18: 2526.7.008 | AE18: 3124200897 | AF18: DHEVANO SEPTIAN | AG18: L | AH18: VII A
A19: 7 | B19: 2526.7.118 | C19: 0134649316 | D19: ALIYA NOVITASARI | E19: P | F19: VII E | G19: 8 | H19: 2526.7.116 | I19: 3129631380 | J19: AHMAD NIZAM MUFASIR | K19: L | L19: VII E | M19: A | N19: 2526.7.019 | O19: 3134527476 | P19: MUHAMMAD RIZKY | Q19: L | R19: VII A | S19: C | U19: 8 | V19: 2526.7.019 | W19: 3134527476 | X19: MUHAMMAD RIZKY | Y19: L | Z19: VII A | AC19: 8 | AD19: 2526.7.009 | AE19: 3136707471 | AF19: DZAKIYAH AFIFATUNNISA | AG19: P | AH19: VII A
A20: 8 | B20: 2526.7.062 | C20: 0129207827 | D20: ALYA OKTAVIANI | E20: P | F20: VII C | G20: 9 | H20: 2526.7.126 | I20: 0135349455 | J20: KHAYRUN KHOYYUM | K20: L | L20: VII E | M20: A | N20: 2526.7.020 | P20: MUHAMMAD ZIAN RIFKY | Q20: L | R20: VII A | S20: D | U20: 9 | V20: 2526.7.020 | X20: MUHAMMAD ZIAN RIFKY | Y20: L | Z20: VII A | AC20: 9 | AD20: 2526.7.010 | AE20: 3126969319 | AF20: FITRA ANGGRAENI | AG20: P | AH20: VII A
A21: 9 | B21: 2526.7.036 | C21: 3133689020 | D21: AQYLA PUTRI AZZAHRA | E21: P | F21: VII B | G21: 10 | H21: 2526.7.140 | J21: AFZAL SYAHPUTRA | K21: L | L21: VII F | M21: A | N21: 2526.7.027 | O21: 3131123912 | P21: RIEZKY MARSYAH FADHIELLA | Q21: L | R21: VII A | S21: E | U21: 10 | V21: 2526.7.027 | W21: 3131123912 | X21: RIEZKY MARSYAH FADHIELLA | Y21: L | Z21: VII A | AC21: 10 | AD21: 2526.7.011 | AE21: 3128181864 | AF21: GUSTI WARDANA | AG21: L | AH21: VII A
A22: 10 | B22: 2526.7.037 | C22: 0128530581 | D22: ASEP HERMANSYAH | E22: L | F22: VII B | G22: 11 | H22: 2526.7.157 | I22: 0124085399 | J22: MUHAMMAD FADILLAH | K22: L | L22: VII F | M22: A | N22: 2526.7.008 | O22: 3124200897 | P22: DHEVANO SEPTIAN | Q22: L | R22: VII A | U22: 11 | V22: 2526.7.008 | W22: 3124200897 | X22: DHEVANO SEPTIAN | Y22: L | Z22: VII A | AC22: 11 | AD22: 2526.7.012 | AE22: 127058104 | AF22: HERLITA VIANI | AG22: P | AH22: VII A
A23: 11 | B23: 2526.7.089 | C23: 3121361780 | D23: AZAM | E23: L | F23: VII D | G23: 12 | H23: 2526.7.099 | I23: 3126231610 | J23: INDRA PRAMANA | K23: L | L23: VII D | M23: A | N23: 2526.7.005 | O23: 0127928792 | P23: BENING | Q23: P | R23: VII A | S23: A | U23: 12 | V23: 2526.7.005 | W23: 0127928792 | X23: BENING | Y23: P | Z23: VII A | AC23: 12 | AD23: 2526.7.014 | AF23: IRWAN TRI SETIAWAN | AG23: L | AH23: VII A
A24: 12 | B24: 2526.7.005 | C24: 0127928792 | D24: BENING | E24: P | F24: VII A | G24: 13 | H24: 2526.7.103 | I24: 0127235926 | J24: MUHAMAD RIZKI MAULANA | K24: L | L24: VII D | M24: A | N24: 2526.7.009 | O24: 3136707471 | P24: DZAKIYAH AFIFATUNNISA | Q24: P | R24: VII A | S24: B | U24: 13 | V24: 2526.7.009 | W24: 3136707471 | X24: DZAKIYAH AFIFATUNNISA | Y24: P | Z24: VII A | AC24: 13 | AD24: 2526.7.015 | AF24: KHOERRUNISA SULISTINAR | AG24: P | AH24: VII A
A25: 13 | B25: 2526.7.092 | C25: 0135862448 | D25: CHATRINE PRISCILLIA NATASYA | E25: P | F25: VII D | G25: 14 | H25: 2526.7.028 | I25: 3133379584 | J25: RISKY ADITYA | K25: L | L25: VII A | M25: A | N25: 2526.7.012 | O25: 127058104 | P25: HERLITA VIANI | Q25: P | R25: VII A | S25: C | U25: 14 | V25: 2526.7.012 | W25: 127058104 | X25: HERLITA VIANI | Y25: P | Z25: VII A | AC25: 14 | AD25: 2526.7.016 | AE25: 3127443097 | AF25: KUMAEDI | AG25: L | AH25: VII A
A26: 14 | B26: 2526.7.097 | C26: 0139468302 | D26: FEBRI MAULIDINA PUTRI | E26: P | F26: VII D | G26: 15 | H26: 2526.7.110 | I26: 3125143544 | J26: RIO RAMADHAN | K26: L | L26: VII D | M26: B | N26: 2526.7.017 | O26: 3137724690 | P26: LISNA RAHMAWATI | Q26: P | R26: VII A | S26: D | U26: 15 | V26: 2526.7.017 | W26: 3137724690 | X26: LISNA RAHMAWATI | Y26: P | Z26: VII A | AC26: 15 | AD26: 2526.7.017 | AE26: 3137724690 | AF26: LISNA RAHMAWATI | AG26: P | AH26: VII A
A27: 15 | B27: 2526.7.069 | C27: 0125183340 | D27: GENGGAM JAGADT AGAMI | E27: L | F27: VII C | G27: 16 | H27: 2526.7.164 | I27: 0115203867 | J27: SAEFUL MAULADI | K27: L | L27: VII F | M27: A | N27: 2526.7.021 | O27: 3123599839 | P27: NAJUWA NUR WARDAHTI | Q27: P | R27: VII A | S27: E | U27: 16 | V27: 2526.7.021 | W27: 3123599839 | X27: NAJUWA NUR WARDAHTI | Y27: P | Z27: VII A | AC27: 16 | AD27: 2526.7.018 | AE27: 0134105339 | AF27: MUHAMMAD HAIQAL | AG27: L | AH27: VII A
A28: 16 | B28: 2526.7.099 | C28: 3126231610 | D28: INDRA PRAMANA | E28: L | F28: VII D | G28: 1 | H28: 2526.7.005 | I28: 0127928792 | J28: BENING | K28: P | L28: VII A | M28: A | N28: 2526.7.022 | O28: 0129643616 | P28: NAURA AUNI FAQIHAH | Q28: P | R28: VII A | S28: A | U28: 17 | V28: 2526.7.022 | W28: 0129643616 | X28: NAURA AUNI FAQIHAH | Y28: P | Z28: VII A | AC28: 17 | AD28: 2526.7.019 | AE28: 3134527476 | AF28: MUHAMMAD RIZKY | AG28: L | AH28: VII A
A29: 17 | B29: 2526.7.126 | C29: 0135349455 | D29: KHAYRUN KHOYYUM | E29: L | F29: VII E | G29: 2 | H29: 2526.7.022 | I29: 0129643616 | J29: NAURA AUNI FAQIHAH | K29: P | L29: VII A | M29: A | N29: 2526.7.023 | O29: 3132819988 | P29: NIA AMANDA | Q29: P | R29: VII A | S29: B | U29: 18 | V29: 2526.7.023 | W29: 3132819988 | X29: NIA AMANDA | Y29: P | Z29: VII A | AC29: 18 | AD29: 2526.7.020 | AF29: MUHAMMAD ZIAN RIFKY | AG29: L | AH29: VII A
A30: 18 | B30: 2526.7.016 | C30: 3127443097 | D30: KUMAEDI | E30: L | F30: VII A | G30: 3 | H30: 2526.7.030 | I30: 0122367887 | J30: SERINA AFIKA SARI | K30: P | L30: VII A | M30: A | N30: 2526.7.024 | O30: 0127200054 | P30: NUR ATIKA | Q30: P | R30: VII A | S30: C | U30: 19 | V30: 2526.7.024 | W30: 0127200054 | X30: NUR ATIKA | Y30: P | Z30: VII A | AC30: 19 | AD30: 2526.7.021 | AE30: 3123599839 | AF30: NAJUWA NUR WARDAHTI | AG30: P | AH30: VII A
A31: 19 | B31: 2526.7.100 | C31: 0136766678 | D31: MADONA ARLINA | E31: P | F31: VII D | G31: 4 | H31: 2526.7.036 | I31: 3133689020 | J31: AQYLA PUTRI AZZAHRA | K31: P | L31: VII B | M31: A | N31: 2526.7.025 | O31: 0128202184 | P31: PRADITA DESVINTA ANGGRAINI | Q31: P | R31: VII A | S31: D | U31: 20 | V31: 2526.7.025 | W31: 0128202184 | X31: PRADITA DESVINTA ANGGRAINI | Y31: P | Z31: VII A | AC31: 20 | AD31: 2526.7.022 | AE31: 0129643616 | AF31: NAURA AUNI FAQIHAH | AG31: P | AH31: VII A
A32: 20 | B32: 2526.7.127 | C32: 0127506086 | D32: MARWAH KURNIASIH | E32: P | F32: VII E | G32: 5 | H32: 2526.7.062 | I32: 0129207827 | J32: ALYA OKTAVIANI | K32: P | L32: VII C | M32: A | N32: 2526.7.029 | O32: 0103025386 | P32: SALSABILAH RAHAYU | Q32: P | R32: VII A | S32: E | U32: 21 | V32: 2526.7.029 | W32: 0103025386 | X32: SALSABILAH RAHAYU | Y32: P | Z32: VII A | AC32: 21 | AD32: 2526.7.023 | AE32: 3132819988 | AF32: NIA AMANDA | AG32: P | AH32: VII A
A33: 21 | B33: 2526.7.047 | C33: 0126488139 | D33: MUHAMAD PADLI AL RIZKY | E33: L | F33: VII B | G33: 6 | H33: 2526.7.078 | J33: NAFILLA USWATUN HASANAH | K33: P | L33: VII C | M33: A | N33: 2526.7.030 | O33: 0122367887 | P33: SERINA AFIKA SARI | Q33: P | R33: VII A | S33: A | U33: 22 | V33: 2526.7.030 | W33: 0122367887 | X33: SERINA AFIKA SARI | Y33: P | Z33: VII A | AC33: 22 | AD33: 2526.7.024 | AE33: 0127200054 | AF33: NUR ATIKA | AG33: P | AH33: VII A
A34: 22 | B34: 2526.7.103 | C34: 0127235926 | D34: MUHAMAD RIZKI MAULANA | E34: L | F34: VII D | G34: 7 | H34: 2526.7.088 | I34: 0124934991 | J34: AURA OKTAVIA | K34: P | L34: VII D | M34: E | N34: 2526.7.031 | O34: 0128219250 | P34: SIFFANI NUR AFINAH | Q34: P | R34: VII A | S34: B | U34: 23 | V34: 2526.7.031 | W34: 0128219250 | X34: SIFFANI NUR AFINAH | Y34: P | Z34: VII A | AC34: 23 | AD34: 2526.7.025 | AE34: 0128202184 | AF34: PRADITA DESVINTA ANGGRAINI | AG34: P | AH34: VII A
A35: 23 | B35: 2526.7.157 | C35: 0124085399 | D35: MUHAMMAD FADILLAH | E35: L | F35: VII F | G35: 8 | H35: 2526.7.100 | I35: 0136766678 | J35: MADONA ARLINA | K35: P | L35: VII D | M35: A | N35: 2526.7.167 | O35: 0133647456 | P35: FEBBY NUR HAYATI PUTRI | Q35: P | R35: VII A | S35: C | U35: 24 | V35: 2526.7.167 | W35: 0133647456 | X35: FEBBY NUR HAYATI PUTRI | Y35: P | Z35: VII A | AC35: 24 | AD35: 2526.7.026 | AE35: 3124785721 | AF35: RENATA SASKIA NURVITRI | AG35: P | AH35: VII A
A36: 24 | B36: 2526.7.078 | D36: NAFILLA USWATUN HASANAH | E36: P | F36: VII C | G36: 9 | H36: 2526.7.114 | I36: 3136402419 | J36: ADHELIA ZAHRA NUR HAFISYAH | K36: P | L36: VII E | M36: A | N36: 2526.7.168 | O36: 0121941284 | P36: BEBBY BALQIS KAYLA PUTRI | Q36: P | R36: VII A | S36: D | U36: 25 | V36: 2526.7.168 | W36: 0121941284 | X36: BEBBY BALQIS KAYLA PUTRI | Y36: P | Z36: VII A | AC36: 25 | AD36: 2526.7.027 | AE36: 3131123912 | AF36: RIEZKY MARSYAH FADHIELLA | AG36: L | AH36: VII A
A37: 25 | B37: 2526.7.022 | C37: 0129643616 | D37: NAURA AUNI FAQIHAH | E37: P | F37: VII A | G37: 10 | H37: 2526.7.127 | I37: 0127506086 | J37: MARWAH KURNIASIH | K37: P | L37: VII E | M37: A | N37: 2526.7.033 | O37: 3124279636 | P37: ABOY YOPAN FARIZI | Q37: L | R37: VII B | U37: 26 | V37: 2526.7.033 | W37: 3124279636 | X37: ABOY YOPAN FARIZI | Y37: L | Z37: VII B | AC37: 26 | AD37: 2526.7.028 | AE37: 3133379584 | AF37: RISKY ADITYA | AG37: L | AH37: VII A
A38: 27 | B38: 2526.7.028 | C38: 3133379584 | D38: RISKY ADITYA | E38: L | F38: VII A | G38: 11 | H38: 2526.7.141 | J38: AERA ZASKIA PUTRI | K38: P | L38: VII F | M38: A | N38: 2526.7.037 | O38: 0128530581 | P38: ASEP HERMANSYAH | Q38: L | R38: VII B | S38: A | U38: 27 | V38: 2526.7.037 | W38: 0128530581 | X38: ASEP HERMANSYAH | Y38: L | Z38: VII B | AC38: 27 | AD38: 2526.7.029 | AE38: 0103025386 | AF38: SALSABILAH RAHAYU | AG38: P | AH38: VII A
A39: 28 | B39: 2526.7.164 | C39: 0115203867 | D39: SAEFUL MAULADI | E39: L | F39: VII F | G39: 12 | H39: 2526.7.118 | I39: 0134649316 | J39: ALIYA NOVITASARI | K39: P | L39: VII E | M39: A | N39: 2526.7.039 | O39: 0125286348 | P39: FAHRI DAIRUL ANWAR | Q39: L | R39: VII B | S39: B | U39: 28 | V39: 2526.7.039 | W39: 0125286348 | X39: FAHRI DAIRUL ANWAR | Y39: L | Z39: VII B | AC39: 28 | AD39: 2526.7.030 | AE39: 0122367887 | AF39: SERINA AFIKA SARI | AG39: P | AH39: VII A
A40: 29 | B40: 2526.7.165 | C40: 3131684734 | D40: SASKIA NURUL SALSABILA | E40: P | F40: VII F | G40: 13 | H40: 2526.7.092 | I40: 0135862448 | J40: CHATRINE PRISCILLIA NATASYA | K40: P | L40: VII D | M40: A | N40: 2526.7.041 | P40: GALANG SAPUTRA | Q40: L | R40: VII B | S40: C | U40: 29 | V40: 2526.7.041 | X40: GALANG SAPUTRA | Y40: L | Z40: VII B | AC40: 29 | AD40: 2526.7.031 | AE40: 0128219250 | AF40: SIFFANI NUR AFINAH | AG40: P | AH40: VII A
A41: 30 | B41: 2526.7.030 | C41: 0122367887 | D41: SERINA AFIKA SARI | E41: P | F41: VII A | G41: 14 | H41: 2526.7.083 | I41: 0128672217 | J41: TASYA NABILA | K41: P | L41: VII C | M41: A | N41: 2526.7.044 | O41: 3126174300 | P41: MOCHAMAD FABRIZIO | Q41: L | R41: VII B | S41: D | U41: 30 | V41: 2526.7.044 | W41: 3126174300 | X41: MOCHAMAD FABRIZIO | Y41: L | Z41: VII B | AC41: 30 | AD41: 2526.7.032 | AE41: 3123952029 | AF41: YAKUB NURAROFA | AG41: L | AH41: VII A
A42: 31 | B42: 2526.7.083 | C42: 0128672217 | D42: TASYA NABILA | E42: P | F42: VII C | G42: 15 | H42: 2526.7.113 | I42: 0124370054 | J42: TRI MULYA DEWI | K42: P | L42: VII D | M42: A | N42: 2526.7.046 | O42: 0122528964 | P42: MUHAMAD AREL | Q42: L | R42: VII B | S42: E | U42: 31 | V42: 2526.7.046 | W42: 0122528964 | X42: MUHAMAD AREL | Y42: L | Z42: VII B | AC42: 31 | AD42: 2526.7.167 | AE42: 0133647456 | AF42: FEBBY NUR HAYATI PUTRI | AG42: P | AH42: VII A
...

Sheet IX
A1: PEMERINTAH KABUPATEN MAJALENGKA
A2: DINAS PENDIDIKAN
A3: SMP NEGERI 3 LEUWIMUNDING
A4: TERAKREDITASI “A” SK.Nomor: 1346/BAN-SM/SK/2021
A5: Alamat : Jalan Raya Parungjaya Leuwimunding Kab. Majalengka 45473 Tlp. (0233) 510066
A7: DAFTAR MURID KELAS IX A
A8: TAHUN PELAJARAN 2026 / 2027
A10: NOMOR | D10: N A M A S I S W A | E10: L / P | F10: KETERANGAN
A11: URUT | B11: INDUK | C11: NISN | F11: ASAL KELAS | Q11: NIS | R11: NISN | S11: NAMA | T11: L/P | U11: KLS
A12: 1 | B12: 2425.7.001 | C12: 0114335435 | D12: AGIF RIFKI | E12: L | F12: VIIIE | H12: 1 | P12: 1 | Q12: 2324.7.008 | R12: 0103230220 | S12: BILQIS AMELIA | T12: P | U12: VIIIB | V12: A
A13: 2 | B13: 2425.7.033 | C13: 3122095715 | D13: AIZLA NUR ZAHRA | E13: P | F13: VIIIA | H13: 2 | P13: 2 | Q13: 2425.7.001 | R13: 0114335435 | S13: AGIF RIFKI | T13: L | U13: VIIIE | V13: A
A14: 3 | B14: 2425.7.002 | C14: 0128544312 | D14: ALICE FIRMANSYAH | E14: P | F14: VIIIA | H14: 3 | P14: 3 | Q14: 2425.7.002 | R14: 0128544312 | S14: ALICE FIRMANSYAH | T14: P | U14: VIIIA | V14: A
A15: 4 | B15: 2425.7.003 | C15: 0129145235 | D15: ALIYA FITHROTUN NISA | E15: P | F15: VIIID | H15: 4 | P15: 4 | Q15: 2425.7.003 | R15: 0129145235 | S15: ALIYA FITHROTUN NISA | T15: P | U15: VIIID | V15: A
A16: 5 | B16: 2425.7.004 | C16: 0119597475 | D16: ALVIAN | E16: L | F16: VIIIA | H16: 5 | P16: 5 | Q16: 2425.7.004 | R16: 0119597475 | S16: ALVIAN | T16: L | U16: VIIIA | V16: A
A17: 6 | B17: 2425.7.005 | C17: 0117061831 | D17: ALZANETA FITRIA NOVANTI | E17: P | F17: VIIIB | H17: 6 | P17: 6 | Q17: 2425.7.005 | R17: 0117061831 | S17: ALZANETA FITRIA NOVANTI | T17: P | U17: VIIIB | V17: A
A18: 7 | B18: 2425.7.006 | C18: 0117575190 | D18: AMANDA AZILLAH RAHMA | E18: P | F18: VIIIC | H18: 7 | P18: 7 | Q18: 2425.7.006 | R18: 0117575190 | S18: AMANDA AZILLAH RAHMA | T18: P | U18: VIIIC | V18: A
A19: 8 | B19: 2425.7.034 | C19: 0124197972 | D19: AMANDA DINDA MARISYA | E19: P | F19: VIIIC | H19: 8 | P19: 8 | Q19: 2425.7.007 | R19: 3121857541 | S19: ANASTASYA FUTRI | T19: P | U19: VIIIB | V19: A
A20: 9 | B20: 2425.7.007 | C20: 3121857541 | D20: ANASTASYA FUTRI | E20: P | F20: VIIIB | H20: 9 | P20: 9 | Q20: 2425.7.008 | R20: 0116912605 | S20: ANDITO PRATAMA | T20: L | U20: VIIIE | V20: A
A21: 10 | B21: 2425.7.008 | C21: 0116912605 | D21: ANDITO PRATAMA | E21: L | F21: VIIIE | H21: 10 | P21: 10 | Q21: 2425.7.009 | R21: 0127241722 | S21: AYUNDHA PUTRI WIJAYA | T21: P | U21: VIIIE | V21: A
A22: 11 | B22: 2425.7.035 | C22: 0126904354 | D22: ANGGUN AFRITA | E22: P | F22: VIIID | H22: 11 | P22: 11 | Q22: 2425.7.010 | R22: 0115771531 | S22: DANI LUKMAN SUMITRO | T22: L | U22: VIIIB | V22: A
A23: 12 | B23: 2425.7.036 | C23: 0118759400 | D23: ARES REAL RAMADANI | E23: L | F23: VIIIE | H23: 12 | P23: 12 | Q23: 2425.7.011 | R23: 0128926178 | S23: DEWI FAJRINA | T23: P | U23: VIIIC | V23: A
... A40: 29 | B40: 2425.7.026 | C40: 0129519809 | D40: RIDHO HIDAYATULLOH | E40: L | F40: VIIID | H40: 29 | P40: 29 | Q40: 2425.7.035 | R40: 0126904354 | S40: ANGGUN AFRITA | T40: P | U40: VIIID | V40: A
A41: 30 | B41: 2425.7.027 | C41: 0111509033 | D41: SANDI KURNIAWAN | E41: L | F41: VIIID | H41: 30 | P41: 30 | Q41: 2425.7.036 | R41: 0118759400 | S41: ARES REAL RAMADANI | T41: L | U41: VIIIE | V41: A | W41: 2425.7.028 | X41: 0113365190 | Y41: TAZRIL MAULANA MALIK | Z41: L | AA41: VIIIC
A42: 31 | B42: 2425.7.029 | C42: 0128401119 | D42: VENNY SUPRIATNA | E42: P | F42: VIIIA | H42: 31 | P42: 31 | Q42: 2425.7.037 | R42: 3127193341 | S42: ASSYIFA NURFITRIAH HARISMAYA | T42: P | U42: VIIIA | V42: A
A43: 32 | B43: 2425.7.031 | C43: 0115558969 | D43: WAHYU SUDRAJAT | E43: L | F43: VIIIE | H43: 32 | P43: 32 | Q43: 2425.7.038 | R43: 0111839880 | S43: DYANDRA PUTRI NUR ALIFA | T43: P | U43: VIIIA | V43: A
A44: P | B44: 20 | P44: 1 | Q44: 2425.7.039 | R44: 3122167330 | S44: ELSA AFIKA | T44: P | U44: VIIIB | V44: B
A45: L | B45: 12 | P45: 2 | Q45: 2425.7.040 | R45: 0124170979 | S45: EVIH KHUNAVIYA SEPTIYA PUTRI | T45: P | U45: VIIIE | V45: B | W45: 2425.7.065 | X45: 3118373266 | Y45: AFKAR FATAH BILHAQ | Z45: L | AA45: VIIIB
E46: Leuwimunding, Juli 2026 | P46: 3 | Q46: 2425.7.042 | R46: 0123011978 | S46: FAUZI MIHARJA | T46: L | U46: VIIIA | V46: B
E47: Wali Kelas | P47: 4 | Q47: 2425.7.043 | R47: 0128999573 | S47: FEBRIAN SYAKIB | T47: L | U47: VIIIE | V47: B
E48: =WLKLS!B12 -> Hj. EHA JULAEHA, S.Pd. | P48: 5 | Q48: 2425.7.044 | R48: 0121124291 | S48: FITRIYA AHIDA YUANDA | T48: P | U48: VIIIB | V48: B
E49: =WLKLS!C12 -> NIP. 198007162008012005 | P49: 6 | Q49: 2425.7.045 | R49: 0115920497 | S49: GAFAH INDRA QIANO | T49: L | U49: VIIID | V49: B
P50: 7 | Q50: 2425.7.046 | R50: 0112439829 | S50: IBRAHIM OVIK | T50: L | U50: VIIID | V50: B
A51: PEMERINTAH KABUPATEN MAJALENGKA | P51: 8 | Q51: 2425.7.047 | R51: 0113420392 | S51: IDA WINDA | T51: P | U51: VIIIB | V51: B
A52: DINAS PENDIDIKAN | P52: 9 | Q52: 2425.7.048 | R52: 0119646725 | S52: MOHAMMAD FAJAR SIDIK | T52: L | U52: VIIID | V52: B
A53: SMP NEGERI 3 LEUWIMUNDING | P53: 10 | Q53: 2425.7.049 | R53: 0121283062 | S53: MAURA DZAKIYAH | T53: P | U53: VIIID | V53: B
A54: TERAKREDITASI “A” SK.Nomor: 1346/BAN-SM/SK/2021 | P54: 11 | Q54: 2425.7.050 | R54: 0124539329 | S54: MOHAMAD RIZKI KURNIAWAN | T54: L | U54: VIIIC | V54: B
A55: Alamat : Jalan Raya Parungjaya Leuwimunding Kab. Majalengka 45473 Tlp. (0233) 510066 | P55: 12 | Q55: 2425.7.051 | R55: 0091533605 | S55: MUHAMAD SULAEMAN | T55: L | U55: VIIIC | V55: B
P56: 13 | Q56: 2425.7.052 | R56: 0115818081 | S56: MUHAMAD AZRIL MAULANA | T56: L | U56: VIIIC | V56: B
A57: DAFTAR MURID KELAS IX B | P57: 14 | Q57: 2425.7.053 | R57: 0129588550 | S57: MUHAMAD ROFI'I SAPUTRA | T57: L | U57: VIIIB | V57: B
A58: TAHUN PELAJARAN 2026 / 2027 | P58: 15 | Q58: 2425.7.054 | R58: 0115644252 | S58: MUHAMAD WINAB | T58: L | U58: VIIIB | V58: B
...

Sheet rekap
A1: PEMERINTAH KABUPATEN MAJALENGKA | G1: PEMERINTAH KABUPATEN MAJALENGKA
A2: DINAS PENDIDIKAN | G2: DINAS PENDIDIKAN
A3: SMP NEGERI 3 LEUWIMUNDING | G3: SMP NEGERI 3 LEUWIMUNDING
A4: TERAKREDITASI “A” SK.Nomor: 1346/BAN-SM/SK/2021 | G4: TERAKREDITASI “A” SK.Nomor: 1346/BAN-SM/SK/2021
A5: Alamat : Jalan Raya Parungjaya Leuwimunding Kab. Majalengka 45473 Tlp. (0233) 510066 | G5: Alamat : Jalan Raya Parungjaya Leuwimunding Kab. Majalengka 45473 Tlp. (0233) 510066
A7: REKAPITULASI JUMLAH SISWA REAL | G7: REKAPITULASI JUMLAH SISWA MUTASI
A8: SMP NEGERI 3 LEUWIMUNDING | G8: SMP NEGERI 3 LEUWIMUNDING
A9: TAHUN PELAJARAN 2026/2027 | G9: TAHUN PELAJARAN 2025/2026
A11: NO | B11: KELAS | C11: P | D11: L | E11: JML | H11: Kelas 7
A12: 1 | B12: 7A | C12: =VII!B45 -> 20 | D12: =VII!B46 -> 12 | E12: =SUM(C12:D12) -> 32
A13: 2 | B13: 7B | C13: =VII!B99 -> 20 | D13: =VII!B100 -> 12 | E13: =SUM(C13:D13) -> 32
A14: 3 | B14: 7C | C14: =VII!B153 -> 20 | D14: =VII!B154 -> 12 | E14: =SUM(C14:D14) -> 32
A15: 4 | B15: 7D | C15: =VII!B207 -> 19 | D15: =VII!B208 -> 13 | E15: =SUM(C15:D15) -> 32
A16: 5 | B16: 7E | C16: =VII!B261 -> 20 | D16: =VII!B262 -> 12 | E16: =SUM(C16:D16) -> 32
A18: JUMLAH | C18: =SUM(C12:C17) -> 99 | D18: =SUM(D12:D17) -> 61 | E18: =SUM(C18:D18) -> 160
A19: 6 | B19: 8A | C19: =VIII!B44 -> 16 | D19: =VIII!B45 -> 16 | E19: =SUM(C19:D19) -> 32
A20: 7 | B20: 8B | C20: =VIII!B96 -> 16 | D20: =VIII!B97 -> 16 | E20: =SUM(C20:D20) -> 32
A21: 8 | B21: 8C | C21: =VIII!B147 -> 16 | D21: =VIII!B148 -> 16 | E21: =SUM(C21:D21) -> 32 | O21: 3126038443
A22: 9 | B22: 8D | C22: =VIII!B198 -> 15 | D22: =VIII!B199 -> 17 | E22: =SUM(C22:D22) -> 32 | H22: Kelas 8 | W22: L | X22: SDN KERINJING
A23: 10 | B23: 8E | C23: =VIII!B250 -> 14 | D23: =VIII!B251 -> 18 | E23: =SUM(C23:D23) -> 32 | G23: 26-06-2026 | H23: RYVAN JANUAR | I23: 2425.7.125 | J23: L | K23: SMPN 2 SBY | L23: TIDAK NAIK
G24: 01-07-2026 | H24: ABDUL FURQON ARROHMAN | I24: 2526.7.170 | J24: L | K24: MTs PRAKARYA
A25: JUMLAH | C25: =SUM(C19:C24) -> 77 | D25: =SUM(D19:D24) -> 83 | E25: =SUM(C25:D25) -> 160 | G25: 13-07-2026 | H25: YUWEST AL LITH | I25: 2526.7.059 | J25: P | K25: MTsN 1 MJL | V25: L
A27: 11 | B27: 9A | C27: =IX!B44 -> 20 | D27: =IX!B45 -> 12 | E27: =SUM(C27:D27) -> 32
A28: 12 | B28: 9B | C28: =IX!B94 -> 16 | D28: =IX!B95 -> 16 | E28: =SUM(C28:D28) -> 32
A29: 13 | B29: 9C | C29: =IX!B144 -> 16 | D29: =IX!B145 -> 16 | E29: =SUM(C29:D29) -> 32
A30: 14 | B30: 9D | C30: =IX!B195 -> 17 | D30: =IX!B196 -> 11 | E30: =SUM(C30:D30) -> 28
A31: 15 | B31: 9E | C31: =IX!B246 -> 15 | D31: =IX!B247 -> 10 | E31: =SUM(C31:D31) -> 25
A34: JUMLAH | C34: =SUM(C27:C31) -> 84 | D34: =SUM(D27:D31) -> 65 | E34: =SUM(C34:D34) -> 149
A36: JUMLAH TOTAL | C36: =C18+C25+C34 -> 260 | D36: =D18+D25+D34 -> 209 | E36: =E18+E25+E34 -> 469
N37: 2425.7.060 | O37: 0125093820 | P37: RAHMA ASYIFA | Q37: P | R37: VII B | T37: 30-042026
D38: UPDATE | E38: 20-07-2026 | N38: 2425.7.108 | O38: 0102853129 | P38: KHAERUL ANWAR | Q38: L | R38: VII D | T38: 30-04-2026
H42: Kelas 9
G43: 01-07-2026 | H43: AFKAR FATAH BILHAQ | I43: 2425.7.065 | J43: L | K43: MTsN 1 MJL
H44: ALIFATULLOH NOVA ALVARIZI | I44: 2425.7.099 | J44: L | K44: IKUT ORANG TUA
H45: TAZRIL MAULANA MALIK | I45: 2425.7.028 | J45: L | K45: MTs GARAWANGI
O49: NELI ROSIKA, S.H
O50: Pembina Tk. I
K51: Leuwimunding, 01 Juni 2026 | O51: NIP. 19790120200012002
A52: PEMERINTAH KABUPATEN MAJALENGKA | K52: Kepala Sekolah,
A53: DINAS PENDIDIKAN
...

Sheet berkas
A1: PEMERINTAH KABUPATEN MAJALENGKA
A2: DINAS PENDIDIKAN
A3: SMP NEGERI 3 LEUWIMUNDING
A4: TERAKREDITASI “A” SK.Nomor: 02.00/692/BAP-SM/I/2017
A5: Alamat : Jalan Raya Parungjaya Leuwimunding Kab. Majalengka 45473 Tlp. (0233) 510066
A7: DAFTAR KEKURANGAN BERKAS
A8: KELAS……………….
A10: NO | B10: NAMA | C10: IJASAH | D10: SKHUN | E10: KIP/PKH/SKTM | F10: AKTE | G10: KK | H10: KTP | I10: KET
A11: 1
A12: 2
A13: 3
A14: 4
A15: 5
A16: 6
A17: 7
A18: 8
A19: 9
A20: 10
A21: 11
A22: 12
... A42: 32
F43: Leuwimunding, Januari 2021
F44: Wali Kelas,
F49: (……………………………….)

Sheet WLKLS
A1: 7A | B1: IKA KARTIKA, S.Pd | C1: NIP. 199104112023212000 | D1: MARLIYANI, S.Pd | E1: NIP. 199608192023212020 | F1: HANY ENDRAWATI, S.Si. | G1: NIP. 198410032022212000
A2: 7B | B2: FATURROHMAN, S.Pd | C2: NIP. - | D2: IKA KARTIKA, S.Pd | E2: NIP. 199104112023212000 | F2: SULASTRI, S.Pd. | G2: NIP. 197808012008012012 | N2: Majalengka, 28 Oktober 1988
A3: 7C | B3: MARLIYANI, S.Pd | C3: NIP. 199608192023212020 | D3: HANY ENDRAWATI, S.Si. | E3: NIP. 198410032022212000 | F3: MARLIYANI, S.Pd | G3: NIP. 199608192023212020
A4: 7D | B4: HANY ENDRAWATI, S.Si. | C4: NIP. 198410032022212000 | D4: SITI NURHALIMAH, S.Pd.I. | E4: NIP. 198103052014062001 | F4: IKA KARTIKA, S.Pd | G4: NIP. 199104112023212000 | N4: Brebes, 7 September 1992
A5: 7E | B5: DIANA FITRIA, S.Pd | C5: NIP. 199502252024212014 | D5: DESY NOVIA ANDRIANI, S.Pd | E5: NIP. 199211192022212022 | F5: SITI NURHALIMAH, S.Pd.I. | G5: NIP. 198103052014062001 | N5: UNI ANDINI, S.E
D6: SRI HARTINI, S.Pd | E6: NIP. 197907052014062004 | F6: EVA RAHMAWATI, S.Pd. | G6: NIP. 199403252022212000 | N6: Majalengka, 24-09-1996
A7: 8A | B7: RINA PARISYANA | C7: NIP.199209072024212041 | D7: NUNUNG NURHAYANI, S.Pd | E7: NIP. 196807211992032006 | F7: DESY NOVIA ANDRIANI, S.Pd | G7: NIP. 199211192022212022
A8: 8B | B8: NUNUNG NURHAYANI, S.Pd | C8: NIP. 196807211992032006 | D8: Hj. IWA YUHARTI S.S | E8: NIP. 197510172007012007 | F8: RINA NINGSIH, S.Pd | G8: NIP. 199802252023212009 | N8: Majalengka, 19 Agustus 1996
A9: 8C | B9: ARIEF RAHMAN HAKIM, S.Pd.I, M.Pd.I | C9: NIP.- | D9: EVA RAHMAWATI, S.Pd. | E9: NIP. 199403252022212000 | F9: DIANA FITRIA, S.Pd | G9: NIP. 199502252024212014 | N9: NURHALIMAH, S.Sos.
A10: 8D | B10: ABDUL ROHMAN S.Pd | C10: NIP. 198903052023211019 | D10: RINA NINGSIH, S.Pd | E10: NIP. 199802252023212009 | F10: Hj. EHA JULAEHA, S.Pd. | G10: NIP. 198007162008012005 | N10: Majalengka, 5 November 1996
A11: 8E | B11: RINA NINGSIH, S.Pd | C11: NIP. 199802252023212009 | D11: ABDUL ROHMAN S.Pd | E11: NIP. 198903052023211019 | F11: NUNUNG NURHAYANI, S.Pd | G11: NIP. 196807211992032006 | N11: DEVI PRATIWI, S.Pd.
A12: 9A | B12: Hj. EHA JULAEHA, S.Pd. | C12: NIP. 198007162008012005 | D12: SULASTRI, S.Pd. | E12: NIP. 197808012008012012 | F12: RINA PARISYANA | G12: NIP.199209072024212041 | N12: Cirebon, 23 Agustus 1996
A13: 9B | B13: SULASTRI, S.Pd. | C13: NIP. 197808012008012012 | D13: Hj. EHA JULAEHA, S.Pd. | E13: NIP. 198007162008012005 | F13: NUNUNG NURHAYANI, S.Pd | G13: NIP. 196807211992032006 | N13: TATIK RAHMATIKA DEWI, S.E.
A14: 9C | B14: SITI NURHALIMAH, S.Pd.I. | C14: NIP. 198103052014062001 | D14: MOCH. HUSSNY F, S.Pd | E14: NIP. 198410022010011012 | F14: MOCH. HUSSNY F, S.Pd | G14: NIP. 198410022010011012 | N14: Majalengka, 26 Januari 1997
A15: 9D | B15: MOCH. HUSSNY F, S.Pd | C15: NIP. 198410022010011012 | D15: ARIEF RAHMAN HAKIM, S.Pd.I, M.Pd.I | E15: NIP.- | N15: SEPTIAN SULAEMAN MUHAMMAD
A16: 9E | B16: Hj. IWA YUHARTI S.S | C16: NIP. 197510172007012007 | N16: Majalengka, 10 September 1998
N17: KUSWARA, S.Pd.
N18: Majalengka, 15 September 1992
N20: Majalengka,25-02-1998
N22: Majalengka, 05-03-1989
N24: Majalengka, 16-08-1997

Sheet Laporan
A1: KEADAAN SISWA
A2: SMP NEGERI 3 LEUWIMUNDING
A3: TAHUN PELAJARAN 2025 / 2026
A5: Nama Sekolah | C5: : SMP Negeri 3 Leuwimunding
A6: NPSN | C6: : 20213901
A7: Status | C7: : Negeri
A8: Akreditasi | C8: : A
A10: No | B10: Kelas VII | D10: Jumlah | E10: Rombel | F10: Kelas VIII | H10: Jumlah | I10: Rombel | J10: Kelas IX | L10: Jumlah | M10: Rombel | N10: Jumlah | Q10: ROMBEL
B11: L | C11: P | F11: L | G11: P | J11: L | K11: P | Q11: 7 | R11: 8 | S11: 9 | T11: JML
A12: 1 | B12: 61 | C12: 99 | D12: =B12+C12 -> 160 | E12: 5 | F12: 83 | G12: 77 | H12: =F12+G12 -> 160 | I12: 5 | J12: 65 | K12: 85 | L12: =J12+K12 -> 150 | M12: 5 | N12: =L12+H12+D12 -> 470 | Q12: =D12/32 -> 5 | R12: =H12/32 -> 5 | S12: =L12/32 -> 4.6875 | T12: =N12/32 -> 14.6875
J16: Leuwimunding, 11 Juli 2026
J17: Kepala Sekolah,
J22: ADA ARMADA PAHLA, S.Pd, M.Pd
J23: Pembina Utama Muda
J24: NIP. 197003181999031008
