Workbook
Name DATA: 'DATA SISWA KLS 7'!#REF!
Name DATA1: 'DATA SISWA KLS 7'!#REF!

Sheet 7.3 (2)
A1: DAFTAR PESERTA DIDIK
A2: SMP TUNAS HARAPAN
A3: TAHUN PELAJARAN 2026/2027
A5: Kelas : VII.3
A7: NO | C7: NAMA PESERTA DIDIK | D7: L/P | E7: BUKU | F7: ASTS 1 | G7: LDKS | H7: ASAT 1 | I7: ASTS 2 | J7: ASAT 2
A8: Urut | B8: Induk
A9: 1 | B9: =VLOOKUP(C9,'DATA SISWA KLS 7'!$A$2:$C$114,2,FALSE) -> 5467 | C9: AMELIA YUNI LISWANTI | D9: =VLOOKUP(C9,'DATA SISWA KLS 7'!$A$2:$D$159,3,FALSE) -> P
A10: 2 | B10: =VLOOKUP(C10,'DATA SISWA KLS 7'!$A$2:$C$114,2,FALSE) -> 5470 | C10: AQIL DAFFA SETIAWAN | D10: =VLOOKUP(C10,'DATA SISWA KLS 7'!$A$2:$D$159,3,FALSE) -> L
A11: 3 | B11: =VLOOKUP(C11,'DATA SISWA KLS 7'!$A$2:$C$114,2,FALSE) -> 5472 | C11: AUFAR ADZWAN | D11: =VLOOKUP(C11,'DATA SISWA KLS 7'!$A$2:$D$159,3,FALSE) -> L
A12: 4 | B12: =VLOOKUP(C12,'DATA SISWA KLS 7'!$A$2:$C$114,2,FALSE) -> 5473 | C12: AZIZAH DWI NUR RIZKI | D12: =VLOOKUP(C12,'DATA SISWA KLS 7'!$A$2:$D$159,3,FALSE) -> P
A13: 5 | B13: =VLOOKUP(C13,'DATA SISWA KLS 7'!$A$2:$C$114,2,FALSE) -> 5478 | C13: DINAR RESTU WINDIANA | D13: =VLOOKUP(C13,'DATA SISWA KLS 7'!$A$2:$D$159,3,FALSE) -> P
A14: 6 | B14: =VLOOKUP(C14,'DATA SISWA KLS 7'!$A$2:$C$114,2,FALSE) -> 5480 | C14: DITO ARYANDI MAULANA | D14: =VLOOKUP(C14,'DATA SISWA KLS 7'!$A$2:$D$159,3,FALSE) -> L
A15: 7 | B15: =VLOOKUP(C15,'DATA SISWA KLS 7'!$A$2:$C$114,2,FALSE) -> 5482 | C15: ERLANGGA MAHARDIKA | D15: =VLOOKUP(C15,'DATA SISWA KLS 7'!$A$2:$D$159,3,FALSE) -> L
A16: 8 | B16: =VLOOKUP(C16,'DATA SISWA KLS 7'!$A$2:$C$114,2,FALSE) -> 5491 | C16: HABSYAH RAMIZA NAIFA PULUNGAN | D16: =VLOOKUP(C16,'DATA SISWA KLS 7'!$A$2:$D$159,3,FALSE) -> P
A17: 9 | B17: =VLOOKUP(C17,'DATA SISWA KLS 7'!$A$2:$C$114,2,FALSE) -> 5494 | C17: IBAIDILLAH RAMADHAN | D17: =VLOOKUP(C17,'DATA SISWA KLS 7'!$A$2:$D$159,3,FALSE) -> L
A18: 10 | B18: =VLOOKUP(C18,'DATA SISWA KLS 7'!$A$2:$C$114,2,FALSE) -> 5497 | C18: KARISA NOVITA PUTRI AMRI | D18: =VLOOKUP(C18,'DATA SISWA KLS 7'!$A$2:$D$159,3,FALSE) -> P
A19: 11 | B19: =VLOOKUP(C19,'DATA SISWA KLS 7'!$A$2:$C$114,2,FALSE) -> 5499 | C19: KHALIZA PUTRI SUSILO | D19: =VLOOKUP(C19,'DATA SISWA KLS 7'!$A$2:$D$159,3,FALSE) -> P
A20: 12 | B20: =VLOOKUP(C20,'DATA SISWA KLS 7'!$A$2:$C$114,2,FALSE) -> 5500 | C20: KHANSA FADILAH | D20: =VLOOKUP(C20,'DATA SISWA KLS 7'!$A$2:$D$159,3,FALSE) -> P
... A45: 37 | B45: =VLOOKUP(C45,'DATA SISWA KLS 7'!$A$2:$C$114,2,FALSE) -> 5559 | C45: ZAHARANI | D45: =VLOOKUP(C45,'DATA SISWA KLS 7'!$A$2:$D$159,3,FALSE) -> P
A46: 38
A47: 39
A49: Laki-laki | C49: =COUNTIF(D9:D46,"L") -> 18
A50: Perempuan | C50: =COUNTIF(D9:D46,"P") -> 19
A51: Jumlah | C51: =SUM(C49:C50) -> 37
A52: Wali Kelas | C52: =guuru!B11 -> Suci Rahayu, S.S

Sheet 7.2 (2)
A1: DAFTAR PESERTA DIDIK
A2: SMP TUNAS HARAPAN
A3: TAHUN PELAJARAN 2026/2027
A5: Kelas : VII.2
A7: NO | C7: NAMA PESERTA DIDIK | D7: L/P | E7: BUKU | F7: ASTS 1 | G7: LDKS | H7: ASAT 1 | I7: ASTS 2 | J7: ASAT 2
A8: Urut | B8: Induk
A9: 1 | B9: =VLOOKUP(C9,'DATA SISWA KLS 7'!$A$2:$C$113,2,FALSE) -> 5455 | C9: AHMAD ZAHIDAN NAUFAL | D9: =VLOOKUP(C9,'DATA SISWA KLS 7'!$A$2:$D$159,3,FALSE) -> L
A10: 2 | B10: =VLOOKUP(C10,'DATA SISWA KLS 7'!$A$2:$C$113,2,FALSE) -> 5459 | C10: AL- AMIN RAFLI ABQARI | D10: =VLOOKUP(C10,'DATA SISWA KLS 7'!$A$2:$D$159,3,FALSE) -> L
A11: 3 | B11: =VLOOKUP(C11,'DATA SISWA KLS 7'!$A$2:$C$113,2,FALSE) -> 5460 | C11: ALDY SAPUTRA | D11: =VLOOKUP(C11,'DATA SISWA KLS 7'!$A$2:$D$159,3,FALSE) -> L
A12: 4 | B12: =VLOOKUP(C12,'DATA SISWA KLS 7'!$A$2:$C$113,2,FALSE) -> 5462 | C12: ALIKA FARZANA AYUNINDIA | D12: =VLOOKUP(C12,'DATA SISWA KLS 7'!$A$2:$D$159,3,FALSE) -> P
A13: 5 | B13: =VLOOKUP(C13,'DATA SISWA KLS 7'!$A$2:$C$113,2,FALSE) -> 5463 | C13: ALIYA HAYATUL HUSNA | D13: =VLOOKUP(C13,'DATA SISWA KLS 7'!$A$2:$D$159,3,FALSE) -> P
A14: 6 | B14: =VLOOKUP(C14,'DATA SISWA KLS 7'!$A$2:$C$113,2,FALSE) -> 5464 | C14: ALKHALIFI ZIKRI ARIEF | D14: =VLOOKUP(C14,'DATA SISWA KLS 7'!$A$2:$D$159,3,FALSE) -> L
A15: 7 | B15: =VLOOKUP(C15,'DATA SISWA KLS 7'!$A$2:$C$113,2,FALSE) -> 5469 | C15: ANDINI NUR OKTAVIANI | D15: =VLOOKUP(C15,'DATA SISWA KLS 7'!$A$2:$D$159,3,FALSE) -> P
A16: 8 | B16: =VLOOKUP(C16,'DATA SISWA KLS 7'!$A$2:$C$113,2,FALSE) -> 5474 | C16: AZKA IBRAHIM AWDEEP | D16: =VLOOKUP(C16,'DATA SISWA KLS 7'!$A$2:$D$159,3,FALSE) -> L
A17: 9 | B17: =VLOOKUP(C17,'DATA SISWA KLS 7'!$A$2:$C$113,2,FALSE) -> 5476 | C17: DIAH AYU SEVINA | D17: =VLOOKUP(C17,'DATA SISWA KLS 7'!$A$2:$D$159,3,FALSE) -> P
A18: 10 | B18: =VLOOKUP(C18,'DATA SISWA KLS 7'!$A$2:$C$113,2,FALSE) -> 5483 | C18: FADILAH INDRA JUNINO | D18: =VLOOKUP(C18,'DATA SISWA KLS 7'!$A$2:$D$159,3,FALSE) -> L
A19: 11 | B19: =VLOOKUP(C19,'DATA SISWA KLS 7'!$A$2:$C$113,2,FALSE) -> 5484 | C19: FADLI FATUR RAHMAN | D19: =VLOOKUP(C19,'DATA SISWA KLS 7'!$A$2:$D$159,3,FALSE) -> L
A20: 12 | B20: =VLOOKUP(C20,'DATA SISWA KLS 7'!$A$2:$C$113,2,FALSE) -> 5486 | C20: FAIZ EFFENDI | D20: =VLOOKUP(C20,'DATA SISWA KLS 7'!$A$2:$D$159,3,FALSE) -> L
... A44: 36 | B44: =VLOOKUP(C44,'DATA SISWA KLS 7'!$A$2:$C$113,2,FALSE) -> 5561 | C44: ZASKIA CLAUDIA | D44: =VLOOKUP(C44,'DATA SISWA KLS 7'!$A$2:$D$159,3,FALSE) -> P
A45: 37
A46: 38
A48: Laki-laki | C48: =COUNTIF(D9:D46,"L") -> 18
A49: Perempuan | C49: =COUNTIF(D9:D46,"P") -> 18
A50: Jumlah | C50: =SUM(C48:C49) -> 36
A51: Wali Kelas | C51: =guuru!B13 -> Ikhlas Munajati, S.Pd

Sheet 7.1 (2)
A1: DAFTAR PESERTA DIDIK
A2: SMP TUNAS HARAPAN
A3: TAHUN PELAJARAN 2026/2027
A5: Kelas : VII.1
A7: NO | C7: NAMA PESERTA DIDIK | D7: L/P | E7: BUKU | F7: ASTS 1 | G7: LDKS | H7: ASAT 1 | I7: ASTS 2 | J7: ASAT 2
A8: Urut | B8: Induk
A9: 1 | B9: =VLOOKUP(C9,'DATA SISWA KLS 7'!$A$2:$C$113,2,FALSE) -> 5453 | C9: AFRA ZAHRA RACHMAWATI | D9: =VLOOKUP(C9,'DATA SISWA KLS 7'!$A$2:$D$159,3,FALSE) -> P
A10: 2 | B10: =VLOOKUP(C10,'DATA SISWA KLS 7'!$A$2:$C$113,2,FALSE) -> 5454 | C10: AHLAM ZULFADLI FIRDAUS | D10: =VLOOKUP(C10,'DATA SISWA KLS 7'!$A$2:$D$159,3,FALSE) -> L
A11: 3 | B11: =VLOOKUP(C11,'DATA SISWA KLS 7'!$A$2:$C$113,2,FALSE) -> 5456 | C11: AHMAD ZULFIKAR | D11: =VLOOKUP(C11,'DATA SISWA KLS 7'!$A$2:$D$159,3,FALSE) -> L
A12: 4 | B12: =VLOOKUP(C12,'DATA SISWA KLS 7'!$A$2:$C$113,2,FALSE) -> 5457 | C12: AINIYA ZAHRA RATIFA | D12: =VLOOKUP(C12,'DATA SISWA KLS 7'!$A$2:$D$159,3,FALSE) -> P
A13: 5 | B13: =VLOOKUP(C13,'DATA SISWA KLS 7'!$A$2:$C$113,2,FALSE) -> 5458 | C13: AJENG ANINDITA | D13: =VLOOKUP(C13,'DATA SISWA KLS 7'!$A$2:$D$159,3,FALSE) -> P
A14: 6 | B14: =VLOOKUP(C14,'DATA SISWA KLS 7'!$A$2:$C$113,2,FALSE) -> 5461 | C14: ALFINO ADITYA PRATAMA | D14: =VLOOKUP(C14,'DATA SISWA KLS 7'!$A$2:$D$159,3,FALSE) -> L
A15: 7 | B15: =VLOOKUP(C15,'DATA SISWA KLS 7'!$A$2:$C$113,2,FALSE) -> 5465 | C15: ALYA MUTIA AZZAHRA | D15: =VLOOKUP(C15,'DATA SISWA KLS 7'!$A$2:$D$159,3,FALSE) -> P
A16: 8 | B16: =VLOOKUP(C16,'DATA SISWA KLS 7'!$A$2:$C$113,2,FALSE) -> 5466 | C16: AMELIA NUR KHASANAH | D16: =VLOOKUP(C16,'DATA SISWA KLS 7'!$A$2:$D$159,3,FALSE) -> P
A17: 9 | B17: =VLOOKUP(C17,'DATA SISWA KLS 7'!$A$2:$C$113,2,FALSE) -> 5468 | C17: ANANDA FADILLAH SYAHPUTRA | D17: =VLOOKUP(C17,'DATA SISWA KLS 7'!$A$2:$D$159,3,FALSE) -> L
A18: 10 | B18: =VLOOKUP(C18,'DATA SISWA KLS 7'!$A$2:$C$113,2,FALSE) -> 5471 | C18: ARTA AZIZI AGUNG | D18: =VLOOKUP(C18,'DATA SISWA KLS 7'!$A$2:$D$159,3,FALSE) -> L
A19: 11 | B19: =VLOOKUP(C19,'DATA SISWA KLS 7'!$A$2:$C$113,2,FALSE) -> 5475 | C19: DEANTA LAMYA NAJMU ADDIEN | D19: =VLOOKUP(C19,'DATA SISWA KLS 7'!$A$2:$D$159,3,FALSE) -> L
A20: 12 | B20: =VLOOKUP(C20,'DATA SISWA KLS 7'!$A$2:$C$113,2,FALSE) -> 5477 | C20: DIMITRI ALVARO RAHMAT | D20: =VLOOKUP(C20,'DATA SISWA KLS 7'!$A$2:$D$159,3,FALSE) -> L
... A44: 36 | B44: =VLOOKUP(C44,'DATA SISWA KLS 7'!$A$2:$C$113,2,FALSE) -> 5547 | C44: SAURA RAMADHANI BAHRI PUTRI | D44: =VLOOKUP(C44,'DATA SISWA KLS 7'!$A$2:$D$159,3,FALSE) -> P
A45: 37
A46: 38
A48: Laki-laki | C48: =COUNTIF(D9:D46,"L") -> 18
A49: Perempuan | C49: =COUNTIF(D9:D46,"P") -> 18
A50: Jumlah | C50: =SUM(C48:C49) -> 36
A51: Wali Kelas | C51: =guuru!B10 -> Jihan Fadyllah, S.Pd

Sheet 7.1
A1: DAFTAR PESERTA DIDIK
A2: SMP TUNAS HARAPAN
A3: TAHUN PELAJARAN 2026/2027
A5: Kelas : VII.1
A7: NO | C7: NAMA PESERTA DIDIK | D7: L/P | E7: AGAMA
A8: Urut | B8: Induk
A9: 1 | B9: =VLOOKUP(C9,'DATA SISWA KLS 7'!$A$2:$C$113,2,FALSE) -> 5453 | C9: AFRA ZAHRA RACHMAWATI | D9: =VLOOKUP(C9,'DATA SISWA KLS 7'!$A$2:$D$159,3,FALSE) -> P | E9: =VLOOKUP(C9,'DATA SISWA KLS 7'!$A$2:$D$113,4,FALSE) -> ISLAM
A10: 2 | B10: =VLOOKUP(C10,'DATA SISWA KLS 7'!$A$2:$C$113,2,FALSE) -> 5454 | C10: AHLAM ZULFADLI FIRDAUS | D10: =VLOOKUP(C10,'DATA SISWA KLS 7'!$A$2:$D$159,3,FALSE) -> L | E10: =VLOOKUP(C10,'DATA SISWA KLS 7'!$A$2:$D$113,4,FALSE) -> ISLAM
A11: 3 | B11: =VLOOKUP(C11,'DATA SISWA KLS 7'!$A$2:$C$113,2,FALSE) -> 5456 | C11: AHMAD ZULFIKAR | D11: =VLOOKUP(C11,'DATA SISWA KLS 7'!$A$2:$D$159,3,FALSE) -> L | E11: =VLOOKUP(C11,'DATA SISWA KLS 7'!$A$2:$D$113,4,FALSE) -> ISLAM
A12: 4 | B12: =VLOOKUP(C12,'DATA SISWA KLS 7'!$A$2:$C$113,2,FALSE) -> 5457 | C12: AINIYA ZAHRA RATIFA | D12: =VLOOKUP(C12,'DATA SISWA KLS 7'!$A$2:$D$159,3,FALSE) -> P | E12: =VLOOKUP(C12,'DATA SISWA KLS 7'!$A$2:$D$113,4,FALSE) -> ISLAM
A13: 5 | B13: =VLOOKUP(C13,'DATA SISWA KLS 7'!$A$2:$C$113,2,FALSE) -> 5458 | C13: AJENG ANINDITA | D13: =VLOOKUP(C13,'DATA SISWA KLS 7'!$A$2:$D$159,3,FALSE) -> P | E13: =VLOOKUP(C13,'DATA SISWA KLS 7'!$A$2:$D$113,4,FALSE) -> ISLAM
A14: 6 | B14: =VLOOKUP(C14,'DATA SISWA KLS 7'!$A$2:$C$113,2,FALSE) -> 5461 | C14: ALFINO ADITYA PRATAMA | D14: =VLOOKUP(C14,'DATA SISWA KLS 7'!$A$2:$D$159,3,FALSE) -> L | E14: =VLOOKUP(C14,'DATA SISWA KLS 7'!$A$2:$D$113,4,FALSE) -> ISLAM
A15: 7 | B15: =VLOOKUP(C15,'DATA SISWA KLS 7'!$A$2:$C$113,2,FALSE) -> 5465 | C15: ALYA MUTIA AZZAHRA | D15: =VLOOKUP(C15,'DATA SISWA KLS 7'!$A$2:$D$159,3,FALSE) -> P | E15: =VLOOKUP(C15,'DATA SISWA KLS 7'!$A$2:$D$113,4,FALSE) -> ISLAM
A16: 8 | B16: =VLOOKUP(C16,'DATA SISWA KLS 7'!$A$2:$C$113,2,FALSE) -> 5466 | C16: AMELIA NUR KHASANAH | D16: =VLOOKUP(C16,'DATA SISWA KLS 7'!$A$2:$D$159,3,FALSE) -> P | E16: =VLOOKUP(C16,'DATA SISWA KLS 7'!$A$2:$D$113,4,FALSE) -> ISLAM
A17: 9 | B17: =VLOOKUP(C17,'DATA SISWA KLS 7'!$A$2:$C$113,2,FALSE) -> 5468 | C17: ANANDA FADILLAH SYAHPUTRA | D17: =VLOOKUP(C17,'DATA SISWA KLS 7'!$A$2:$D$159,3,FALSE) -> L | E17: =VLOOKUP(C17,'DATA SISWA KLS 7'!$A$2:$D$113,4,FALSE) -> ISLAM
A18: 10 | B18: =VLOOKUP(C18,'DATA SISWA KLS 7'!$A$2:$C$113,2,FALSE) -> 5471 | C18: ARTA AZIZI AGUNG | D18: =VLOOKUP(C18,'DATA SISWA KLS 7'!$A$2:$D$159,3,FALSE) -> L | E18: =VLOOKUP(C18,'DATA SISWA KLS 7'!$A$2:$D$113,4,FALSE) -> ISLAM
A19: 11 | B19: =VLOOKUP(C19,'DATA SISWA KLS 7'!$A$2:$C$113,2,FALSE) -> 5475 | C19: DEANTA LAMYA NAJMU ADDIEN | D19: =VLOOKUP(C19,'DATA SISWA KLS 7'!$A$2:$D$159,3,FALSE) -> L | E19: =VLOOKUP(C19,'DATA SISWA KLS 7'!$A$2:$D$113,4,FALSE) -> ISLAM
A20: 12 | B20: =VLOOKUP(C20,'DATA SISWA KLS 7'!$A$2:$C$113,2,FALSE) -> 5477 | C20: DIMITRI ALVARO RAHMAT | D20: =VLOOKUP(C20,'DATA SISWA KLS 7'!$A$2:$D$159,3,FALSE) -> L | E20: =VLOOKUP(C20,'DATA SISWA KLS 7'!$A$2:$D$113,4,FALSE) -> ISLAM
... A44: 36 | B44: =VLOOKUP(C44,'DATA SISWA KLS 7'!$A$2:$C$113,2,FALSE) -> 5547 | C44: SAURA RAMADHANI BAHRI PUTRI | D44: =VLOOKUP(C44,'DATA SISWA KLS 7'!$A$2:$D$159,3,FALSE) -> P | E44: =VLOOKUP(C44,'DATA SISWA KLS 7'!$A$2:$D$113,4,FALSE) -> ISLAM
A45: 37
A46: 38
A48: Laki-laki | C48: =COUNTIF(D9:D46,"L") -> 18 | F48: Jakarta | J48: :
A49: Perempuan | C49: =COUNTIF(D9:D46,"P") -> 18 | F49: Guru Mat Pel | J49: :
A50: Jumlah | C50: =SUM(C48:C49) -> 36 | F50: Tanda Tangan | J50: :
A51: Wali Kelas | C51: =guuru!B10 -> Jihan Fadyllah, S.Pd
F52: Nama Jelas | J52: :

Sheet 7.2
A1: DAFTAR PESERTA DIDIK
A2: SMP TUNAS HARAPAN
A3: TAHUN PELAJARAN 2026/2027
A5: Kelas : VII.2
A7: NO | C7: NAMA PESERTA DIDIK | D7: L/P | E7: AGAMA
A8: Urut | B8: Induk
A9: 1 | B9: =VLOOKUP(C9,'DATA SISWA KLS 7'!$A$2:$C$113,2,FALSE) -> 5455 | C9: AHMAD ZAHIDAN NAUFAL | D9: =VLOOKUP(C9,'DATA SISWA KLS 7'!$A$2:$D$159,3,FALSE) -> L | E9: =VLOOKUP(C9,'DATA SISWA KLS 7'!$A$2:$D$114,4,FALSE) -> ISLAM
A10: 2 | B10: =VLOOKUP(C10,'DATA SISWA KLS 7'!$A$2:$C$113,2,FALSE) -> 5459 | C10: AL- AMIN RAFLI ABQARI | D10: =VLOOKUP(C10,'DATA SISWA KLS 7'!$A$2:$D$159,3,FALSE) -> L | E10: =VLOOKUP(C10,'DATA SISWA KLS 7'!$A$2:$D$114,4,FALSE) -> ISLAM
A11: 3 | B11: =VLOOKUP(C11,'DATA SISWA KLS 7'!$A$2:$C$113,2,FALSE) -> 5460 | C11: ALDY SAPUTRA | D11: =VLOOKUP(C11,'DATA SISWA KLS 7'!$A$2:$D$159,3,FALSE) -> L | E11: =VLOOKUP(C11,'DATA SISWA KLS 7'!$A$2:$D$114,4,FALSE) -> ISLAM
A12: 4 | B12: =VLOOKUP(C12,'DATA SISWA KLS 7'!$A$2:$C$113,2,FALSE) -> 5462 | C12: ALIKA FARZANA AYUNINDIA | D12: =VLOOKUP(C12,'DATA SISWA KLS 7'!$A$2:$D$159,3,FALSE) -> P | E12: =VLOOKUP(C12,'DATA SISWA KLS 7'!$A$2:$D$114,4,FALSE) -> ISLAM
A13: 5 | B13: =VLOOKUP(C13,'DATA SISWA KLS 7'!$A$2:$C$113,2,FALSE) -> 5463 | C13: ALIYA HAYATUL HUSNA | D13: =VLOOKUP(C13,'DATA SISWA KLS 7'!$A$2:$D$159,3,FALSE) -> P | E13: =VLOOKUP(C13,'DATA SISWA KLS 7'!$A$2:$D$114,4,FALSE) -> ISLAM
A14: 6 | B14: =VLOOKUP(C14,'DATA SISWA KLS 7'!$A$2:$C$113,2,FALSE) -> 5464 | C14: ALKHALIFI ZIKRI ARIEF | D14: =VLOOKUP(C14,'DATA SISWA KLS 7'!$A$2:$D$159,3,FALSE) -> L | E14: =VLOOKUP(C14,'DATA SISWA KLS 7'!$A$2:$D$114,4,FALSE) -> ISLAM
A15: 7 | B15: =VLOOKUP(C15,'DATA SISWA KLS 7'!$A$2:$C$113,2,FALSE) -> 5469 | C15: ANDINI NUR OKTAVIANI | D15: =VLOOKUP(C15,'DATA SISWA KLS 7'!$A$2:$D$159,3,FALSE) -> P | E15: =VLOOKUP(C15,'DATA SISWA KLS 7'!$A$2:$D$114,4,FALSE) -> ISLAM
A16: 8 | B16: =VLOOKUP(C16,'DATA SISWA KLS 7'!$A$2:$C$113,2,FALSE) -> 5474 | C16: AZKA IBRAHIM AWDEEP | D16: =VLOOKUP(C16,'DATA SISWA KLS 7'!$A$2:$D$159,3,FALSE) -> L | E16: =VLOOKUP(C16,'DATA SISWA KLS 7'!$A$2:$D$114,4,FALSE) -> ISLAM
A17: 9 | B17: =VLOOKUP(C17,'DATA SISWA KLS 7'!$A$2:$C$113,2,FALSE) -> 5476 | C17: DIAH AYU SEVINA | D17: =VLOOKUP(C17,'DATA SISWA KLS 7'!$A$2:$D$159,3,FALSE) -> P | E17: =VLOOKUP(C17,'DATA SISWA KLS 7'!$A$2:$D$114,4,FALSE) -> ISLAM
A18: 10 | B18: =VLOOKUP(C18,'DATA SISWA KLS 7'!$A$2:$C$113,2,FALSE) -> 5483 | C18: FADILAH INDRA JUNINO | D18: =VLOOKUP(C18,'DATA SISWA KLS 7'!$A$2:$D$159,3,FALSE) -> L | E18: =VLOOKUP(C18,'DATA SISWA KLS 7'!$A$2:$D$114,4,FALSE) -> ISLAM
A19: 11 | B19: =VLOOKUP(C19,'DATA SISWA KLS 7'!$A$2:$C$113,2,FALSE) -> 5484 | C19: FADLI FATUR RAHMAN | D19: =VLOOKUP(C19,'DATA SISWA KLS 7'!$A$2:$D$159,3,FALSE) -> L | E19: =VLOOKUP(C19,'DATA SISWA KLS 7'!$A$2:$D$114,4,FALSE) -> ISLAM
A20: 12 | B20: =VLOOKUP(C20,'DATA SISWA KLS 7'!$A$2:$C$113,2,FALSE) -> 5486 | C20: FAIZ EFFENDI | D20: =VLOOKUP(C20,'DATA SISWA KLS 7'!$A$2:$D$159,3,FALSE) -> L | E20: =VLOOKUP(C20,'DATA SISWA KLS 7'!$A$2:$D$114,4,FALSE) -> ISLAM
... A44: 36 | B44: =VLOOKUP(C44,'DATA SISWA KLS 7'!$A$2:$C$113,2,FALSE) -> 5561 | C44: ZASKIA CLAUDIA | D44: =VLOOKUP(C44,'DATA SISWA KLS 7'!$A$2:$D$159,3,FALSE) -> P | E44: =VLOOKUP(C44,'DATA SISWA KLS 7'!$A$2:$D$114,4,FALSE) -> ISLAM
A45: 37
A46: 38
A48: Laki-laki | C48: =COUNTIF(D9:D46,"L") -> 18 | F48: Jakarta | J48: :
A49: Perempuan | C49: =COUNTIF(D9:D46,"P") -> 18 | F49: Guru Mat Pel | J49: :
A50: Jumlah | C50: =SUM(C48:C49) -> 36 | F50: Tanda Tangan | J50: :
A51: Wali Kelas | C51: =guuru!B13 -> Ikhlas Munajati, S.Pd
F52: Nama Jelas | J52: :

Sheet 7.3
A1: DAFTAR PESERTA DIDIK
A2: SMP TUNAS HARAPAN
A3: TAHUN PELAJARAN 2026/2027
A5: Kelas : VII.3
A7: NO | C7: NAMA PESERTA DIDIK | D7: L/P | E7: AGAMA
A8: Urut | B8: Induk
A9: 1 | B9: =VLOOKUP(C9,'DATA SISWA KLS 7'!$A$2:$C$114,2,FALSE) -> 5467 | C9: AMELIA YUNI LISWANTI | D9: =VLOOKUP(C9,'DATA SISWA KLS 7'!$A$2:$D$159,3,FALSE) -> P | E9: =VLOOKUP(C9,'DATA SISWA KLS 7'!$A$2:$D$114,4,FALSE) -> ISLAM
A10: 2 | B10: =VLOOKUP(C10,'DATA SISWA KLS 7'!$A$2:$C$114,2,FALSE) -> 5470 | C10: AQIL DAFFA SETIAWAN | D10: =VLOOKUP(C10,'DATA SISWA KLS 7'!$A$2:$D$159,3,FALSE) -> L | E10: =VLOOKUP(C10,'DATA SISWA KLS 7'!$A$2:$D$114,4,FALSE) -> ISLAM
A11: 3 | B11: =VLOOKUP(C11,'DATA SISWA KLS 7'!$A$2:$C$114,2,FALSE) -> 5472 | C11: AUFAR ADZWAN | D11: =VLOOKUP(C11,'DATA SISWA KLS 7'!$A$2:$D$159,3,FALSE) -> L | E11: =VLOOKUP(C11,'DATA SISWA KLS 7'!$A$2:$D$114,4,FALSE) -> ISLAM
A12: 4 | B12: =VLOOKUP(C12,'DATA SISWA KLS 7'!$A$2:$C$114,2,FALSE) -> 5473 | C12: AZIZAH DWI NUR RIZKI | D12: =VLOOKUP(C12,'DATA SISWA KLS 7'!$A$2:$D$159,3,FALSE) -> P | E12: =VLOOKUP(C12,'DATA SISWA KLS 7'!$A$2:$D$114,4,FALSE) -> ISLAM
A13: 5 | B13: =VLOOKUP(C13,'DATA SISWA KLS 7'!$A$2:$C$114,2,FALSE) -> 5478 | C13: DINAR RESTU WINDIANA | D13: =VLOOKUP(C13,'DATA SISWA KLS 7'!$A$2:$D$159,3,FALSE) -> P | E13: =VLOOKUP(C13,'DATA SISWA KLS 7'!$A$2:$D$114,4,FALSE) -> ISLAM
A14: 6 | B14: =VLOOKUP(C14,'DATA SISWA KLS 7'!$A$2:$C$114,2,FALSE) -> 5480 | C14: DITO ARYANDI MAULANA | D14: =VLOOKUP(C14,'DATA SISWA KLS 7'!$A$2:$D$159,3,FALSE) -> L | E14: =VLOOKUP(C14,'DATA SISWA KLS 7'!$A$2:$D$114,4,FALSE) -> ISLAM
A15: 7 | B15: =VLOOKUP(C15,'DATA SISWA KLS 7'!$A$2:$C$114,2,FALSE) -> 5482 | C15: ERLANGGA MAHARDIKA | D15: =VLOOKUP(C15,'DATA SISWA KLS 7'!$A$2:$D$159,3,FALSE) -> L | E15: =VLOOKUP(C15,'DATA SISWA KLS 7'!$A$2:$D$114,4,FALSE) -> ISLAM
A16: 8 | B16: =VLOOKUP(C16,'DATA SISWA KLS 7'!$A$2:$C$114,2,FALSE) -> 5491 | C16: HABSYAH RAMIZA NAIFA PULUNGAN | D16: =VLOOKUP(C16,'DATA SISWA KLS 7'!$A$2:$D$159,3,FALSE) -> P | E16: =VLOOKUP(C16,'DATA SISWA KLS 7'!$A$2:$D$114,4,FALSE) -> ISLAM
A17: 9 | B17: =VLOOKUP(C17,'DATA SISWA KLS 7'!$A$2:$C$114,2,FALSE) -> 5494 | C17: IBAIDILLAH RAMADHAN | D17: =VLOOKUP(C17,'DATA SISWA KLS 7'!$A$2:$D$159,3,FALSE) -> L | E17: =VLOOKUP(C17,'DATA SISWA KLS 7'!$A$2:$D$114,4,FALSE) -> ISLAM
A18: 10 | B18: =VLOOKUP(C18,'DATA SISWA KLS 7'!$A$2:$C$114,2,FALSE) -> 5497 | C18: KARISA NOVITA PUTRI AMRI | D18: =VLOOKUP(C18,'DATA SISWA KLS 7'!$A$2:$D$159,3,FALSE) -> P | E18: =VLOOKUP(C18,'DATA SISWA KLS 7'!$A$2:$D$114,4,FALSE) -> ISLAM
A19: 11 | B19: =VLOOKUP(C19,'DATA SISWA KLS 7'!$A$2:$C$114,2,FALSE) -> 5499 | C19: KHALIZA PUTRI SUSILO | D19: =VLOOKUP(C19,'DATA SISWA KLS 7'!$A$2:$D$159,3,FALSE) -> P | E19: =VLOOKUP(C19,'DATA SISWA KLS 7'!$A$2:$D$114,4,FALSE) -> ISLAM
A20: 12 | B20: =VLOOKUP(C20,'DATA SISWA KLS 7'!$A$2:$C$114,2,FALSE) -> 5500 | C20: KHANSA FADILAH | D20: =VLOOKUP(C20,'DATA SISWA KLS 7'!$A$2:$D$159,3,FALSE) -> P | E20: =VLOOKUP(C20,'DATA SISWA KLS 7'!$A$2:$D$114,4,FALSE) -> ISLAM
... A45: 37 | B45: =VLOOKUP(C45,'DATA SISWA KLS 7'!$A$2:$C$114,2,FALSE) -> 5559 | C45: ZAHARANI | D45: =VLOOKUP(C45,'DATA SISWA KLS 7'!$A$2:$D$159,3,FALSE) -> P | E45: =VLOOKUP(C45,'DATA SISWA KLS 7'!$A$2:$D$114,4,FALSE) -> ISLAM
A46: 38
A47: 39
A49: Laki-laki | C49: =COUNTIF(D9:D46,"L") -> 18 | F49: Jakarta | J49: :
A50: Perempuan | C50: =COUNTIF(D9:D46,"P") -> 19 | F50: Guru Mat Pel | J50: :
A51: Jumlah | C51: =SUM(C49:C50) -> 37 | F51: Tanda Tangan | J51: :
A52: Wali Kelas | C52: =guuru!B11 -> Suci Rahayu, S.S
F53: Nama Jelas | J53: :

Sheet DATA SISWA KLS 7
A1: 1 | B1: 2 | C1: 3
A2: AFRA ZAHRA RACHMAWATI | B2: 5453 | C2: P | D2: ISLAM
A3: AHLAM ZULFADLI FIRDAUS | B3: 5454 | C3: L | D3: ISLAM
A4: AHMAD ZAHIDAN NAUFAL | B4: 5455 | C4: L | D4: ISLAM
A5: AHMAD ZULFIKAR | B5: 5456 | C5: L | D5: ISLAM
A6: AINIYA ZAHRA RATIFA | B6: 5457 | C6: P | D6: ISLAM
A7: AJENG ANINDITA | B7: 5458 | C7: P | D7: ISLAM
A8: AL- AMIN RAFLI ABQARI | B8: 5459 | C8: L | D8: ISLAM
A9: ALDY SAPUTRA | B9: 5460 | C9: L | D9: ISLAM
A10: ALFINO ADITYA PRATAMA | B10: 5461 | C10: L | D10: ISLAM
A11: ALIKA FARZANA AYUNINDIA | B11: 5462 | C11: P | D11: ISLAM
A12: ALIYA HAYATUL HUSNA | B12: 5463 | C12: P | D12: ISLAM
A13: ALKHALIFI ZIKRI ARIEF | B13: 5464 | C13: L | D13: ISLAM
... A110: ZASKIA CLAUDIA | B110: 5561 | C110: P | D110: ISLAM
D111: ISLAM
D112: ISLAM
D113: ISLAM
D114: ISLAM
D115: ISLAM
D116: ISLAM
D117: ISLAM
D118: ISLAM
D119: ISLAM
D120: ISLAM
D121: ISLAM
D122: ISLAM
... D136: ISLAM

Sheet Sheet1
A1: 1 | B1: 2 | C1: 3 | D1: 4 | E1: 5 | F1: 6 | G1: 7 | H1: 8 | I1: 9 | J1: 10 | K1: 11 | L1: 12 | M1: 13 | N1: 14 | O1: 15 | P1: 16 | Q1: 17 | R1: 18 | S1: 19 | T1: 20 | U1: 21 | V1: 22 | W1: 23 | X1: 24 | Y1: 25 | Z1: 26 | AA1: 27
A2: 78 | B2: 84 | C2: 80 | D2: 82 | E2: 90 | F2: 80 | G2: 88 | H2: 77 | I2: 80 | J2: 82 | K2: 92 | L2: 84 | M2: 80 | N2: 80 | O2: 78 | P2: 86 | Q2: 78 | R2: 78 | S2: 78 | T2: 75 | U2: 86 | V2: 80 | W2: 80 | X2: 80 | Y2: 78 | Z2: 80 | AA2: 76
A3: 86 | B3: 87 | C3: 84 | D3: 87 | E3: 87 | F3: 86 | G3: 88 | H3: 86 | I3: 87 | J3: 87 | K3: 87 | L3: 86 | M3: 83 | N3: 85 | O3: 85 | P3: 86 | Q3: 84 | R3: 86 | S3: 83 | T3: 78 | U3: 85 | V3: 85 | W3: 82 | X3: 84 | Y3: 85 | Z3: 83 | AA3: 81
A4: 83 | B4: 83 | C4: 80 | D4: 85 | E4: 87 | F4: 82 | G4: 84 | H4: 80 | I4: 83 | J4: 80 | K4: 82 | L4: 82 | M4: 80 | N4: 84 | O4: 80 | P4: 82 | Q4: 82 | R4: 80 | S4: 82 | T4: 78 | U4: 83 | V4: 83 | W4: 78 | X4: 80 | Y4: 83 | Z4: 78 | AA4: 78
A5: 78 | B5: 78 | C5: 80 | D5: 75 | E5: 75 | F5: 77 | G5: 78 | H5: 74 | I5: 84 | J5: 78 | K5: 77 | L5: 76 | M5: 77 | N5: 75 | O5: 76 | P5: 81 | Q5: 78 | R5: 76 | S5: 76 | T5: 73 | U5: 75 | V5: 77 | W5: 76 | X5: 76 | Y5: 77 | Z5: 74 | AA5: 74
A6: 71 | B6: 82 | C6: 72 | D6: 71 | E6: 75 | F6: 75 | G6: 80 | H6: 70 | I6: 71 | J6: 73 | K6: 79 | L6: 85 | M6: 80 | N6: 70 | O6: 72 | P6: 71 | Q6: 73 | R6: 75 | S6: 74 | T6: 70 | U6: 80 | V6: 71 | W6: 70 | X6: 70 | Y6: 80 | Z6: 70 | AA6: 72
A7: 85 | B7: 84 | C7: 80 | D7: 78 | E7: 83 | F7: 82 | G7: 86 | H7: 75 | I7: 78 | J7: 77 | K7: 84 | L7: 81 | M7: 76 | N7: 82 | O7: 78 | P7: 79 | Q7: 80 | R7: 82 | S7: 84 | T7: 75 | U7: 83 | V7: 82 | W7: 77 | X7: 76 | Y7: 81 | Z7: 80 | AA7: 78
A8: 83 | B8: 80 | C8: 84 | D8: 83 | E8: 85 | F8: 82 | G8: 81 | H8: 76 | I8: 82 | J8: 82 | K8: 83 | L8: 83 | M8: 81 | N8: 82 | O8: 78 | P8: 83 | Q8: 82 | R8: 83 | S8: 84 | T8: 76 | U8: 81 | V8: 83 | W8: 81 | X8: 80 | Y8: 81 | Z8: 80 | AA8: 79
A9: 82 | B9: 83 | C9: 85 | D9: 84 | E9: 85 | F9: 85 | G9: 85 | H9: 81 | I9: 83 | J9: 83 | K9: 84 | L9: 85 | M9: 80 | N9: 83 | O9: 80 | P9: 83 | Q9: 83 | R9: 84 | S9: 85 | T9: 80 | U9: 81 | V9: 83 | W9: 80 | X9: 80 | Y9: 82 | Z9: 82 | AA9: 80
A10: 78 | B10: 78 | C10: 78 | D10: 77 | E10: 78 | F10: 78 | G10: 78 | H10: 77 | I10: 77 | J10: 79 | K10: 79 | L10: 77 | M10: 79 | N10: 77 | O10: 77 | P10: 80 | Q10: 77 | R10: 79 | S10: 79 | T10: 77 | U10: 78 | V10: 78 | W10: 77 | X10: 78 | Y10: 78 | Z10: 77 | AA10: 77
A11: 80 | B11: 79 | C11: 79 | D11: 78 | E11: 81 | F11: 80 | G11: 82 | H11: 76 | I11: 80 | J11: 79 | K11: 81 | L11: 80 | M11: 79 | N11: 80 | O11: 78 | P11: 80 | Q11: 78 | R11: 79 | S11: 80 | T11: 77 | U11: 80 | V11: 80 | W11: 78 | X11: 78 | Y11: 79 | Z11: 78 | AA11: 79
A12: 83 | B12: 83 | C12: 85 | D12: 83 | E12: 85 | F12: 85 | G12: 85 | H12: 82 | I12: 82 | J12: 83 | K12: 84 | L12: 85 | M12: 80 | N12: 83 | O12: 81 | P12: 83 | Q12: 83 | R12: 84 | S12: 85 | T12: 80 | U12: 82 | V12: 83 | W12: 80 | X12: 80 | Y12: 82 | Z12: 82 | AA12: 80
A13: 76 | B13: 75 | C13: 75 | D13: 73 | E13: 77 | F13: 76 | G13: 74 | H13: 70 | I13: 72 | J13: 73 | K13: 74 | L13: 75 | M13: 72 | N13: 73 | O13: 73 | P13: 74 | Q13: 72 | R13: 72 | S13: 76 | T13: 70 | U13: 75 | V13: 75 | W13: 72 | X13: 72 | Y13: 75 | Z13: 73 | AA13: 72
A14: =SUM(A2:A13) -> 963 | B14: =SUM(B2:B13) -> 976 | C14: =SUM(C2:C13) -> 962 | D14: =SUM(D2:D13) -> 956 | E14: =SUM(E2:E13) -> 988 | F14: =SUM(F2:F13) -> 968 | G14: =SUM(G2:G13) -> 989 | H14: =SUM(H2:H13) -> 924 | ... AA14: =SUM(AA2:AA13) -> 926
A15: =RANK($A$14:$AA$14,$A$14:$AA$14,0) -> 10 | B15: =RANK($A$14:$AA$14,$A$14:$AA$14,0) -> 5 | C15: =RANK($A$14:$AA$14,$A$14:$AA$14,0) -> 11 | D15: =RANK($A$14:$AA$14,$A$14:$AA$14,0) -> 16 | E15: =RANK($A$14:$AA$14,$A$14:$AA$14,0) -> 2 | F15: =RANK($A$14:$AA$14,$A$14:$AA$14,0) -> 7 | G15: =RANK($A$14:$AA$14,$A$14:$AA$14,0) -> 1 | H15: =RANK($A$14:$AA$14,$A$14:$AA$14,0) -> 26 | ... AA15: =RANK($A$14:$AA$14,$A$14:$AA$14,0) -> 25
E16: =AVERAGE(E2:E13) -> 82.333333 | G16: =AVERAGE(G2:G13) -> 82.416667 | K16: =AVERAGE(K2:K13) -> 82.166667

Sheet Sheet2
A1: DAFTAR PERINGKAT SISWA SEMESTER GENAP
A2: SMP TUNAS HARAPAN
A3: TAHUN PELAJARAN 2017/2019
A5: NO | B5: NAMA | C5: KELAS | D5: PERINGKAT | E5: JUMLAH NILAI | G5: RATA-RATA
E6: PENGETAHUAN | F6: KETRAMPILAN
A7: 1 | B7: EKA DHANI | C7: VIII.1 | D7: I | E7: 989 | G7: 82.42
A8: 2 | B8: ISNAINI RAHMADANI | C8: VIII.2 | D8: II | E8: 988 | G8: 82.33
A9: 3 | B9: DEWI NOPITA SARI | C9: VIII.3 | D9: III | E9: 986 | G9: 82.17
A10: 4 | B10: =#REF! -> #REF! | C10: VII.1 | D10: I | E10: 849.2 | F10: 855 | G10: 85.372727
A11: 5 | B11: =#REF! -> #REF! | C11: VII.2 | D11: II | E11: 840.9 | F11: 853 | G11: 84.404545
A12: 6 | B12: =#REF! -> #REF! | C12: VII.3 | D12: III | E12: 837.9 | F12: 842 | G12: 84.086364
F14: Jakarta, 29 Juni 2008
F15: PANITIA UAS

Sheet guuru
A1: NO | B1: NAMA | C1: JABATAN
A2: 1 | B2: Siti Sundari, S.Pd, MM
A3: 2 | B3: Putri Rachmawati, S.Pd
A4: 3 | B4: Kusdaryono, S.Th
A5: 4 | B5: Agus Sigit Pamungkas, S.Pd
A6: 5 | B6: Ferni Fajarwati, S.Pd
A7: 6 | B7: Bayu Fitriatmoko, S.E
A8: 7 | B8: Istighfria Romadlonawati, S.Pd
A9: 8 | B9: Pradipta Arjunanta, S.Pd
A10: 9 | B10: Jihan Fadyllah, S.Pd
A11: 10 | B11: Suci Rahayu, S.S
A12: 11 | B12: Desman Manik, S.Pd
A13: 12 | B13: Ikhlas Munajati, S.Pd
... A19: 18 | B19: Kristianti, S.Pd

Sheet DAFTAR TTD RAPOT
A1: DAFTAR PESERTA DIDIK
A2: SMP TUNAS HARAPAN
A3: TAHUN PELAJARAN 2023/2024
A5: Kelas : VII.1
A6: NO | C6: NAMA PESERTA DIDIK | D6: L/P | E6: TANDA TANGAN
A7: Urut | B7: Induk
A8: 1 | B8: =VLOOKUP(C8,'DATA SISWA KLS 7'!$A$2:$C$165,'DATA SISWA KLS 7'!$C$1,FALSE) -> #N/A | C8: AISYAH | D8: =VLOOKUP(C8,'DATA SISWA KLS 7'!$A$2:$C$165,'DATA SISWA KLS 7'!$B$1,FALSE) -> #N/A | E8: 1 | F8: 2
A9: 2 | B9: =VLOOKUP(C9,'DATA SISWA KLS 7'!$A$2:$C$165,'DATA SISWA KLS 7'!$C$1,FALSE) -> #N/A | C9: AJILA KANA PUTRI | D9: =VLOOKUP(C9,'DATA SISWA KLS 7'!$A$2:$C$165,'DATA SISWA KLS 7'!$B$1,FALSE) -> #N/A
A10: 3 | B10: =VLOOKUP(C10,'DATA SISWA KLS 7'!$A$2:$C$165,'DATA SISWA KLS 7'!$C$1,FALSE) -> #N/A | C10: ALEA PARAS ZIVILIA | D10: =VLOOKUP(C10,'DATA SISWA KLS 7'!$A$2:$C$165,'DATA SISWA KLS 7'!$B$1,FALSE) -> #N/A | E10: 3 | F10: 4
A11: 4 | B11: =VLOOKUP(C11,'DATA SISWA KLS 7'!$A$2:$C$165,'DATA SISWA KLS 7'!$C$1,FALSE) -> #N/A | C11: ALGI PACHRI SYAHPUTRA | D11: =VLOOKUP(C11,'DATA SISWA KLS 7'!$A$2:$C$165,'DATA SISWA KLS 7'!$B$1,FALSE) -> #N/A
A12: 5 | B12: =VLOOKUP(C12,'DATA SISWA KLS 7'!$A$2:$C$165,'DATA SISWA KLS 7'!$C$1,FALSE) -> #N/A | C12: ASQY KEVIN PRAYOGA | D12: =VLOOKUP(C12,'DATA SISWA KLS 7'!$A$2:$C$165,'DATA SISWA KLS 7'!$B$1,FALSE) -> #N/A | E12: 5 | F12: 6
A13: 6 | B13: =VLOOKUP(C13,'DATA SISWA KLS 7'!$A$2:$C$165,'DATA SISWA KLS 7'!$C$1,FALSE) -> #N/A | C13: AURA FITRI DWIKHARIRA | D13: =VLOOKUP(C13,'DATA SISWA KLS 7'!$A$2:$C$165,'DATA SISWA KLS 7'!$B$1,FALSE) -> #N/A
A14: 7 | B14: =VLOOKUP(C14,'DATA SISWA KLS 7'!$A$2:$C$165,'DATA SISWA KLS 7'!$C$1,FALSE) -> #N/A | C14: AURA MAHARANI PUTRI | D14: =VLOOKUP(C14,'DATA SISWA KLS 7'!$A$2:$C$165,'DATA SISWA KLS 7'!$B$1,FALSE) -> #N/A | E14: 7 | F14: 8
A15: 8 | B15: =VLOOKUP(C15,'DATA SISWA KLS 7'!$A$2:$C$165,'DATA SISWA KLS 7'!$C$1,FALSE) -> #N/A | C15: BAGAS FATHUR RACHMANSYAH | D15: =VLOOKUP(C15,'DATA SISWA KLS 7'!$A$2:$C$165,'DATA SISWA KLS 7'!$B$1,FALSE) -> #N/A
A16: 9 | B16: =VLOOKUP(C16,'DATA SISWA KLS 7'!$A$2:$C$165,'DATA SISWA KLS 7'!$C$1,FALSE) -> #N/A | C16: CINTA SALSABILA | D16: =VLOOKUP(C16,'DATA SISWA KLS 7'!$A$2:$C$165,'DATA SISWA KLS 7'!$B$1,FALSE) -> #N/A | E16: 9 | F16: 10
A17: 10 | B17: =VLOOKUP(C17,'DATA SISWA KLS 7'!$A$2:$C$165,'DATA SISWA KLS 7'!$C$1,FALSE) -> #N/A | C17: DERIP PANI | D17: =VLOOKUP(C17,'DATA SISWA KLS 7'!$A$2:$C$165,'DATA SISWA KLS 7'!$B$1,FALSE) -> #N/A
A18: 11 | B18: =VLOOKUP(C18,'DATA SISWA KLS 7'!$A$2:$C$165,'DATA SISWA KLS 7'!$C$1,FALSE) -> #N/A | C18: DERLY RAVIANSA | D18: =VLOOKUP(C18,'DATA SISWA KLS 7'!$A$2:$C$165,'DATA SISWA KLS 7'!$B$1,FALSE) -> #N/A | E18: 11 | F18: 12
A19: 12 | B19: =VLOOKUP(C19,'DATA SISWA KLS 7'!$A$2:$C$165,'DATA SISWA KLS 7'!$C$1,FALSE) -> #N/A | C19: DION DENILSON SINAGA | D19: =VLOOKUP(C19,'DATA SISWA KLS 7'!$A$2:$C$165,'DATA SISWA KLS 7'!$B$1,FALSE) -> #N/A
A20: 13 | B20: =VLOOKUP(C20,'DATA SISWA KLS 7'!$A$2:$C$165,'DATA SISWA KLS 7'!$C$1,FALSE) -> #N/A | C20: DWI AADIBAH PUTRI | D20: =VLOOKUP(C20,'DATA SISWA KLS 7'!$A$2:$C$165,'DATA SISWA KLS 7'!$B$1,FALSE) -> #N/A | E20: 13 | F20: 14
A21: 14 | B21: =VLOOKUP(C21,'DATA SISWA KLS 7'!$A$2:$C$165,'DATA SISWA KLS 7'!$C$1,FALSE) -> #N/A | C21: FADLAN AL JUNIOR AQIRON | D21: =VLOOKUP(C21,'DATA SISWA KLS 7'!$A$2:$C$165,'DATA SISWA KLS 7'!$B$1,FALSE) -> #N/A
A22: 15 | B22: =VLOOKUP(C22,'DATA SISWA KLS 7'!$A$2:$C$165,'DATA SISWA KLS 7'!$C$1,FALSE) -> #N/A | C22: GHENDIS AULIA ZEFANA | D22: =VLOOKUP(C22,'DATA SISWA KLS 7'!$A$2:$C$165,'DATA SISWA KLS 7'!$B$1,FALSE) -> #N/A | E22: 15 | F22: 16
A23: 16 | B23: =VLOOKUP(C23,'DATA SISWA KLS 7'!$A$2:$C$165,'DATA SISWA KLS 7'!$C$1,FALSE) -> #N/A | C23: GIFARI BELVA PRATAMA | D23: =VLOOKUP(C23,'DATA SISWA KLS 7'!$A$2:$C$165,'DATA SISWA KLS 7'!$B$1,FALSE) -> #N/A
A24: 17 | B24: =VLOOKUP(C24,'DATA SISWA KLS 7'!$A$2:$C$165,'DATA SISWA KLS 7'!$C$1,FALSE) -> #N/A | C24: JESLIN DEFINA FRANCITA | D24: =VLOOKUP(C24,'DATA SISWA KLS 7'!$A$2:$C$165,'DATA SISWA KLS 7'!$B$1,FALSE) -> #N/A | E24: 17 | F24: 18
A25: 18 | B25: =VLOOKUP(C25,'DATA SISWA KLS 7'!$A$2:$C$165,'DATA SISWA KLS 7'!$C$1,FALSE) -> #N/A | C25: JOSLIN DEFINA FRANCITA | D25: =VLOOKUP(C25,'DATA SISWA KLS 7'!$A$2:$C$165,'DATA SISWA KLS 7'!$B$1,FALSE) -> #N/A
A26: 19 | B26: =VLOOKUP(C26,'DATA SISWA KLS 7'!$A$2:$C$165,'DATA SISWA KLS 7'!$C$1,FALSE) -> #N/A | C26: KEYLA AGUSTIN RAMADHANI | D26: =VLOOKUP(C26,'DATA SISWA KLS 7'!$A$2:$C$165,'DATA SISWA KLS 7'!$B$1,FALSE) -> #N/A | E26: 19 | F26: 20
A27: 20 | B27: =VLOOKUP(C27,'DATA SISWA KLS 7'!$A$2:$C$165,'DATA SISWA KLS 7'!$C$1,FALSE) -> #N/A | C27: MOVIC SATRIANI PRATAMA YUNIOR | D27: =VLOOKUP(C27,'DATA SISWA KLS 7'!$A$2:$C$165,'DATA SISWA KLS 7'!$B$1,FALSE) -> #N/A
A28: 21 | B28: =VLOOKUP(C28,'DATA SISWA KLS 7'!$A$2:$C$165,'DATA SISWA KLS 7'!$C$1,FALSE) -> #N/A | C28: MUHAMMAD BALQIS | D28: =VLOOKUP(C28,'DATA SISWA KLS 7'!$A$2:$C$165,'DATA SISWA KLS 7'!$B$1,FALSE) -> #N/A | E28: 21 | F28: 22
A29: 22 | B29: =VLOOKUP(C29,'DATA SISWA KLS 7'!$A$2:$C$165,'DATA SISWA KLS 7'!$C$1,FALSE) -> #N/A | C29: MUHTAR LATIF | D29: =VLOOKUP(C29,'DATA SISWA KLS 7'!$A$2:$C$165,'DATA SISWA KLS 7'!$B$1,FALSE) -> #N/A
A30: 23 | B30: =VLOOKUP(C30,'DATA SISWA KLS 7'!$A$2:$C$165,'DATA SISWA KLS 7'!$C$1,FALSE) -> #N/A | C30: NADINE NADA SUBHAN | D30: =VLOOKUP(C30,'DATA SISWA KLS 7'!$A$2:$C$165,'DATA SISWA KLS 7'!$B$1,FALSE) -> #N/A | E30: 23 | F30: 24
A31: 24 | B31: =VLOOKUP(C31,'DATA SISWA KLS 7'!$A$2:$C$165,'DATA SISWA KLS 7'!$C$1,FALSE) -> #N/A | C31: NAYYA GEVIRA AURORA WIJAYA | D31: =VLOOKUP(C31,'DATA SISWA KLS 7'!$A$2:$C$165,'DATA SISWA KLS 7'!$B$1,FALSE) -> #N/A
A32: 25 | B32: =VLOOKUP(C32,'DATA SISWA KLS 7'!$A$2:$C$165,'DATA SISWA KLS 7'!$C$1,FALSE) -> #N/A | C32: NIKY RAHMADHANI | D32: =VLOOKUP(C32,'DATA SISWA KLS 7'!$A$2:$C$165,'DATA SISWA KLS 7'!$B$1,FALSE) -> #N/A | E32: 25 | F32: 26
A33: 26 | B33: =VLOOKUP(C33,'DATA SISWA KLS 7'!$A$2:$C$165,'DATA SISWA KLS 7'!$C$1,FALSE) -> #N/A | C33: NURUL NIKI HAFIZAH | D33: =VLOOKUP(C33,'DATA SISWA KLS 7'!$A$2:$C$165,'DATA SISWA KLS 7'!$B$1,FALSE) -> #N/A
A34: 27 | B34: =VLOOKUP(C34,'DATA SISWA KLS 7'!$A$2:$C$165,'DATA SISWA KLS 7'!$C$1,FALSE) -> #N/A | C34: PANJI GANJAR ABIMANYU | D34: =VLOOKUP(C34,'DATA SISWA KLS 7'!$A$2:$C$165,'DATA SISWA KLS 7'!$B$1,FALSE) -> #N/A | E34: 27 | F34: 28
A35: 28 | B35: =VLOOKUP(C35,'DATA SISWA KLS 7'!$A$2:$C$165,'DATA SISWA KLS 7'!$C$1,FALSE) -> #N/A | C35: PRASETYO JATI NURCAHY0NO | D35: =VLOOKUP(C35,'DATA SISWA KLS 7'!$A$2:$C$165,'DATA SISWA KLS 7'!$B$1,FALSE) -> #N/A
A36: 29 | B36: =VLOOKUP(C36,'DATA SISWA KLS 7'!$A$2:$C$165,'DATA SISWA KLS 7'!$C$1,FALSE) -> #N/A | C36: REVALINA DEWI | D36: =VLOOKUP(C36,'DATA SISWA KLS 7'!$A$2:$C$165,'DATA SISWA KLS 7'!$B$1,FALSE) -> #N/A | E36: 29 | F36: 30
A37: 30 | B37: =VLOOKUP(C37,'DATA SISWA KLS 7'!$A$2:$C$165,'DATA SISWA KLS 7'!$C$1,FALSE) -> #N/A | C37: SABRINA VALERIA | D37: =VLOOKUP(C37,'DATA SISWA KLS 7'!$A$2:$C$165,'DATA SISWA KLS 7'!$B$1,FALSE) -> #N/A
A38: 31 | B38: =VLOOKUP(C38,'DATA SISWA KLS 7'!$A$2:$C$165,'DATA SISWA KLS 7'!$C$1,FALSE) -> #N/A | C38: SEPTIANA RAMADAN | D38: =VLOOKUP(C38,'DATA SISWA KLS 7'!$A$2:$C$165,'DATA SISWA KLS 7'!$B$1,FALSE) -> #N/A | E38: 31 | F38: 32
A39: 32 | B39: =VLOOKUP(C39,'DATA SISWA KLS 7'!$A$2:$C$165,'DATA SISWA KLS 7'!$C$1,FALSE) -> #N/A | C39: SYIFA AMELIA | D39: =VLOOKUP(C39,'DATA SISWA KLS 7'!$A$2:$C$165,'DATA SISWA KLS 7'!$B$1,FALSE) -> #N/A
A40: 33 | B40: =VLOOKUP(C40,'DATA SISWA KLS 7'!$A$2:$C$165,'DATA SISWA KLS 7'!$C$1,FALSE) -> #N/A | C40: TRENDON DELAPENA | D40: =VLOOKUP(C40,'DATA SISWA KLS 7'!$A$2:$C$165,'DATA SISWA KLS 7'!$B$1,FALSE) -> #N/A | E40: 33 | F40: 34
A41: 34 | B41: =VLOOKUP(C41,'DATA SISWA KLS 7'!$A$2:$C$165,'DATA SISWA KLS 7'!$C$1,FALSE) -> #N/A | C41: VALEN SABDA ALBANI | D41: =VLOOKUP(C41,'DATA SISWA KLS 7'!$A$2:$C$165,'DATA SISWA KLS 7'!$B$1,FALSE) -> #N/A
...
